File: dados/150k5p.raw
[Header]
; ACMS Raw Data File (default extension .raw)
; Copyright 1999, Quantum Design, Inc. All rights reserved.
TITLE,Xac-time_150K_5point_microfios-FeSiB_hac_10Oe_f_10Hz_28-04-24
FILEOPENTIME,10234292.92,04/28/2024,2:49 pm
BYAPP,ACMS,1.0,1.1,RAW
INFO,PPMS ACMS Option Version: 1.0.9 Build 14,APPNAME
INFO,HARMONICS,1
DATATYPE,COMMENT,1
DATATYPE,TIME,2
STARTUPAXIS,X,2,LINEAR,AUTO
STARTUPAXIS,Y,7,LINEAR,AUTO
STARTUPAXIS,Y,8,LINEAR,AUTO
TIMEMODE,MINUTES,RELATIVE
PLOT_APPEARANCE,ALL,HORZ_GRID_ON,VERT_GRID_ON,MARKERS_AND_LINES
RECORDS,ALL_RECORDS
DATATYPE,TIME,2
DATATYPE,COMMENT,1
[Data]
Comment,Time Stamp (sec),Temperature (K),Magnetic Field (Oe),Position (cm),Frequency (Hz),Amplitude (Oe),Drive (Oe),Signal (mV),Measure Type,Bin,Gain,PPMS Status (code),DSP Status (code)
,10234270.38,150.0063,0.07,0.199208755372504,10,10.0004080549069,0,-0.000484786869492382,5,0,25,4369,0
,10234273.8880469,150.006429687499,0.07,0.199208755372504,10,10.0004080549069,-8.03240306758093,0.000387010804843158,5,83,25,4369,0
,10234297.8626562,150.0086359375,0.07,0.199208755372504,30,10.0003985509341,9.56978474678673,0.000181755167432129,5,38,25,4369,0
,10234301.6689843,150.005328906251,0.07,0.199208755372504,30,10.0003985509341,-3.36903280168794,-0.000472769930234386,5,121,25,4369,0
,10234326.1354687,150.005346874999,0.07,0.199208755372504,50,10.0003795430668,-5.55591319302611,0.00039952527731657,5,76,25,4369,0
,10234360.8434766,150.0046703125,0.07,0.199208755372504,10,10.0004080549069,9.98836212543862,-0.000114650465548039,5,31,25,4369,0
,10234364.6011719,150.002984375,0.07,0.199208755372504,10,10.0004080549069,-6.34419170892896,-0.00035556935472414,5,114,25,4369,0
,10234388.8087891,150.004226171874,0.07,0.199208755372504,30,10.0003985509341,-2.4298986390103,0.000405837393676242,5,69,25,4369,0
,10234413.045,150.00471875,0.07,0.199208755372504,50,10.0003795430668,9.23914597718402,-0.000288336304947734,5,24,25,4369,0
,10234416.3649999,150.007377343749,0.07,0.199208755372504,50,10.0003795430668,-8.57761164494987,-0.00017314744181931,5,107,25,4369,0
,10234448.0267188,150.00241328125,0.07,0.199208755372504,10,10.0004080549069,0.980211399670675,0.000384213926736266,5,62,25,4369,0
,10234471.4825781,150.001029296875,0.07,0.199208755372504,30,10.0003985509341,7.40980656031269,-0.000448981170646019,5,17,25,4369,0
,10234474.9128125,149.9977546875,0.07,0.199208755372504,30,10.0003985509341,-9.80824369692192,-3.79021771045191E-5,5,100,25,4369,0
,10234498.6511328,150.0042703125,0.07,0.199208755372504,50,10.0003795430668,4.27571320987422,0.000397084886208176,5,55,25,4369,0
,10234530.4896094,150.0013234375,0.07,0.199208755372504,10,10.0004080549069,4.71415972401153,-0.00047702225856483,5,10,25,4369,0
,10234534.2213673,150.00151796875,0.07,0.199208755372504,10,10.0004080549069,-9.89216873797649,0.000257590436376631,5,93,25,4369,0
,10234558.53875,150.001568750001,0.07,0.199208755372504,30,10.0003985509341,7.0713496299336,0.000376435669345989,5,48,25,4369,0
,10234582.6904687,150.000987109375,0.07,0.199208755372504,50,10.0003795430668,1.46736043508789,-0.000479167606681585,5,3,25,4369,0
,10234586.4384375,150.00063046875,0.07,0.199208755372504,50,10.0003795430668,-8.81954737058493,0.000365736987441778,5,86,25,4369,0
,10234621.4572266,150.001513671875,0.07,0.199208755372504,10,10.0004080549069,9.04026180850127,0.000197688350453973,5,41,25,4369,0
,10234625.2473438,150.000832812501,0.07,0.199208755372504,10,10.0004080549069,-1.95098282772447,-0.000459149305243046,5,124,25,4369,0
,10234649.5541797,150.000274609375,0.07,0.199208755372504,30,10.0003985509341,-6.71585719891891,0.000393788989943763,5,79,25,4369,0
,10234674.8738281,150.0051109375,0.07,0.199208755372504,50,10.0003795430668,9.9522249821852,2.84483190625907E-5,5,34,25,4369,0
,10234678.5083203,150.004527343751,0.07,0.199208755372504,50,10.0003795430668,-5.14122256606442,-0.000452274130657315,5,117,25,4369,0
,10234713.2875,150.000634375,0.07,0.199208755372504,10,10.0004080549069,-3.82699047950326,0.000405227474402636,5,72,25,4369,0
,10234737.8069922,149.999713671875,0.07,0.199208755372504,30,10.0003985509341,9.70069913880747,-0.000163823715411127,5,27,25,4369,0
,10234741.3636718,150.000524218751,0.07,0.199208755372504,30,10.0003985509341,-7.73041261766559,-0.000270273885689676,5,110,25,4369,0
,10234766.1488281,150.000873046875,0.07,0.199208755372504,50,10.0003795430668,-0.490695366569778,0.000411453051492572,5,65,25,4369,0
,10234800.5078125,149.9989234375,0.07,0.199208755372504,10,10.0004080549069,8.31503540828069,-0.000447860511485487,5,20,25,4369,0
,10234804.2752343,150.000058203125,0.07,0.199208755372504,10,10.0004080549069,-9.41582485350606,-2.63273250311616E-5,5,103,25,4369,0
,10234828.8671875,149.99991484375,0.07,0.199208755372504,30,10.0003985509341,2.90296246577389,0.000403427984565496,5,58,25,4369,0
,10234853.1660547,149.998253515625,0.07,0.199208755372504,50,10.0003795430668,5.95721913846527,-0.000473525049164891,5,13,25,4369,0
,10234856.7162499,149.997637499999,0.07,0.199208755372504,50,10.0003795430668,-10.0003795430668,0.00010389843955636,5,96,25,4369,0
,10234891.7399609,149.999629687499,0.07,0.199208755372504,10,10.0004080549069,5.95723612294857,0.000370627676602453,5,51,25,4369,0
,10234915.7553125,150.001659375,0.07,0.199208755372504,30,10.0003985509341,2.90296246577389,-0.000481457552976079,5,6,25,4369,0
,10234919.6329688,150.001789062499,0.07,0.199208755372504,30,10.0003985509341,-9.41581590509685,0.000331251713861194,5,89,25,4369,0
,10234945.0490625,149.999923437501,0.07,0.199208755372504,50,10.0003795430668,8.31501170155208,0.00033121039159596,5,44,25,4369,0
,10234948.6219531,150.000344921877,0.07,0.199208755372504,50,10.0003795430668,-0.490695366569778,-0.000477961404249072,5,127,25,4369,0
,10234984.0927344,149.9977984375,0.07,0.199208755372504,10,10.0004080549069,-7.73041996433595,0.000392804795410484,5,82,25,4369,0
,10235008.4938282,150.00094765625,0.07,0.199208755372504,30,10.0003985509341,9.70069913880747,0.000147129111509356,5,37,25,4369,0
,10235012.0018751,150.00049375,0.07,0.199208755372504,30,10.0003985509341,-3.82698684249031,-0.000470050791692403,5,120,25,4369,0
,10235036.0527344,150.001328906249,0.07,0.199208755372504,50,10.0003795430668,-5.14122256606441,0.000401718122884631,5,75,25,4369,0
,10235070.7786719,149.99956171875,0.07,0.199208755372504,10,10.0004080549069,9.95225335673296,-0.000168256228789687,5,30,25,4369,0
,10235074.4131641,149.999594140624,0.07,0.199208755372504,10,10.0004080549069,-6.71586358139698,-0.000311922922264785,5,113,25,4369,0
,10235098.4489062,150.001345312501,0.07,0.199208755372504,30,10.0003985509341,-1.95098097359135,0.000408952603013151,5,68,25,4369,0
,10235122.3694531,150.000098828125,0.07,0.199208755372504,50,10.0003795430668,9.04023603410313,-0.000320989871397614,5,23,25,4369,0
,10235125.9942187,150.000455468751,0.07,0.199208755372504,50,10.0003795430668,-8.81954737058493,-0.000153640378266573,5,106,25,4369,0
,10235157.0794922,150.000718749999,0.07,0.199208755372504,10,10.0004080549069,1.46736461864371,0.000409534259233624,5,61,25,4369,0
,10235181.11125,150.00073125,0.07,0.199208755372504,30,10.0003985509341,7.0713496299336,-0.000456564141333931,5,16,25,4369,0
,10235185.0342968,150.000115234374,0.07,0.199208755372504,30,10.0003985509341,-9.89215933686981,-5.18681998882056E-6,5,99,25,4369,0
,10235209.8384375,149.998001562499,0.07,0.199208755372504,50,10.0003795430668,4.71414628362317,0.000393568119034171,5,54,25,4369,0
,10235245.5517578,149.998623828125,0.07,0.199208755372504,10,10.0004080549069,4.27572540025666,-0.000480015878565609,5,9,25,4369,0
,10235248.8879687,149.999304687499,0.07,0.199208755372504,10,10.0004080549069,-9.80825301827858,0.000278329825960099,5,92,25,4369,0
,10235273.1188282,150.000068359375,0.07,0.199208755372504,30,10.0003985509341,7.40980656031269,0.000375031053812967,5,47,25,4369,0
,10235297.1614844,150.00008515625,0.07,0.199208755372504,50,10.0003795430668,0.980208605021649,-0.000482451030984521,5,2,25,4369,0
,10235300.5430859,150.001544140626,0.07,0.199208755372504,50,10.0003795430668,-8.57761164494987,0.000374245410785079,5,85,25,4369,0
,10235335.936875,150,0.07,0.199208755372504,10,10.0004080549069,9.23917231868949,0.000152603024616838,5,40,25,4369,0
,10235339.3541406,150,0.07,0.199208755372504,10,10.0004080549069,-2.42990094828733,-0.000469523074571043,5,123,25,4369,0
,10235363.9007813,149.999528125001,0.07,0.199208755372504,30,10.0003985509341,-6.34418567967242,0.000397345607375933,5,78,25,4369,0
,10235388.2716016,149.98608046875,0.07,0.199208755372504,50,10.0003795430668,9.98833364794231,-5.61047345399863E-6,5,33,25,4369,0
,10235392.0357813,149.994834375001,0.07,0.199208755372504,50,10.0003795430668,-5.5559131930261,-0.00044754478149116,5,116,25,4369,0
,10235427.8560547,149.997953515624,0.07,0.199208755372504,10,10.0004080549069,-3.36903600347996,0.000414218520745635,5,71,25,4369,0
,10235451.7476562,150.0029875,0.07,0.199208755372504,30,10.0003985509341,9.56978474678673,-0.000196298028135466,5,26,25,4369,0
,10235455.2038281,150.000393749999,0.07,0.199208755372504,30,10.0003985509341,-8.03239543391836,-0.000238765561435785,5,109,25,4369,0
,10235479.3825,150.000274999999,0.07,0.199208755372504,50,10.0003795430668,1.2246528329075E-15,0.000409047631546855,5,64,25,4369,0
,10235515.9864062,150.00003125,0.07,0.199208755372504,10,10.0004080549069,8.03240306758093,-0.000451377127319574,5,19,25,4369,0
,10235519.5528125,149.999512499999,0.07,0.199208755372504,10,10.0004080549069,-9.56979384152169,-8.38103005662569E-6,5,102,25,4369,0
,10235543.5591797,150.0006734375,0.07,0.199208755372504,30,10.0003985509341,3.36903280168794,0.000403168960474432,5,57,25,4369,0
,10235567.269375,150.002040625,0.07,0.199208755372504,50,10.0003795430668,5.5559131930261,-0.000472346600145102,5,12,25,4369,0
,10235570.7579688,150.001975781249,0.07,0.199208755372504,50,10.0003795430668,-9.98833364794231,0.00013419110327959,5,95,25,4369,0
,10235602.0889063,150,0.07,0.199208755372504,10,10.0004080549069,6.34419170892896,0.000364402367267758,5,50,25,4369,0
,10235626.9956641,150.000720703125,0.07,0.199208755372504,30,10.0003985509341,2.4298986390103,-0.000478774373833504,5,5,25,4369,0
,10235630.4096876,150.000234375001,0.07,0.199208755372504,30,10.0003985509341,-9.23916353816351,0.000353313581500616,5,88,25,4369,0
,10235655.3583594,149.999467578124,0.07,0.199208755372504,50,10.0003795430668,8.57761164494987,0.000320328213274479,5,43,25,4369,0
,10235659.0998437,149.999694531248,0.07,0.199208755372504,50,10.0003795430668,-0.980208605021648,-0.000479467120021582,5,126,25,4369,0
,10235693.189414,150.000791796874,0.07,0.199208755372504,10,10.0004080549069,-7.40981360229206,0.00039826991269365,5,81,25,4369,0
,10235717.988125,149.9996890625,0.07,0.199208755372504,30,10.0003985509341,9.80824369692192,0.000113352758085562,5,36,25,4369,0
,10235721.4767189,150.000240234375,0.07,0.199208755372504,30,10.0003985509341,-4.27572133678467,-0.000465204939246177,5,119,25,4369,0
,10235746.5211719,149.999553125,0.07,0.199208755372504,50,10.0003795430668,-4.71414628362317,0.000408553052693606,5,74,25,4369,0
,10235781.2230859,149.999756640625,0.07,0.199208755372504,10,10.0004080549069,9.89216873797649,-0.000180781644303352,5,29,25,4369,0
,10235784.838125,149.999918750001,0.07,0.199208755372504,10,10.0004080549069,-7.07135635025724,-0.0002776097971946,5,112,25,4369,0
,10235808.6989062,149.996933203125,0.07,0.199208755372504,30,10.0003985509341,-1.46736322412126,0.000411804260996481,5,67,25,4369,0
,10235833.5367187,150.00224453125,0.07,0.199208755372504,50,10.0003795430668,8.81954737058493,-0.000360614713281393,5,22,25,4369,0
,10235837.2782031,150.000526171876,0.07,0.199208755372504,50,10.0003795430668,-9.04023603410313,-0.00012841341085732,5,105,25,4369,0
,10235872.5929688,150.000476562501,0.07,0.199208755372504,10,10.0004080549069,1.95098282772447,0.000404758902732283,5,60,25,4369,0
,10235896.2155859,150.000882421875,0.07,0.199208755372504,30,10.0003985509341,6.71585719891891,-0.000460266859994994,5,15,25,4369,0
,10235899.5388281,150.00078515625,0.07,0.199208755372504,30,10.0003985509341,-9.95224389852435,1.76829699840811E-5,5,98,25,4369,0
,10235923.6382813,149.999594531249,0.07,0.199208755372504,50,10.0003795430668,5.14122256606442,0.0003898608032614,5,53,25,4369,0
,10235955.4171875,149.998128125,0.07,0.199208755372504,10,10.0004080549069,3.82699047950326,-0.000469138612970709,5,8,25,4369,0
,10235958.9155078,149.999976171876,0.07,0.199208755372504,10,10.0004080549069,-9.70070835795815,0.000309997703880071,5,91,25,4369,0
,10235983.475,150.00035390625,0.07,0.199208755372504,30,10.0003985509341,7.7304126176656,0.000362624220239619,5,46,25,4369,0
,10236008.9164453,149.999408984375,0.07,0.199208755372504,50,10.0003795430668,0.490695366569777,-0.000483764661476016,5,1,25,4369,0
,10236012.3564063,150.0001546875,0.07,0.199208755372504,50,10.0003795430668,-8.31501170155209,0.000378841161727905,5,84,25,4369,0
,10236046.2171485,150.000197656251,0.07,0.199208755372504,10,10.0004080549069,9.41582485350606,0.000136133166961372,5,39,25,4369,0
,10236049.4885157,149.999873437502,0.07,0.199208755372504,10,10.0004080549069,-2.90296522463158,-0.000455905392300337,5,122,25,4369,0
,10236073.7734765,149.997499609374,0.07,0.199208755372504,30,10.0003985509341,-5.95723046143856,0.000398393733323448,5,77,25,4369,0
,10236097.79125,150.001025,0.07,0.199208755372504,50,10.0003795430668,10.0003795430668,-4.03959769755602E-5,5,32,25,4369,0
,10236101.3219921,149.999663281249,0.07,0.199208755372504,50,10.0003795430668,-5.95721913846527,-0.000429558753967285,5,115,25,4369,0
,10236133.2366406,150.00008203125,0.07,0.199208755372504,10,10.0004080549069,-2.90296522463158,0.0004030522541143,5,70,25,4369,0
,10236158.2080078,149.9999390625,0.07,0.199208755372504,30,10.0003985509341,9.41581590509685,-0.000222049614725013,5,25,25,4369,0
,10236161.8035938,150.000068749999,0.07,0.199208755372504,30,10.0003985509341,-8.31502750601608,-0.000220362433335847,5,108,25,4369,0
,10236186.6517969,150.002248046875,0.07,0.199208755372504,50,10.0003795430668,0.490695366569776,0.000411085039377212,5,63,25,4369,0
,10236220.7357031,149.99951015625,0.07,0.199208755372504,10,10.0004080549069,7.73041996433595,-0.000463856558781117,5,18,25,4369,0
,10236224.4739454,150.000709765625,0.07,0.199208755372504,10,10.0004080549069,-9.70070835795815,1.99809437617657E-5,5,101,25,4369,0
,10236248.6040625,150.000246875001,0.07,0.199208755372504,30,10.0003985509341,3.82698684249032,0.000403215849979057,5,56,25,4369,0
,10236273.2333203,149.99970703125,0.07,0.199208755372504,50,10.0003795430668,5.14122256606442,-0.000474704010412097,5,11,25,4369,0
,10236277.0688281,149.999382812501,0.07,0.199208755372504,50,10.0003795430668,-9.9522249821852,0.000165362842381001,5,94,25,4369,0
,10236312.4814844,149.998751953125,0.07,0.199208755372504,10,10.0004080549069,6.71586358139698,0.000363288854714483,5,49,25,4369,0
,10236336.4628125,150.000528125,0.07,0.199208755372504,30,10.0003985509341,1.95098097359135,-0.000482620736066666,5,4,25,4369,0
,10236340.1524219,150.00007421875,0.07,0.199208755372504,30,10.0003985509341,-9.04025321701159,0.000355071194159488,5,87,25,4369,0
,10236364.1896875,150.0004796875,0.07,0.199208755372504,50,10.0003795430668,8.81954737058493,0.00028915461152792,5,42,25,4369,0
,10236367.7560938,149.998858593751,0.07,0.199208755372504,50,10.0003795430668,-1.46736043508789,-0.000475873565301299,5,125,25,4369,0
,10236403.661875,150.00016875,0.07,0.199208755372504,10,10.0004080549069,-7.07135635025724,0.00039498379919678,5,80,25,4369,0
,10236428.2248047,150.002923828125,0.07,0.199208755372504,30,10.0003985509341,9.89215933686981,8.17805347550247E-5,5,35,25,4369,0
,10236431.7814843,150.003928906251,0.07,0.199208755372504,30,10.0003985509341,-4.71415524386975,-0.000465516867633495,5,118,25,4369,0
,10236455.4164452,149.999021484376,0.07,0.199208755372504,50,10.0003795430668,-4.27571320987422,0.000405179429799318,5,73,25,4369,0
,10236491.821875,149.9958828125,0.07,0.199208755372504,10,10.0004080549069,9.80825301827858,-0.000216095359064638,5,28,25,4369,0
,10236495.5179688,149.995980078125,0.07,0.199208755372504,10,10.0004080549069,-7.40981360229206,-0.000230793957598507,5,111,25,4369,0
,10236520.1997656,150.00071640625,0.07,0.199208755372504,30,10.0003985509341,-0.980210468118438,0.000411535212252703,5,66,25,4369,0
,10236544.6088281,149.998042578125,0.07,0.199208755372504,50,10.0003795430668,8.57761164494987,-0.000398718472570181,5,21,25,4369,0
,10236548.2206249,150.001965625,0.07,0.199208755372504,50,10.0003795430668,-9.23914597718402,-0.000107029685750604,5,104,25,4369,0
,10236582.3389063,149.999376171876,0.07,0.199208755372504,10,10.0004080549069,2.42990094828733,0.000385228486265987,5,59,25,4369,0
,10236607.17,149.999890625,0.07,0.199208755372504,30,10.0003985509341,6.34418567967242,-0.000466900140357514,5,14,25,4369,0
,10236610.6975,149.9992421875,0.07,0.199208755372504,30,10.0003985509341,-9.98835263291373,4.84178437747886E-5,5,97,25,4369,0
,10236634.6751562,150.0002046875,0.07,0.199208755372504,50,10.0003795430668,5.5559131930261,0.000388384936377406,5,52,25,4369,0
,10236670.6860547,149.998808984375,0.07,0.199208755372504,10,10.0004080549069,3.36903600347996,-0.000468298967462033,5,7,25,4369,0
,10236674.2557032,149.998322656251,0.07,0.199208755372504,10,10.0004080549069,-9.56979384152169,0.00033805932616815,5,90,25,4369,0
,10236698.1775781,150.001217187501,0.07,0.199208755372504,30,10.0003985509341,8.03239543391837,0.000359658733941615,5,45,25,4369,0
,10236722.455,149.99345,0.07,0.199208755372504,50,10.0003795430668,0,-0.000478951400145888,5,0,25,4369,0
,10236726.1673046,149.997956640624,0.07,0.199208755372504,50,10.0003795430668,-8.03238016665625,0.00038328287191689,5,83,25,4369,0
,10236761.1988282,149.99947265625,0.07,0.199208755372504,10,10.0004080549069,9.56979384152169,9.55059658735991E-5,5,38,25,4369,0
,10236764.4507423,149.999958984374,0.07,0.199208755372504,10,10.0004080549069,-3.36903600347996,-0.000452892563771457,5,121,25,4369,0
,10236788.6598437,150.0006578125,0.07,0.199208755372504,30,10.0003985509341,-5.55592375323133,0.000394545818885996,5,76,25,4369,0
,10236813.0372265,150.00005,0.07,0.199208755372504,50,10.0003795430668,9.98833364794231,-7.30399508029222E-5,5,31,25,4369,0
,10236816.8986718,150.00005,0.07,0.199208755372504,50,10.0003795430668,-6.3441736212091,-0.000407575676217675,5,114,25,4369,0
,10236847.0876562,150.001731640626,0.07,0.199208755372504,10,10.0004080549069,-2.42990094828733,0.000416217080783099,5,69,25,4369,0
,10236871.0209375,149.999075,0.07,0.199208755372504,30,10.0003985509341,9.23916353816351,-0.000248056344894899,5,24,25,4369,0
,10236874.5516796,150.000371875,0.07,0.199208755372504,30,10.0003985509341,-8.57762794854141,-0.000200515431869361,5,107,25,4369,0
,10236899.4729687,149.9962234375,0.07,0.199208755372504,50,10.0003795430668,0.980208605021647,0.000409846985712648,5,62,25,4369,0
,10236935.5379297,149.9985734375,0.07,0.199208755372504,10,10.0004080549069,7.40981360229206,-0.000457195565104485,5,17,25,4369,0
,10236938.9454688,149.998443750001,0.07,0.199208755372504,10,10.0004080549069,-9.80825301827858,3.48270987160503E-5,5,100,25,4369,0
,10236962.5982422,150.00032890625,0.07,0.199208755372504,30,10.0003985509341,4.27572133678467,0.000399948071895374,5,55,25,4369,0
,10236987.1538281,149.99996640625,0.07,0.199208755372504,50,10.0003795430668,4.71414628362317,-0.000478019425645471,5,10,25,4369,0
,10236990.6716015,150.000517578125,0.07,0.199208755372504,50,10.0003795430668,-9.89214053473404,0.000206332188099623,5,93,25,4369,0
,10237026.870625,149.997793749999,0.07,0.199208755372504,10,10.0004080549069,7.07135635025724,0.000365642772521824,5,48,25,4369,0
,10237050.9967578,150.000332421875,0.07,0.199208755372504,30,10.0003985509341,1.46736322412127,-0.000478021942803429,5,3,25,4369,0
,10237054.3653906,149.99984609375,0.07,0.199208755372504,30,10.0003985509341,-8.81956413402722,0.000357734906073245,5,86,25,4369,0
,10237077.9189063,150.0002140625,0.07,0.199208755372504,50,10.0003795430668,9.04023603410313,0.000253144931048155,5,41,25,4369,0
,10237081.459375,150.000343749999,0.07,0.199208755372504,50,10.0003795430668,-1.95097726534041,-0.000477866223081946,5,124,25,4369,0
,10237113.3973047,150.000257812499,0.07,0.199208755372504,10,10.0004080549069,-6.71586358139698,0.000411456276196987,5,79,25,4369,0
,10237136.8532031,150.0002796875,0.07,0.199208755372504,30,10.0003985509341,9.95224389852435,5.34819749494398E-5,5,34,25,4369,0
,10237140.6692578,150.00047421875,0.07,0.199208755372504,30,10.0003985509341,-5.14123233806112,-0.000460824877437618,5,117,25,4369,0
,10237166.056875,149.999012499999,0.07,0.199208755372504,50,10.0003795430668,-3.82697956849444,0.000408792309463024,5,72,25,4369,0
,10237195.7241406,149.999311328125,0.07,0.199208755372504,10,10.0004080549069,9.70070835795815,-0.000229229044634849,5,27,25,4369,0
,10237199.3489062,150.000575781251,0.07,0.199208755372504,10,10.0004080549069,-7.73041996433595,-0.000212407612707466,5,110,25,4369,0
,10237223.941211,149.999163671875,0.07,0.199208755372504,30,10.0003985509341,-0.490696299241617,0.000416275385456781,5,65,25,4369,0
,10237247.844375,149.99933125,0.07,0.199208755372504,50,10.0003795430668,8.31501170155209,-0.000428105471655727,5,20,25,4369,0
,10237251.0995312,149.999460937499,0.07,0.199208755372504,50,10.0003795430668,-9.41579800835226,-8.18667467683556E-5,5,103,25,4369,0
,10237281.8260937,150.001923437501,0.07,0.199208755372504,10,10.0004080549069,2.90296522463157,0.000395478855352849,5,58,25,4369,0
,10237306.7675391,149.999605078125,0.07,0.199208755372504,30,10.0003985509341,5.95723046143856,-0.000468557765189972,5,13,25,4369,0
,10237310.5187501,149.999637499999,0.07,0.199208755372504,30,10.0003985509341,-10.0003985509341,6.40171088485258E-5,5,96,25,4369,0
,10237335.1803906,149.999141015624,0.07,0.199208755372504,50,10.0003795430668,5.95721913846527,0.000386056443676353,5,51,25,4369,0
,10237370.2421094,150.00003125,0.07,0.199208755372504,10,10.0004080549069,2.90296522463157,-0.000494048290420324,5,6,25,4369,0
,10237374.0062891,149.999771874999,0.07,0.199208755372504,10,10.0004080549069,-9.41582485350607,0.000370305788237602,5,89,25,4369,0
,10237397.458125,150.000673437501,0.07,0.199208755372504,30,10.0003985509341,8.31502750601608,0.000358460108853049,5,44,25,4369,0
,10237400.9726563,150.001094921877,0.07,0.199208755372504,30,10.0003985509341,-0.490696299241616,-0.000482645830036037,5,127,25,4369,0
,10237425.0442188,150.000370312499,0.07,0.199208755372504,50,10.0003795430668,-7.73039792438554,0.000389402685686945,5,82,25,4369,0
,10237456.1683203,150.0003046875,0.07,0.199208755372504,10,10.0004080549069,9.70070835795815,6.50098081678151E-5,5,37,25,4369,0
,10237459.8546874,149.997062499999,0.07,0.199208755372504,10,10.0004080549069,-3.82699047950326,-0.00045090913772583,5,120,25,4369,0
,10237484.2684376,150.00172421875,0.07,0.199208755372504,30,10.0003985509341,-5.14123233806112,0.000398785858932469,5,75,25,4369,0
,10237508.2226563,149.99299140625,0.07,0.199208755372504,50,10.0003795430668,9.9522249821852,-0.000101073319092392,5,30,25,4369,0
,10237511.7436719,149.992829296874,0.07,0.199208755372504,50,10.0003795430668,-6.71584443401547,-0.000379198417067528,5,113,25,4369,0
,10237547.7928125,149.999365624999,0.07,0.199208755372504,10,10.0004080549069,-1.95098282772447,0.000406761828344315,5,68,25,4369,0
,10237571.3998047,150.001703515625,0.07,0.199208755372504,30,10.0003985509341,9.04025321701159,-0.000283723089119627,5,23,25,4369,0
,10237574.9175781,150.000633593751,0.07,0.199208755372504,30,10.0003985509341,-8.81956413402722,-0.000182418152689933,5,106,25,4369,0
,10237599.0801954,149.99969296875,0.07,0.199208755372504,50,10.0003795430668,1.46736043508789,0.000408853869885206,5,61,25,4369,0
,10237634.883125,150.00125,0.07,0.199208755372504,10,10.0004080549069,7.07135635025724,-0.000466400815639645,5,16,25,4369,0
,10237638.4527735,150.0002125,0.07,0.199208755372504,10,10.0004080549069,-9.89216873797649,6.70921872369947E-5,5,99,25,4369,0
,10237663.6002344,149.9999046875,0.07,0.199208755372504,30,10.0003985509341,4.71415524386975,0.000402096581334869,5,54,25,4369,0
,10237687.5442188,149.9995,0.07,0.199208755372504,50,10.0003795430668,4.27571320987422,-0.00047960109077394,5,9,25,4369,0
,10237690.903125,149.995350000001,0.07,0.199208755372504,50,10.0003795430668,-9.80822505428553,0.000246810214594007,5,92,25,4369,0
,10237726.8533594,149.999006249999,0.07,0.199208755372504,10,10.0004080549069,7.40981360229206,0.000341323320753873,5,47,25,4369,0
,10237752.3960937,150.0090328125,0.07,0.199208755372504,30,10.0003985509341,0.980210468118438,-0.000482205133367744,5,2,25,4369,0
,10237755.9689844,150.00416953125,0.07,0.199208755372504,30,10.0003985509341,-8.57762794854141,0.000368943049882849,5,85,25,4369,0
,10237779.6428125,149.99975,0.07,0.199208755372504,50,10.0003795430668,9.23914597718402,0.00021729008294642,5,40,25,4369,0
,10237783.0827735,149.99975,0.07,0.199208755372504,50,10.0003795430668,-2.4298940204753,-0.000477782776579261,5,123,25,4369,0
,10237818.0192968,149.99971875,0.07,0.199208755372504,10,10.0004080549069,-6.34419170892896,0.000396948598790914,5,78,25,4369,0
,10237841.9083594,150.0007,0.07,0.199208755372504,30,10.0003985509341,9.98835263291373,2.13276750097673E-5,5,33,25,4369,0
,10237845.2996875,150.0007,0.07,0.199208755372504,30,10.0003985509341,-5.55592375323133,-0.000455348894724415,5,116,25,4369,0
,10237870.0614844,149.999766796875,0.07,0.199208755372504,50,10.0003795430668,-3.36902639813034,0.000407655397430063,5,71,25,4369,0
,10237906.5810156,149.999753125,0.07,0.199208755372504,10,10.0004080549069,9.56979384152169,-0.000279886589851231,5,26,25,4369,0
,10237910.1117578,150.0004015625,0.07,0.199208755372504,10,10.0004080549069,-8.03240306758092,-0.000181533396244049,5,109,25,4369,0
,10237935.12,149.996850000001,0.07,0.199208755372504,30,10.0003985509341,1.22465516062299E-15,0.000410590437240899,5,64,25,4369,0
,10237960.2141797,149.999844140625,0.07,0.199208755372504,50,10.0003795430668,8.03238016665625,-0.000441368017345667,5,19,25,4369,0
,10237963.7708593,149.999163281251,0.07,0.199208755372504,50,10.0003795430668,-9.56976655739189,-5.81035390496251E-5,5,102,25,4369,0
,10237997.7451172,150.001724609376,0.07,0.199208755372504,10,10.0004080549069,3.36903600347996,0.000408478081226348,5,57,25,4369,0
,10238021.9860937,149.9993171875,0.07,0.199208755372504,30,10.0003985509341,5.55592375323133,-0.000468695782021516,5,12,25,4369,0
,10238025.6594922,150.000127734376,0.07,0.199208755372504,30,10.0003985509341,-9.98835263291373,0.000101364696294897,5,95,25,4369,0
,10238049.6597656,149.999987499999,0.07,0.199208755372504,50,10.0003795430668,6.34417362120911,0.000380403082817793,5,50,25,4369,0
,10238079.7304297,149.999109765625,0.07,0.199208755372504,10,10.0004080549069,2.42990094828733,-0.000475163978990168,5,5,25,4369,0
,10238082.8915625,149.999271875001,0.07,0.199208755372504,10,10.0004080549069,-9.23917231868949,0.000371219648513943,5,88,25,4369,0
,10238106.1187891,150.00066484375,0.07,0.199208755372504,30,10.0003985509341,8.57762794854141,0.000341444198663036,5,43,25,4369,0
,10238109.5522657,150.000210937499,0.07,0.199208755372504,30,10.0003985509341,-0.980210468118437,-0.000480863446783688,5,126,25,4369,0
,10238134.0927734,150.00135,0.07,0.199208755372504,50,10.0003795430668,-7.40979247641208,0.000389613723382354,5,81,25,4369,0
,10238166.8121875,150.0000828125,0.07,0.199208755372504,10,10.0004080549069,9.80825301827859,3.84380109608176E-5,5,36,25,4369,0
,10238170.2294531,150.000504296877,0.07,0.199208755372504,10,10.0004080549069,-4.27572540025666,-0.000464032636955381,5,119,25,4369,0
,10238194.9717187,149.99835859375,0.07,0.199208755372504,30,10.0003985509341,-4.71415524386975,0.00040241685282025,5,74,25,4369,0
,10238218.1876953,150.000748046875,0.07,0.199208755372504,50,10.0003795430668,9.89214053473404,-0.000132662802934647,5,29,25,4369,0
,10238221.7443749,150.00045625,0.07,0.199208755372504,50,10.0003795430668,-7.07133618934179,-0.000326646445319057,5,112,25,4369,0
,10238257.5630469,149.999854296876,0.07,0.199208755372504,10,10.0004080549069,-1.46736461864371,0.000412965309806168,5,67,25,4369,0
,10238282.2025781,150.000578125,0.07,0.199208755372504,30,10.0003985509341,8.81956413402722,-0.000325745139788422,5,22,25,4369,0
,10238285.5323047,149.9999296875,0.07,0.199208755372504,30,10.0003985509341,-9.04025321701159,-0.000154947241147359,5,105,25,4369,0
,10238309.5145313,149.998957812501,0.07,0.199208755372504,50,10.0003795430668,1.95097726534041,0.000409459928050637,5,60,25,4369,0
,10238346.1408594,149.99985,0.07,0.199208755372504,10,10.0004080549069,6.71586358139698,-0.000475771084893495,5,15,25,4369,0
,10238349.9082812,149.99985,0.07,0.199208755372504,10,10.0004080549069,-9.95225335673296,0.000110164110083133,5,98,25,4369,0
,10238374.0119531,150.00356328125,0.07,0.199208755372504,30,10.0003985509341,5.14123233806112,0.000394893318621649,5,53,25,4369,0
,10238398.175,149.9989875,0.07,0.199208755372504,50,10.0003795430668,3.82697956849444,-0.000477543519809842,5,8,25,4369,0
,10238402.1174999,149.9993765625,0.07,0.199208755372504,50,10.0003795430668,-9.7006807005822,0.000288934540003538,5,91,25,4369,0
,10238436.5847656,150.00100390625,0.07,0.199208755372504,10,10.0004080549069,7.73041996433595,0.000341532577294856,5,46,25,4369,0
,10238461.0554297,149.999851953125,0.07,0.199208755372504,30,10.0003985509341,0.490696299241615,-0.000486483978521493,5,1,25,4369,0
,10238464.8260938,150.000014062501,0.07,0.199208755372504,30,10.0003985509341,-8.31502750601608,0.000381839733260373,5,84,25,4369,0
,10238489.7325391,150.001396875,0.07,0.199208755372504,50,10.0003795430668,9.41579800835227,0.000179894408211112,5,39,25,4369,0
,10238493.3346094,150.00373125,0.07,0.199208755372504,50,10.0003795430668,-2.90295694808129,-0.000471990462392568,5,122,25,4369,0
,10238527.9902344,150.000210546874,0.07,0.199208755372504,10,10.0004080549069,-5.95723612294857,0.000420677242800594,5,77,25,4369,0
,10238551.92375,149.9987125,0.07,0.199208755372504,30,10.0003985509341,10.0003985509341,-7.89063051342977E-6,5,32,25,4369,0
,10238555.1886329,149.997188671876,0.07,0.199208755372504,30,10.0003985509341,-5.95723046143856,-0.000450685102906492,5,115,25,4369,0
,10238579.0774999,150.000972656251,0.07,0.199208755372504,50,10.0003795430668,-2.90295694808129,0.000409275060519576,5,70,25,4369,0
,10238610.701836,149.999454296875,0.07,0.199208755372504,10,10.0004080549069,9.41582485350606,-0.000304775312542916,5,25,25,4369,0
,10238614.4595313,149.997476562501,0.07,0.199208755372504,10,10.0004080549069,-8.31503540828069,-0.000166557147167623,5,108,25,4369,0
,10238639.4153906,150.00115234375,0.07,0.199208755372504,30,10.0003985509341,0.490696299241615,0.000411015611866282,5,63,25,4369,0
,10238664.0505469,149.995865625,0.07,0.199208755372504,50,10.0003795430668,7.73039792438553,-0.000449793506413698,5,18,25,4369,0
,10238667.4191796,149.9975515625,0.07,0.199208755372504,50,10.0003795430668,-9.7006807005822,-3.34778800606727E-5,5,101,25,4369,0
,10238702.32375,149.9987875,0.07,0.199208755372504,10,10.0004080549069,3.82699047950326,0.00039970240322873,5,56,25,4369,0
,10238727.3476953,149.999771484375,0.07,0.199208755372504,30,10.0003985509341,5.14123233806112,-0.000470640693998171,5,11,25,4369,0
,10238730.6125782,149.999933593751,0.07,0.199208755372504,30,10.0003985509341,-9.95224389852435,0.000130238929866917,5,94,25,4369,0
,10238755.6041016,150.00026484375,0.07,0.199208755372504,50,10.0003795430668,6.71584443401547,0.00037552360445261,5,49,25,4369,0
,10238790.6001562,150.0008015625,0.07,0.199208755372504,10,10.0004080549069,1.95098282772447,-0.000480418384540826,5,4,25,4369,0
,10238794.1308984,149.999796484374,0.07,0.199208755372504,10,10.0004080549069,-9.04026180850128,0.000375518575310707,5,87,25,4369,0
,10238818.5739844,150.0000515625,0.07,0.199208755372504,30,10.0003985509341,8.81956413402722,0.000324208910266558,5,42,25,4369,0
,10238822.0204297,149.99985703125,0.07,0.199208755372504,30,10.0003985509341,-1.46736322412126,-0.000482270843349397,5,125,25,4369,0
,10238847.1299999,149.998137500001,0.07,0.199208755372504,50,10.0003795430668,-7.07133618934179,0.000393763883039355,5,80,25,4369,0
,10238881.6907031,149.999640234375,0.07,0.199208755372504,10,10.0004080549069,9.89216873797649,1.36339804157611E-5,5,35,25,4369,0
,10238885.2376563,149.999024218749,0.07,0.199208755372504,10,10.0004080549069,-4.71415972401154,-0.000440534786321223,5,118,25,4369,0
,10238909.3739844,150.001136328125,0.07,0.199208755372504,30,10.0003985509341,-4.27572133678467,0.000410963289646639,5,73,25,4369,0
,10238934.0665625,149.998628125,0.07,0.199208755372504,50,10.0003795430668,9.80822505428553,-0.0001641018781811,5,28,25,4369,0
,10238937.9247657,149.999600781249,0.07,0.199208755372504,50,10.0003795430668,-7.40979247641208,-0.000287761259824037,5,111,25,4369,0
,10238972.716875,150.0015484375,0.07,0.199208755372504,10,10.0004080549069,-0.980211399670677,0.0004189444007352,5,66,25,4369,0
,10238997.0751953,150.00019765625,0.07,0.199208755372504,30,10.0003985509341,8.57762794854141,-0.000376590243023303,5,21,25,4369,0
,10239000.5540625,150.000781249999,0.07,0.199208755372504,30,10.0003985509341,-9.23916353816351,-0.000128670362755657,5,104,25,4369,0
,10239024.8221094,149.99711875,0.07,0.199208755372504,50,10.0003795430668,2.4298940204753,0.000405632145702839,5,59,25,4369,0
,10239060.0251562,149.9991046875,0.07,0.199208755372504,10,10.0004080549069,6.34419170892896,-0.000473478867206722,5,14,25,4369,0
,10239063.4942968,149.999428906249,0.07,0.199208755372504,10,10.0004080549069,-9.98836212543862,0.000121234043035656,5,97,25,4369,0
,10239088.0701562,149.9966125,0.07,0.199208755372504,30,10.0003985509341,5.55592375323133,0.000397367079535292,5,52,25,4369,0
,10239111.1425391,150.00010625,0.07,0.199208755372504,50,10.0003795430668,3.36902639813034,-0.000478346413001418,5,7,25,4369,0
,10239114.8483593,149.999587499999,0.07,0.199208755372504,50,10.0003795430668,-9.56976655739189,0.000326781580224633,5,90,25,4369,0
,10239146.5042188,150.001738671874,0.07,0.199208755372504,10,10.0004080549069,8.03240306758093,0.000323815911542624,5,45,25,4369,0
,10239171.905,149.9981,0.07,0.199208755372504,30,10.0003985509341,0,-0.000488170642509229,5,0,25,4369,0
,10239175.3482031,149.999169921874,0.07,0.199208755372504,30,10.0003985509341,-8.03239543391837,0.000383216603141692,5,83,25,4369,0
,10239200.1615625,150.00031953125,0.07,0.199208755372504,50,10.0003795430668,9.56976655739189,0.00014652363024652,5,38,25,4369,0
,10239203.7798437,149.999379296875,0.07,0.199208755372504,50,10.0003795430668,-3.36902639813034,-0.000466677220538259,5,121,25,4369,0
,10239237.8576562,150.00015625,0.07,0.199208755372504,10,10.0004080549069,-5.55592903335573,0.000403221056330949,5,76,25,4369,0
,10239261.5817578,149.999880078125,0.07,0.199208755372504,30,10.0003985509341,9.98835263291373,-4.08810511645342E-5,5,31,25,4369,0
,10239265.0671094,150.000496093751,0.07,0.199208755372504,30,10.0003985509341,-6.34418567967242,-0.000442081881273124,5,114,25,4369,0
,10239289.0867188,149.998650390626,0.07,0.199208755372504,50,10.0003795430668,-2.4298940204753,0.000412139808759093,5,69,25,4369,0
,10239320.5940625,150.00044375,0.07,0.199208755372504,10,10.0004080549069,9.23917231868949,-0.000341607956215739,5,24,25,4369,0
,10239324.2739453,149.999730468749,0.07,0.199208755372504,10,10.0004080549069,-8.57763610037082,-0.000150305859278887,5,107,25,4369,0
,10239348.7558594,150.00488828125,0.07,0.199208755372504,30,10.0003985509341,0.980210468118436,0.000410839501354429,5,62,25,4369,0
,10239373.8264844,149.99870625,0.07,0.199208755372504,50,10.0003795430668,7.40979247641208,-0.000453949393704534,5,17,25,4369,0
,10239377.3734375,149.999225000001,0.07,0.199208755372504,50,10.0003795430668,-9.80822505428553,-7.61835835874072E-6,5,100,25,4369,0
,10239412.4086328,149.997980859375,0.07,0.199208755372504,10,10.0004080549069,4.27572540025666,0.000405352911911905,5,55,25,4369,0
,10239436.4702344,150.00104453125,0.07,0.199208755372504,30,10.0003985509341,4.71415524386975,-0.00047792227835291,5,10,25,4369,0
,10239439.9166797,150.000169140626,0.07,0.199208755372504,30,10.0003985509341,-9.89215933686981,0.000166317266929481,5,93,25,4369,0
,10239464.286875,149.99854375,0.07,0.199208755372504,50,10.0003795430668,7.07133618934179,0.000368933007121086,5,48,25,4369,0
,10239499.5714062,150.00015,0.07,0.199208755372504,10,10.0004080549069,1.46736461864371,-0.000486794742755592,5,3,25,4369,0
,10239502.9303125,150.00015,0.07,0.199208755372504,10,10.0004080549069,-8.81957251578296,0.000383041042368859,5,86,25,4369,0
,10239528.0723437,149.99955546875,0.07,0.199208755372504,30,10.0003985509341,9.04025321701159,0.000295074035724004,5,41,25,4369,0
,10239531.6906249,149.998453124999,0.07,0.199208755372504,30,10.0003985509341,-1.95098097359134,-0.000483603216707706,5,124,25,4369,0
,10239556.5367578,149.999310546875,0.07,0.199208755372504,50,10.0003795430668,-6.71584443401547,0.00039496123790741,5,79,25,4369,0
,10239591.0857031,150.00037265625,0.07,0.199208755372504,10,10.0004080549069,9.95225335673296,-3.09155439026651E-5,5,34,25,4369,0
,10239594.3830078,150.000794140627,0.07,0.199208755372504,10,10.0004080549069,-5.14123722407964,-0.000415125396102667,5,117,25,4369,0
,10239618.9075,149.99991875,0.07,0.199208755372504,30,10.0003985509341,-3.82698684249031,0.000407007691036496,5,72,25,4369,0
,10239643.6685156,149.998223046875,0.07,0.199208755372504,50,10.0003795430668,9.7006807005822,-0.000193781172856689,5,27,25,4369,0
,10239647.1376562,149.997217968749,0.07,0.199208755372504,50,10.0003795430668,-7.73039792438553,-0.000251160562038422,5,110,25,4369,0
,10239682.0461719,150.000366015625,0.07,0.199208755372504,10,10.0004080549069,-0.490696765579461,0.000410611391998828,5,65,25,4369,0
,10239705.61125,150.003628125,0.07,0.199208755372504,30,10.0003985509341,8.31502750601608,-0.000415038278636833,5,20,25,4369,0
,10239708.8534375,150.004989843751,0.07,0.199208755372504,30,10.0003985509341,-9.41581590509684,-0.00010981444372899,5,103,25,4369,0
,10239733.5107031,149.9984859375,0.07,0.199208755372504,50,10.0003795430668,2.90295694808128,0.000406317925080657,5,58,25,4369,0
,10239765.765625,149.9997875,0.07,0.199208755372504,10,10.0004080549069,5.95723612294857,-0.000480789749417454,5,13,25,4369,0
,10239769.345,149.99875,0.07,0.199208755372504,10,10.0004080549069,-10.0004080549069,0.000156883324962109,5,96,25,4369,0
,10239793.8167969,150.000161328125,0.07,0.199208755372504,30,10.0003985509341,5.95723046143856,0.000390977365896106,5,51,25,4369,0
,10239818.673125,150.003353125,0.07,0.199208755372504,50,10.0003795430668,2.90295694808128,-0.000477790413424373,5,6,25,4369,0
,10239822.1746876,150.0006296875,0.07,0.199208755372504,50,10.0003795430668,-9.41579800835227,0.000347746722400189,5,89,25,4369,0
,10239857.2470312,150.0006140625,0.07,0.199208755372504,10,10.0004080549069,8.31503540828069,0.000285222195088863,5,44,25,4369,0
,10239861.1084765,150.000451953124,0.07,0.199208755372504,10,10.0004080549069,-0.49069676557946,-0.000500392052344979,5,127,25,4369,0
,10239884.5534375,150.00089453125,0.07,0.199208755372504,30,10.0003985509341,-7.7304126176656,0.000382644292484555,5,82,25,4369,0
,10239908.7319141,149.999822265625,0.07,0.199208755372504,50,10.0003795430668,9.7006807005822,0.000116085028275847,5,37,25,4369,0
,10239912.5609375,149.999984375001,0.07,0.199208755372504,50,10.0003795430668,-3.82697956849444,-0.00046657701022923,5,120,25,4369,0
,10239943.1187891,150.000005859374,0.07,0.199208755372504,10,10.0004080549069,-5.14123722407963,0.000412573281209916,5,75,25,4369,0
,10239967.4760937,149.99964375,0.07,0.199208755372504,30,10.0003985509341,9.95224389852435,-7.27655262582835E-5,5,30,25,4369,0
,10239971.0619531,149.999903125001,0.07,0.199208755372504,30,10.0003985509341,-6.71585719891892,-0.000415875304800769,5,113,25,4369,0
,10239994.4432813,149.9997125,0.07,0.199208755372504,50,10.0003795430668,-1.95097726534041,0.000412916159257293,5,68,25,4369,0
,10240031.0084375,150.000191015625,0.07,0.199208755372504,10,10.0004080549069,9.04026180850127,-0.000367231841664761,5,23,25,4369,0
,10240034.6656251,150.000158593751,0.07,0.199208755372504,10,10.0004080549069,-8.81957251578297,-0.000111720291897655,5,106,25,4369,0
,10240058.2224609,149.999670703124,0.07,0.199208755372504,30,10.0003985509341,1.46736322412127,0.000405556315349208,5,61,25,4369,0
,10240083.52,150.0007625,0.07,0.199208755372504,50,10.0003795430668,7.07133618934179,-0.000462550157681107,5,16,25,4369,0
,10240087.3068749,150.00030859375,0.07,0.199208755372504,50,10.0003795430668,-9.89214053473404,2.20559537410741E-5,5,99,25,4369,0
,10240122.1995312,149.9929578125,0.07,0.199208755372504,10,10.0004080549069,4.71415972401154,0.000401610741391778,5,54,25,4369,0
,10240145.9378516,150.001106640625,0.07,0.199208755372504,30,10.0003985509341,4.27572133678467,-0.00047319238850226,5,9,25,4369,0
,10240149.4685937,149.9993234375,0.07,0.199208755372504,30,10.0003985509341,-9.80824369692192,0.000197851719955603,5,92,25,4369,0
,10240174.2007422,150.003275390625,0.07,0.199208755372504,50,10.0003795430668,7.40979247641208,0.000365044036880135,5,47,25,4369,0
,10240210.3217188,150.0009703125,0.07,0.199208755372504,10,10.0004080549069,0.980211399670678,-0.000485526979900897,5,2,25,4369,0
,10240213.5055469,150.00181328125,0.07,0.199208755372504,10,10.0004080549069,-8.57763610037082,0.000383986625820398,5,85,25,4369,0
,10240237.46625,149.99905,0.07,0.199208755372504,30,10.0003985509341,9.23916353816351,0.000254362433527907,5,40,25,4369,0
,10240240.8510938,150.0000875,0.07,0.199208755372504,30,10.0003985509341,-2.4298986390103,-0.000476951956645482,5,123,25,4369,0
,10240265.6985937,150.000039843749,0.07,0.199208755372504,50,10.0003795430668,-6.34417362120911,0.000399018963798881,5,78,25,4369,0
,10240296.186914,149.999058984375,0.07,0.199208755372504,10,10.0004080549069,9.98836212543862,-4.60862065665424E-5,5,33,25,4369,0
,10240299.5620312,149.996692187501,0.07,0.199208755372504,10,10.0004080549069,-5.55592903335573,-0.000406947219744325,5,116,25,4369,0
,10240323.2465625,150.0012125,0.07,0.199208755372504,30,10.0003985509341,-3.36903280168795,0.000406337268133131,5,71,25,4369,0
,10240347.0739063,149.9995140625,0.07,0.199208755372504,50,10.0003795430668,9.56976655739189,-0.000225876737385988,5,26,25,4369,0
,10240350.5819532,150.00035703125,0.07,0.199208755372504,50,10.0003795430668,-8.03238016665625,-0.000223023118451238,5,109,25,4369,0
,10240382.3275,150.0021,0.07,0.199208755372504,10,10.0004080549069,1.22465632448555E-15,0.000428013154305517,5,64,25,4369,0
,10240407.1528516,149.99997421875,0.07,0.199208755372504,30,10.0003985509341,8.03239543391837,-0.00043578310093532,5,19,25,4369,0
,10240411.0532032,150.000298437499,0.07,0.199208755372504,30,10.0003985509341,-9.56978474678674,-8.7444204837084E-5,5,102,25,4369,0
,10240435.2957813,149.998805078125,0.07,0.199208755372504,50,10.0003795430668,3.36902639813034,0.000405540177598595,5,57,25,4369,0
,10240470.7775,150.000909375,0.07,0.199208755372504,10,10.0004080549069,5.55592903335573,-0.000472580140922218,5,12,25,4369,0
,10240474.149375,149.999936718751,0.07,0.199208755372504,10,10.0004080549069,-9.98836212543862,0.000188529375009238,5,95,25,4369,0
,10240499.1999219,149.995253906251,0.07,0.199208755372504,30,10.0003985509341,6.34418567967242,0.000388507873544263,5,50,25,4369,0
,10240523.3753906,150.001634375,0.07,0.199208755372504,50,10.0003795430668,2.4298940204753,-0.000480960821732879,5,5,25,4369,0
,10240527.116875,150.001374999999,0.07,0.199208755372504,50,10.0003795430668,-9.23914597718402,0.000359034491702914,5,88,25,4369,0
,10240561.61375,150.002076953125,0.07,0.199208755372504,10,10.0004080549069,8.57763610037082,0.000255649792961776,5,43,25,4369,0
,10240565.4525001,150.00048828125,0.07,0.199208755372504,10,10.0004080549069,-0.980211399670677,-0.000453733955509961,5,126,25,4369,0
,10240590.5647656,149.999784765625,0.07,0.199208755372504,30,10.0003985509341,-7.4098065603127,0.000390134907017152,5,81,25,4369,0
,10240614.8473437,149.9992046875,0.07,0.199208755372504,50,10.0003795430668,9.80822505428553,8.44395253807307E-5,5,36,25,4369,0
,10240618.241914,149.999561328126,0.07,0.199208755372504,50,10.0003795430668,-4.27571320987422,-0.000459846388548613,5,119,25,4369,0
,10240653.3264844,150.00008671875,0.07,0.199208755372504,10,10.0004080549069,-4.71415972401153,0.000421548611484468,5,74,25,4369,0
,10240677.8810547,150.000698046875,0.07,0.199208755372504,30,10.0003985509341,9.89215933686981,-0.000105318289974497,5,29,25,4369,0
,10240681.2756249,150.00040625,0.07,0.199208755372504,30,10.0003985509341,-7.0713496299336,-0.000374995547139811,5,112,25,4369,0
,10240705.4367969,149.999823828126,0.07,0.199208755372504,50,10.0003795430668,-1.46736043508789,0.000413819355890155,5,67,25,4369,0
,10240740.5180469,150.00249296875,0.07,0.199208755372504,10,10.0004080549069,8.81957251578297,-0.000401991710532456,5,22,25,4369,0
,10240744.1136329,150.002655078126,0.07,0.199208755372504,10,10.0004080549069,-9.04026180850127,-8.49610660225156E-5,5,105,25,4369,0
,10240769.1979687,149.9993875,0.07,0.199208755372504,30,10.0003985509341,1.95098097359135,0.00041257842288663,5,60,25,4369,0
,10240793.0996094,150.000384765625,0.07,0.199208755372504,50,10.0003795430668,6.71584443401547,-0.000463757896795869,5,15,25,4369,0
,10240796.9707813,149.996980468751,0.07,0.199208755372504,50,10.0003795430668,-9.9522249821852,4.66375611722469E-5,5,98,25,4369,0
,10240832.1344532,150.00121015625,0.07,0.199208755372504,10,10.0004080549069,5.14123722407964,0.000409417261835188,5,53,25,4369,0
,10240856.99875,150.003628125,0.07,0.199208755372504,30,10.0003985509341,3.82698684249032,-0.000474482852344712,5,8,25,4369,0
,10240860.5132813,150.005476171876,0.07,0.199208755372504,30,10.0003985509341,-9.70069913880747,0.000245893994967142,5,91,25,4369,0
,10240884.0297656,149.998428125001,0.07,0.199208755372504,50,10.0003795430668,7.73039792438553,0.000358995655551553,5,46,25,4369,0
,10240919.6478516,149.996300390625,0.07,0.199208755372504,10,10.0004080549069,0.490696765579459,-0.000495195854455233,5,1,25,4369,0
,10240923.2045312,149.996332812499,0.07,0.199208755372504,10,10.0004080549069,-8.31503540828069,0.000397243129555136,5,84,25,4369,0
,10240947.8860156,150.001197656251,0.07,0.199208755372504,30,10.0003985509341,9.41581590509684,0.000209408657004436,5,39,25,4369,0
,10240951.4848437,150.000873437502,0.07,0.199208755372504,30,10.0003985509341,-2.90296246577389,-0.000471659457414515,5,122,25,4369,0
,10240976.0526173,149.998970703125,0.07,0.199208755372504,50,10.0003795430668,-5.95721913846527,0.000400598952546716,5,77,25,4369,0
,10241010.84375,150.0002625,0.07,0.199208755372504,10,10.0004080549069,10.0004080549069,-8.6012296378613E-5,5,32,25,4369,0
,10241014.1475391,149.999776171876,0.07,0.199208755372504,10,10.0004080549069,-5.95723612294856,-0.000377992400899529,5,115,25,4369,0
,10241039.7426563,150.00036484375,0.07,0.199208755372504,30,10.0003985509341,-2.90296246577389,0.00040830229409039,5,70,25,4369,0
,10241063.8242187,149.999931640625,0.07,0.199208755372504,50,10.0003795430668,9.41579800835227,-0.000258839968591929,5,25,25,4369,0
,10241067.390625,149.999704687501,0.07,0.199208755372504,50,10.0003795430668,-8.31501170155209,-0.000196907995268702,5,108,25,4369,0
,10241102.0412891,150.000175390626,0.07,0.199208755372504,10,10.0004080549069,0.490696765579459,0.000410575303249061,5,63,25,4369,0
,10241125.8698438,150.00051484375,0.07,0.199208755372504,30,10.0003985509341,7.73041261766559,-0.000444125422897438,5,18,25,4369,0
,10241129.2352344,150.000352734374,0.07,0.199208755372504,30,10.0003985509341,-9.70069913880747,-5.87318532375826E-5,5,101,25,4369,0
,10241153.71875,149.998765625,0.07,0.199208755372504,50,10.0003795430668,3.82697956849445,0.000402290653437376,5,56,25,4369,0
,10241185.5202734,150.000361328125,0.07,0.199208755372504,10,10.0004080549069,5.14123722407964,-0.000475320848636329,5,11,25,4369,0
,10241188.8046094,150.00006953125,0.07,0.199208755372504,10,10.0004080549069,-9.95225335673296,0.000214717874769122,5,94,25,4369,0
,10241212.5104688,149.99572265625,0.07,0.199208755372504,30,10.0003985509341,6.71585719891891,0.000378675823513832,5,49,25,4369,0
,10241236.8665625,150.00073125,0.07,0.199208755372504,50,10.0003795430668,1.95097726534041,-0.00048139076679945,5,4,25,4369,0
,10241240.5302344,149.999304687501,0.07,0.199208755372504,50,10.0003795430668,-9.04023603410313,0.00036535388790071,5,87,25,4369,0
,10241271.584375,150.006275,0.07,0.199208755372504,10,10.0004080549069,8.81957251578296,0.00021846208255738,5,42,25,4369,0
,10241275.1896874,150.0052375,0.07,0.199208755372504,10,10.0004080549069,-1.46736461864371,-0.000474418047815562,5,125,25,4369,0
,10241299.4056249,149.999781250001,0.07,0.199208755372504,30,10.0003985509341,-7.0713496299336,0.000387019374304348,5,80,25,4369,0
,10241322.8559765,149.99974921875,0.07,0.199208755372504,50,10.0003795430668,9.89214053473404,5.1505770534277E-5,5,35,25,4369,0
,10241326.237578,149.999035937499,0.07,0.199208755372504,50,10.0003795430668,-4.71414628362317,-0.000455889292061329,5,118,25,4369,0
,10241357.6566406,150.000709375,0.07,0.199208755372504,10,10.0004080549069,-4.27572540025667,0.000416174298152328,5,73,25,4369,0
,10241381.4390625,150.000384375,0.07,0.199208755372504,30,10.0003985509341,9.80824369692192,-0.000133948698122468,5,28,25,4369,0
,10241385.0378906,150.00018984375,0.07,0.199208755372504,30,10.0003985509341,-7.40980656031269,-0.000323409331031143,5,111,25,4369,0
,10241409.4592188,149.9961,0.07,0.199208755372504,50,10.0003795430668,-0.980208605021649,0.000412614829838276,5,66,25,4369,0
,10241440.1778125,149.999646875,0.07,0.199208755372504,10,10.0004080549069,8.57763610037082,-0.000438075221609324,5,21,25,4369,0
,10241443.6274999,150.000424999999,0.07,0.199208755372504,10,10.0004080549069,-9.23917231868949,-6.25752727501095E-5,5,104,25,4369,0
,10241467.423125,150.002464453125,0.07,0.199208755372504,30,10.0003985509341,2.4298986390103,0.000408512100370394,5,59,25,4369,0
,10241492.2871875,149.99818046875,0.07,0.199208755372504,50,10.0003795430668,6.34417362120911,-0.000463184295222163,5,14,25,4369,0
,10241495.8276563,149.999250390624,0.07,0.199208755372504,50,10.0003795430668,-9.98833364794231,7.32413958758112E-5,5,97,25,4369,0
,10241526.6198438,150.00155625,0.07,0.199208755372504,10,10.0004080549069,5.55592903335573,0.00039053411455825,5,52,25,4369,0
,10241552.0246094,149.99917734375,0.07,0.199208755372504,30,10.0003985509341,3.36903280168794,-0.000475881776461999,5,7,25,4369,0
,10241555.6364062,149.999501562499,0.07,0.199208755372504,30,10.0003985509341,-9.56978474678673,0.000296379116156863,5,90,25,4369,0
,10241580.1942187,150.001077734375,0.07,0.199208755372504,50,10.0003795430668,8.03238016665625,0.000347012048587203,5,45,25,4369,0
,10241583.5639062,149.999123828126,0.07,0.199208755372504,50,10.0003795430668,-0.490695366569778,-0.000478748930618167,5,127,25,4369,0