File: dados/200k5p.raw
[Header]
; ACMS Raw Data File (default extension .raw)
; Copyright 1999, Quantum Design, Inc. All rights reserved.
TITLE,Xac-time_200K_5point_microfios-FeSiB_hac_10Oe_f_10Hz_29-04-24
FILEOPENTIME,10314900.61,04/29/2024,1:13 pm
BYAPP,ACMS,1.0,1.1,RAW
INFO,PPMS ACMS Option Version: 1.0.9 Build 14,APPNAME
INFO,HARMONICS,1
DATATYPE,COMMENT,1
DATATYPE,TIME,2
STARTUPAXIS,X,2,LINEAR,AUTO
STARTUPAXIS,Y,7,LINEAR,AUTO
STARTUPAXIS,Y,8,LINEAR,AUTO
TIMEMODE,MINUTES,RELATIVE
PLOT_APPEARANCE,ALL,HORZ_GRID_ON,VERT_GRID_ON,MARKERS_AND_LINES
RECORDS,ALL_RECORDS
DATATYPE,TIME,2
DATATYPE,COMMENT,1
[Data]
Comment,Time Stamp (sec),Temperature (K),Magnetic Field (Oe),Position (cm),Frequency (Hz),Amplitude (Oe),Drive (Oe),Signal (mV),Measure Type,Bin,Gain,PPMS Status (code),DSP Status (code)
,10314877.765,199.99965,0.07,0.199208755372504,10,10.0004080549069,0,-0.000818064436316491,5,0,25,4369,0
,10314881.3875,200.008673437499,0.07,0.199208755372504,10,10.0004080549069,-8.31503540828069,0.000714490888640286,5,84,25,4369,0
,10314905.5171875,200.029221874999,0.07,0.199208755372504,30,10.0003985509341,9.23916353816351,0.000552265684948199,5,40,25,4369,0
,10314909.2282812,200.016982812498,0.07,0.199208755372504,30,10.0003985509341,-1.95098097359134,-0.000789024828312297,5,124,25,4369,0
,10314932.76875,200.0217875,0.07,0.199208755372504,50,10.0003795430668,-7.07133618934179,0.000687811616808176,5,80,25,4369,0
,10314963.6067188,200.0113390625,0.07,0.199208755372504,10,10.0004080549069,9.80825301827859,8.39529093354895E-6,5,36,25,4369,0
,10314967.2390626,200.008746875001,0.07,0.199208755372504,10,10.0004080549069,-3.82699047950326,-0.000731259933672845,5,120,25,4369,0
,10314992.1559375,199.999712499999,0.07,0.199208755372504,30,10.0003985509341,-5.55592375323133,0.000681564884467257,5,76,25,4369,0
,10315016.36625,199.9984,0.07,0.199208755372504,50,10.0003795430668,10.0003795430668,-0.000175274489447474,5,32,25,4369,0
,10315019.7032813,199.9984,0.07,0.199208755372504,50,10.0003795430668,-5.5559131930261,-0.000689667789265514,5,116,25,4369,0
,10315050.2971875,199.987834375001,0.07,0.199208755372504,10,10.0004080549069,-3.82699047950326,0.000693238689564168,5,72,25,4369,0
,10315074.736875,199.9946,0.07,0.199208755372504,30,10.0003985509341,9.80824369692192,-0.000413942810458441,5,28,25,4369,0
,10315078.3725,199.9946,0.07,0.199208755372504,30,10.0003985509341,-7.0713496299336,-0.000653337984759774,5,112,25,4369,0
,10315103.0867188,199.992257812499,0.07,0.199208755372504,50,10.0003795430668,-1.95097726534041,0.000679865386337042,5,68,25,4369,0
,10315138.3078125,200.00005625,0.07,0.199208755372504,10,10.0004080549069,9.23917231868949,-0.000615536991972476,5,24,25,4369,0
,10315141.8351563,199.998153125,0.07,0.199208755372504,10,10.0004080549069,-8.31503540828069,-0.000408714695367963,5,108,25,4369,0
,10315166.5899999,199.999625000001,0.07,0.199208755372504,30,10.0003985509341,1.22465516062299E-15,0.00066624753849788,5,64,25,4369,0
,10315191.1554687,199.9972875,0.07,0.199208755372504,50,10.0003795430668,8.31501170155209,-0.000642522657290102,5,20,25,4369,0
,10315194.7484374,199.995975,0.07,0.199208755372504,50,10.0003795430668,-9.23914597718402,-0.000255127856507897,5,104,25,4369,0
,10315229.6245313,199.995726562501,0.07,0.199208755372504,10,10.0004080549069,1.95098282772447,0.000652217713650316,5,60,25,4369,0
,10315253.673125,199.99495,0.07,0.199208755372504,30,10.0003985509341,7.0713496299336,-0.000662873240394725,5,16,25,4369,0
,10315257.4957813,200.0020375,0.07,0.199208755372504,30,10.0003985509341,-9.80824369692192,-9.12442596422308E-5,5,100,25,4369,0
,10315281.4253125,200.003021875001,0.07,0.199208755372504,50,10.0003795430668,3.82697956849445,0.000637259194627405,5,56,25,4369,0
,10315318.3196875,199.9979921875,0.07,0.199208755372504,10,10.0004080549069,5.55592903335573,-0.000687988067511469,5,12,25,4369,0
,10315321.9225,199.994087500001,0.07,0.199208755372504,10,10.0004080549069,-10.0004080549069,0.000329849717672914,5,96,25,4369,0
,10315345.0653125,200.0003125,0.07,0.199208755372504,30,10.0003985509341,5.55592375323133,0.000622750958427787,5,52,25,4369,0
,10315369.2975,199.99498125,0.07,0.199208755372504,50,10.0003795430668,3.82697956849444,-0.000695230625569821,5,8,25,4369,0
,10315372.89375,199.998984374999,0.07,0.199208755372504,50,10.0003795430668,-9.80822505428553,0.000498517416417599,5,92,25,4369,0
,10315404.571875,200.00748125,0.07,0.199208755372504,10,10.0004080549069,7.07135635025724,0.000560297630727291,5,48,25,4369,0
,10315428.985625,199.995840625,0.07,0.199208755372504,30,10.0003985509341,1.95098097359135,-0.000696038736754822,5,4,25,4369,0
,10315432.77875,199.99774375,0.07,0.199208755372504,30,10.0003985509341,-9.23916353816351,0.000543099918609692,5,88,25,4369,0
,10315457.9826562,199.995685937501,0.07,0.199208755372504,50,10.0003795430668,8.31501170155208,0.000537516083568335,5,44,25,4369,0
,10315492.28,199.99675,0.07,0.199208755372504,10,10.0004080549069,0,-0.000696350180078299,5,0,25,4369,0
,10315495.7417188,199.997373437501,0.07,0.199208755372504,10,10.0004080549069,-8.31503540828069,0.000593544391449541,5,84,25,4369,0
,10315520.69875,199.992721874999,0.07,0.199208755372504,30,10.0003985509341,9.23916353816351,0.000481872767623928,5,40,25,4369,0
,10315524.465625,199.994657812498,0.07,0.199208755372504,30,10.0003985509341,-1.95098097359134,-0.000688614996357097,5,124,25,4369,0
,10315549.016875,200.007143750001,0.07,0.199208755372504,50,10.0003795430668,-7.07133618934179,0.000614254269748926,5,80,25,4369,0
,10315585.043125,199.9991890625,0.07,0.199208755372504,10,10.0004080549069,9.80825301827859,-7.15663190931615E-7,5,36,25,4369,0
,10315588.78375,200.004996874998,0.07,0.199208755372504,10,10.0004080549069,-3.82699047950326,-0.000647036067675799,5,120,25,4369,0
,10315612.8875,199.9966734375,0.07,0.199208755372504,30,10.0003985509341,-5.55592375323133,0.000629822089750733,5,76,25,4369,0
,10315637.415,199.9938375,0.07,0.199208755372504,50,10.0003795430668,10.0003795430668,-0.000155465677380562,5,32,25,4369,0
,10315640.565,199.994460937501,0.07,0.199208755372504,50,10.0003795430668,-5.5559131930261,-0.00065149962902069,5,116,25,4369,0
,10315675.3409375,200.00155,0.07,0.199208755372504,10,10.0004080549069,-3.82699047950326,0.000655291078146547,5,72,25,4369,0
,10315699.655625,199.9932875,0.07,0.199208755372504,30,10.0003985509341,9.80824369692192,-0.000363335711881518,5,28,25,4369,0
,10315703.5275001,199.9946,0.07,0.199208755372504,30,10.0003985509341,-7.0713496299336,-0.000631552732860049,5,112,25,4369,0
,10315727.6225,200.001357812499,0.07,0.199208755372504,50,10.0003795430668,-1.95097726534041,0.000651826849207282,5,68,25,4369,0
,10315758.7428125,200.00115,0.07,0.199208755372504,10,10.0004080549069,9.23917231868949,-0.000605958630330861,5,24,25,4369,0
,10315762.1126562,200.00955,0.07,0.199208755372504,10,10.0004080549069,-8.31503540828069,-0.000384891754947603,5,108,25,4369,0
,10315786.915,199.9973,0.07,0.199208755372504,30,10.0003985509341,1.22465516062299E-15,0.000658093615331584,5,64,25,4369,0
,10315811.2132813,200.0065,0.07,0.199208755372504,50,10.0003795430668,8.31501170155209,-0.000628844043239951,5,20,25,4369,0
,10315814.7340625,200.0065,0.07,0.199208755372504,50,10.0003795430668,-9.23914597718402,-0.000250759301707148,5,104,25,4369,0
,10315850.7873438,200.002229687501,0.07,0.199208755372504,10,10.0004080549069,1.95098282772447,0.000643982202745974,5,60,25,4369,0
,10315875.255,200.00305625,0.07,0.199208755372504,30,10.0003985509341,7.0713496299336,-0.00065422649236603,5,16,25,4369,0
,10315879.035,200.011489062499,0.07,0.199208755372504,30,10.0003985509341,-9.80824369692192,-8.5642160330381E-5,5,100,25,4369,0
,10315903.9965625,199.995184374999,0.07,0.199208755372504,50,10.0003795430668,3.82697956849445,0.000631050299853086,5,56,25,4369,0
,10315937.8826563,199.9925109375,0.07,0.199208755372504,10,10.0004080549069,5.55592903335573,-0.000681809324305504,5,12,25,4369,0
,10315941.22625,200.000287499999,0.07,0.199208755372504,10,10.0004080549069,-10.0004080549069,0.000320379913318903,5,96,25,4369,0
,10315965.5614062,200.0011875,0.07,0.199208755372504,30,10.0003985509341,5.55592375323133,0.000620221576860382,5,52,25,4369,0
,10315990.03625,199.993184375,0.07,0.199208755372504,50,10.0003795430668,3.82697956849444,-0.000694358302280307,5,8,25,4369,0
,10315993.619375,199.997745312499,0.07,0.199208755372504,50,10.0003795430668,-9.80822505428553,0.000501338811591268,5,92,25,4369,0
,10316025.031875,199.9997,0.07,0.199208755372504,10,10.0004080549069,7.07135635025724,0.000556328159291297,5,48,25,4369,0
,10316049.0084375,200.0006578125,0.07,0.199208755372504,30,10.0003985509341,1.95098097359135,-0.000702902907505631,5,4,25,4369,0
,10316052.8606249,200.007121874999,0.07,0.199208755372504,30,10.0003985509341,-9.23916353816351,0.000550620542425249,5,88,25,4369,0
,10316077.230625,199.998134375,0.07,0.199208755372504,50,10.0003795430668,8.31501170155208,0.00053830505348742,5,44,25,4369,0
,10316112.82,200.01075,0.07,0.199208755372504,10,10.0004080549069,0,-0.000695870548952371,5,0,25,4369,0
,10316116.57375,200.001070312501,0.07,0.199208755372504,10,10.0004080549069,-8.31503540828069,0.000613877491559834,5,84,25,4369,0
,10316140.6921875,200.00295625,0.07,0.199208755372504,30,10.0003985509341,9.23916353816351,0.000485587709893783,5,40,25,4369,0
,10316144.2457812,199.999084375,0.07,0.199208755372504,30,10.0003985509341,-1.95098097359134,-0.000692825867897934,5,124,25,4369,0
,10316167.84375,200.0054125,0.07,0.199208755372504,50,10.0003795430668,-7.07133618934179,0.000620484352111816,5,80,25,4369,0
,10316199.105625,200.00646875,0.07,0.199208755372504,10,10.0004080549069,9.80825301827859,-4.2005558498199E-6,5,36,25,4369,0
,10316203.0037501,199.997412499999,0.07,0.199208755372504,10,10.0004080549069,-3.82699047950326,-0.000670815643388778,5,120,25,4369,0
,10316226.7164063,199.999940625,0.07,0.199208755372504,30,10.0003985509341,-5.55592375323133,0.000634176346162955,5,76,25,4369,0
,10316251.19,200.003775,0.07,0.199208755372504,50,10.0003795430668,10.0003795430668,-0.000162708153948187,5,32,25,4369,0
,10316254.94375,200.006990625,0.07,0.199208755372504,50,10.0003795430668,-5.5559131930261,-0.000651973253116012,5,116,25,4369,0
,10316285.0971876,199.99678125,0.07,0.199208755372504,10,10.0004080549069,-3.82699047950326,0.000647680717520416,5,72,25,4369,0
,10316308.7451562,199.996553125,0.07,0.199208755372504,30,10.0003985509341,9.80824369692192,-0.000385789899155497,5,28,25,4369,0
,10316312.285625,200.0075125,0.07,0.199208755372504,30,10.0003985509341,-7.0713496299336,-0.000638398212484187,5,112,25,4369,0
,10316337.1540625,199.998196875,0.07,0.199208755372504,50,10.0003795430668,-1.95097726534041,0.000658628810197115,5,68,25,4369,0
,10316368.3228125,200.0065,0.07,0.199208755372504,10,10.0004080549069,9.23917231868949,-0.000620329519733787,5,24,25,4369,0
,10316371.6926562,200.0065,0.07,0.199208755372504,10,10.0004080549069,-8.31503540828069,-0.000391891226172447,5,108,25,4369,0
,10316395.895,199.994225000001,0.07,0.199208755372504,30,10.0003985509341,1.22465516062299E-15,0.000660344828955001,5,64,25,4369,0
,10316420.3423437,199.997209375,0.07,0.199208755372504,50,10.0003795430668,8.31501170155209,-0.000639018462970852,5,20,25,4369,0
,10316423.9221874,199.99976875,0.07,0.199208755372504,50,10.0003795430668,-9.23914597718402,-0.000253896461799742,5,104,25,4369,0
,10316455.1603125,199.998860937501,0.07,0.199208755372504,10,10.0004080549069,1.95098282772447,0.000664634280838072,5,60,25,4369,0
,10316478.48875,199.99958125,0.07,0.199208755372504,30,10.0003985509341,7.0713496299336,-0.000661931569791503,5,16,25,4369,0
,10316482.0784375,199.998957812499,0.07,0.199208755372504,30,10.0003985509341,-9.80824369692192,-8.93536748157601E-5,5,100,25,4369,0
,10316506.8640625,199.998409375001,0.07,0.199208755372504,50,10.0003795430668,3.82697956849445,0.000639590295031667,5,56,25,4369,0
,10316543.1389062,199.99370625,0.07,0.199208755372504,10,10.0004080549069,5.55592903335573,-0.000699939555488526,5,12,25,4369,0
,10316547.19125,199.99305,0.07,0.199208755372504,10,10.0004080549069,-10.0004080549069,0.000340293045155704,5,96,25,4369,0
,10316572.6717187,199.99678125,0.07,0.199208755372504,30,10.0003985509341,5.55592375323133,0.00062421061253796,5,52,25,4369,0
,10316597.074375,200.0075,0.07,0.199208755372504,50,10.0003795430668,3.82697956849444,-0.000701215257868171,5,8,25,4369,0
,10316600.5328125,200.0075,0.07,0.199208755372504,50,10.0003795430668,-9.80822505428553,0.000510150613263249,5,92,25,4369,0
,10316634.020625,199.9938625,0.07,0.199208755372504,10,10.0004080549069,7.07135635025724,0.000566060480196029,5,48,25,4369,0
,10316657.29125,199.9936984375,0.07,0.199208755372504,30,10.0003985509341,1.95098097359135,-0.000702574163571828,5,4,25,4369,0
,10316661.3074999,199.993665625001,0.07,0.199208755372504,30,10.0003985509341,-9.23916353816351,0.000555448091795875,5,88,25,4369,0
,10316686.5951563,200.0053125,0.07,0.199208755372504,50,10.0003795430668,8.31501170155208,0.000547364354133606,5,44,25,4369,0
,10316722.045,200.0005,0.07,0.199208755372504,10,10.0004080549069,0,-0.000721023825462907,5,0,25,4369,0
,10316725.470625,200.0005,0.07,0.199208755372504,10,10.0004080549069,-8.31503540828069,0.000605365785304457,5,84,25,4369,0
,10316749.344375,199.998046874999,0.07,0.199208755372504,30,10.0003985509341,9.23916353816351,0.000501825448332562,5,40,25,4369,0
,10316752.8815626,199.992895312498,0.07,0.199208755372504,30,10.0003985509341,-1.95098097359134,-0.000705096689570282,5,124,25,4369,0
,10316777.6550001,199.998631250001,0.07,0.199208755372504,50,10.0003795430668,-7.07133618934179,0.000629300530999899,5,80,25,4369,0
,10316809.2428125,200.004470312501,0.07,0.199208755372504,10,10.0004080549069,9.80825301827859,2.36960477195685E-5,5,36,25,4369,0
,10316812.819375,200.002534375002,0.07,0.199208755372504,10,10.0004080549069,-3.82699047950326,-0.000676480412948876,5,120,25,4369,0
,10316836.5103125,199.99960625,0.07,0.199208755372504,30,10.0003985509341,-5.55592375323133,0.000647405589309831,5,76,25,4369,0
,10316861.56625,200.0017125,0.07,0.199208755372504,50,10.0003795430668,10.0003795430668,-0.000166180869564414,5,32,25,4369,0
,10316865.4545312,199.997151562501,0.07,0.199208755372504,50,10.0003795430668,-5.5559131930261,-0.000661013973876833,5,116,25,4369,0
,10316900.7065626,199.995965625001,0.07,0.199208755372504,10,10.0004080549069,-3.82699047950326,0.000665191910229623,5,72,25,4369,0
,10316924.5525,199.998284375,0.07,0.199208755372504,30,10.0003985509341,9.80824369692192,-0.000406439002189372,5,28,25,4369,0
,10316928.175,199.997037500001,0.07,0.199208755372504,30,10.0003985509341,-7.0713496299336,-0.000641557853668928,5,112,25,4369,0
,10316953.7632812,200.000932812501,0.07,0.199208755372504,50,10.0003795430668,-1.95097726534041,0.000666809780523181,5,68,25,4369,0
,10316988.7390625,199.99975,0.07,0.199208755372504,10,10.0004080549069,9.23917231868949,-0.000620648788753897,5,24,25,4369,0
,10316992.3582813,199.997124999999,0.07,0.199208755372504,10,10.0004080549069,-8.31503540828069,-0.000430445943493397,5,108,25,4369,0
,10317016.7375,199.998024999999,0.07,0.199208755372504,30,10.0003985509341,1.22465516062299E-15,0.000668674215881361,5,64,25,4369,0
,10317040.0382812,199.993225,0.07,0.199208755372504,50,10.0003795430668,8.31501170155209,-0.000644426653161645,5,20,25,4369,0
,10317043.4540624,199.995850000001,0.07,0.199208755372504,50,10.0003795430668,-9.23914597718402,-0.000255657779052853,5,104,25,4369,0
,10317075.7642188,200.0056,0.07,0.199208755372504,10,10.0004080549069,1.95098282772447,0.000655223266221583,5,60,25,4369,0
,10317100.321875,199.9974625,0.07,0.199208755372504,30,10.0003985509341,7.0713496299336,-0.000663562483775118,5,16,25,4369,0
,10317104.0329687,200.000678125,0.07,0.199208755372504,30,10.0003985509341,-9.80824369692192,-8.60056348351971E-5,5,100,25,4369,0
,10317128.2346875,199.994559375001,0.07,0.199208755372504,50,10.0003795430668,3.82697956849445,0.000647872779518366,5,56,25,4369,0
,10317163.428125,200.001478125,0.07,0.199208755372504,10,10.0004080549069,5.55592903335573,-0.000704591220710427,5,12,25,4369,0
,10317167.0899999,199.999575,0.07,0.199208755372504,10,10.0004080549069,-10.0004080549069,0.000347078021150083,5,96,25,4369,0
,10317192.0695313,199.995173437501,0.07,0.199208755372504,30,10.0003985509341,5.55592375323133,0.000636171704779069,5,52,25,4369,0
,10317217.809375,200.009675,0.07,0.199208755372504,50,10.0003795430668,3.82697956849444,-0.000708594592288136,5,8,25,4369,0
,10317221.4778124,200.0025875,0.07,0.199208755372504,50,10.0003795430668,-9.80822505428553,0.000516944890841842,5,92,25,4369,0
,10317254.5325,200.012125,0.07,0.199208755372504,10,10.0004080549069,7.07135635025724,0.000586731475777924,5,48,25,4369,0
,10317279.1276563,200.0038671875,0.07,0.199208755372504,30,10.0003985509341,1.95098097359135,-0.000710017047822475,5,4,25,4369,0
,10317282.7534376,199.991628124999,0.07,0.199208755372504,30,10.0003985509341,-9.23916353816351,0.000559851630694337,5,88,25,4369,0
,10317306.9228125,200.003173437499,0.07,0.199208755372504,50,10.0003795430668,8.31501170155208,0.000552287651225924,5,44,25,4369,0
,10317337.905,199.99635,0.07,0.199208755372504,10,10.0004080549069,0,-0.000717902730684728,5,0,25,4369,0
,10317341.5110937,200.002814062499,0.07,0.199208755372504,10,10.0004080549069,-8.31503540828069,0.000632506853435188,5,84,25,4369,0
,10317366.03625,199.998221875,0.07,0.199208755372504,30,10.0003985509341,9.23916353816351,0.00050742916452388,5,40,25,4369,0
,10317369.776875,199.991757812501,0.07,0.199208755372504,30,10.0003985509341,-1.95098097359134,-0.000710015366267828,5,124,25,4369,0
,10317395.2868749,199.999175,0.07,0.199208755372504,50,10.0003795430668,-7.07133618934179,0.000635965680703521,5,80,25,4369,0
,10317429.6739063,200.0124296875,0.07,0.199208755372504,10,10.0004080549069,9.80825301827859,-7.38655216991899E-6,5,36,25,4369,0
,10317433.8246875,200.000715625,0.07,0.199208755372504,10,10.0004080549069,-3.82699047950326,-0.000685725826770068,5,120,25,4369,0
,10317458.61375,200.001153125,0.07,0.199208755372504,30,10.0003985509341,-5.55592375323133,0.000652407244261768,5,76,25,4369,0
,10317482.3575,199.993475,0.07,0.199208755372504,50,10.0003795430668,10.0003795430668,-0.000168876629322767,5,32,25,4369,0
,10317485.8159375,199.998003125,0.07,0.199208755372504,50,10.0003795430668,-5.5559131930261,-0.000668136868625879,5,116,25,4369,0
,10317520.0003125,200.004303124999,0.07,0.199208755372504,10,10.0004080549069,-3.82699047950326,0.000676257477607579,5,72,25,4369,0
,10317542.7834375,199.9970703125,0.07,0.199208755372504,30,10.0003985509341,9.80824369692192,-0.000423243683245447,5,28,25,4369,0
,10317546.54375,200.001631249999,0.07,0.199208755372504,30,10.0003985509341,-7.0713496299336,-0.000647343436463012,5,112,25,4369,0
,10317570.9339062,200.002984375,0.07,0.199208755372504,50,10.0003795430668,-1.95097726534041,0.000673035113140941,5,68,25,4369,0
,10317603.45375,200.00546875,0.07,0.199208755372504,10,10.0004080549069,9.23917231868949,-0.000620829232502728,5,24,25,4369,0
,10317607.036875,199.994509375,0.07,0.199208755372504,10,10.0004080549069,-8.31503540828069,-0.000425811449531466,5,108,25,4369,0
,10317630.3525,200.00505,0.07,0.199208755372504,30,10.0003985509341,1.22465516062299E-15,0.000676457356247637,5,64,25,4369,0
,10317654.768125,199.9993453125,0.07,0.199208755372504,50,10.0003795430668,8.31501170155209,-0.000649357866495848,5,20,25,4369,0
,10317658.7712499,200.006465624999,0.07,0.199208755372504,50,10.0003795430668,-9.23914597718402,-0.000259605329483748,5,104,25,4369,0
,10317690.2451562,200.00505,0.07,0.199208755372504,10,10.0004080549069,1.95098282772447,0.000649479334242641,5,60,25,4369,0
,10317713.8925,199.99106875,0.07,0.199208755372504,30,10.0003985509341,7.0713496299336,-0.000672573676436312,5,16,25,4369,0
,10317717.370625,200.000092187499,0.07,0.199208755372504,30,10.0003985509341,-9.80824369692192,-9.36811557039615E-5,5,100,25,4369,0
,10317741.615625,200.0070625,0.07,0.199208755372504,50,10.0003795430668,3.82697956849445,0.00065209069289267,5,56,25,4369,0
,10317773.5701562,200.0009703125,0.07,0.199208755372504,10,10.0004080549069,5.55592903335573,-0.000716289214324207,5,12,25,4369,0
,10317777.28125,200.003562499999,0.07,0.199208755372504,10,10.0004080549069,-10.0004080549069,0.00035702280001715,5,96,25,4369,0
,10317801.3276563,200.001957812499,0.07,0.199208755372504,30,10.0003985509341,5.55592375323133,0.000639720625864963,5,52,25,4369,0
,10317824.5196875,200.006328125,0.07,0.199208755372504,50,10.0003795430668,3.82697956849444,-0.000712908804416656,5,8,25,4369,0
,10317827.8239063,200.002423437501,0.07,0.199208755372504,50,10.0003795430668,-9.80822505428553,0.000521854870021343,5,92,25,4369,0
,10317859.559375,199.995799999999,0.07,0.199208755372504,10,10.0004080549069,7.07135635025724,0.000580472114961594,5,48,25,4369,0
,10317885.2379688,199.9931421875,0.07,0.199208755372504,30,10.0003985509341,1.95098097359135,-0.000720621254812512,5,4,25,4369,0
,10317888.7653125,200.003478124999,0.07,0.199208755372504,30,10.0003985509341,-9.23916353816351,0.000559505424462258,5,88,25,4369,0
,10317912.3815625,199.9970640625,0.07,0.199208755372504,50,10.0003795430668,8.31501170155208,0.000556201348081231,5,44,25,4369,0
,10317947.235,199.99755,0.07,0.199208755372504,10,10.0004080549069,0,-0.0007090691360645,5,0,25,4369,0
,10317950.5621875,199.99755,0.07,0.199208755372504,10,10.0004080549069,-8.31503540828069,0.000626368273515255,5,84,25,4369,0
,10317974.64125,200.0013125,0.07,0.199208755372504,30,10.0003985509341,9.23916353816351,0.000515743158757687,5,40,25,4369,0
,10317978.0143751,200.00301875,0.07,0.199208755372504,30,10.0003985509341,-1.95098097359134,-0.000715457523862521,5,124,25,4369,0
,10318002.354375,200.003725,0.07,0.199208755372504,50,10.0003795430668,-7.07133618934179,0.000641709007322789,5,80,25,4369,0
,10318033.9451562,199.9910375,0.07,0.199208755372504,10,10.0004080549069,9.80825301827859,4.41446900367685E-6,5,36,25,4369,0
,10318037.4921875,199.998125,0.07,0.199208755372504,10,10.0004080549069,-3.82699047950326,-0.000695249764248729,5,120,25,4369,0
,10318060.7867188,199.995089062499,0.07,0.199208755372504,30,10.0003985509341,-5.55592375323133,0.000654957127860851,5,76,25,4369,0
,10318085.13875,200.0027375,0.07,0.199208755372504,50,10.0003795430668,10.0003795430668,-0.000173409981653094,5,32,25,4369,0
,10318088.7842188,200.002704687501,0.07,0.199208755372504,50,10.0003795430668,-5.5559131930261,-0.000672422489151359,5,116,25,4369,0
,10318120.8868751,200.00455625,0.07,0.199208755372504,10,10.0004080549069,-3.82699047950326,0.000676184426993132,5,72,25,4369,0
,10318144.3648437,199.9989046875,0.07,0.199208755372504,30,10.0003985509341,9.80824369692192,-0.0004396617360827,5,28,25,4369,0
,10318147.754375,199.996968750002,0.07,0.199208755372504,30,10.0003985509341,-7.0713496299336,-0.000650484192495545,5,112,25,4369,0
,10318172.881875,199.99843125,0.07,0.199208755372504,50,10.0003795430668,-1.95097726534041,0.000676405522972345,5,68,25,4369,0
,10318204.11125,200.00196875,0.07,0.199208755372504,10,10.0004080549069,9.23917231868949,-0.000627826084382832,5,24,25,4369,0
,10318207.563125,199.999409375,0.07,0.199208755372504,10,10.0004080549069,-8.31503540828069,-0.000412500812672079,5,108,25,4369,0
,10318232.075,199.999275000001,0.07,0.199208755372504,30,10.0003985509341,1.22465516062299E-15,0.000679815808931987,5,64,25,4369,0
,10318257.1957813,200.005728125,0.07,0.199208755372504,50,10.0003795430668,8.31501170155209,-0.000654614949598908,5,20,25,4369,0
,10318260.8740625,199.99345625,0.07,0.199208755372504,50,10.0003795430668,-9.23914597718402,-0.000263905758038163,5,104,25,4369,0
,10318295.1917187,199.99629375,0.07,0.199208755372504,10,10.0004080549069,1.95098282772447,0.000665301049593836,5,60,25,4369,0
,10318319.526875,199.99633125,0.07,0.199208755372504,30,10.0003985509341,7.0713496299336,-0.000681329143440558,5,16,25,4369,0
,10318323.0804687,199.994395312501,0.07,0.199208755372504,30,10.0003985509341,-9.80824369692192,-9.11996984440417E-5,5,100,25,4369,0
,10318346.713125,199.991571874999,0.07,0.199208755372504,50,10.0003795430668,3.82697956849445,0.000658214045688511,5,56,25,4369,0
,10318378.5773437,200.0007765625,0.07,0.199208755372504,10,10.0004080549069,5.55592903335573,-0.000708492589183151,5,12,25,4369,0
,10318382.4787499,200.002712499999,0.07,0.199208755372504,10,10.0004080549069,-10.0004080549069,0.000382958096452057,5,96,25,4369,0
,10318408.0271875,199.99863125,0.07,0.199208755372504,30,10.0003985509341,5.55592375323133,0.000644862755305238,5,52,25,4369,0
,10318432.5059375,200.011503125,0.07,0.199208755372504,50,10.0003795430668,3.82697956849444,-0.000715219229459763,5,8,25,4369,0
,10318436.1382813,200.003135937499,0.07,0.199208755372504,50,10.0003795430668,-9.80822505428553,0.000523573718965054,5,92,25,4369,0
,10318469.56375,200.0044625,0.07,0.199208755372504,10,10.0004080549069,7.07135635025724,0.000573898432776333,5,48,25,4369,0
,10318494.5557812,200.0105296875,0.07,0.199208755372504,30,10.0003985509341,1.95098097359135,-0.000722540620093544,5,4,25,4369,0
,10318497.8271874,200.011153125001,0.07,0.199208755372504,30,10.0003985509341,-9.23916353816351,0.000564489229064848,5,88,25,4369,0
,10318523.0007813,199.995225,0.07,0.199208755372504,50,10.0003795430668,8.31501170155208,0.000561535730957985,5,44,25,4369,0
,10318557.87,199.99935,0.07,0.199208755372504,10,10.0004080549069,0,-0.000715991191100329,5,0,25,4369,0
,10318561.3907813,199.996757812501,0.07,0.199208755372504,10,10.0004080549069,-8.31503540828069,0.000634746684227138,5,84,25,4369,0
,10318586.1153125,200.010453125,0.07,0.199208755372504,30,10.0003985509341,9.23916353816351,0.000512873650425011,5,40,25,4369,0
,10318589.5704688,200.0056296875,0.07,0.199208755372504,30,10.0003985509341,-1.95098097359134,-0.00071948135478629,5,124,25,4369,0
,10318612.950625,200.000125,0.07,0.199208755372504,50,10.0003795430668,-7.07133618934179,0.000643889931961895,5,80,25,4369,0
,10318643.7765625,199.9979890625,0.07,0.199208755372504,10,10.0004080549069,9.80825301827859,-6.23404048383079E-7,5,36,25,4369,0
,10318647.4318749,200.005896875001,0.07,0.199208755372504,10,10.0004080549069,-3.82699047950326,-0.000686367857269944,5,120,25,4369,0
,10318673.0129688,199.998770312501,0.07,0.199208755372504,30,10.0003985509341,-5.55592375323133,0.000661774603132573,5,76,25,4369,0
,10318696.18,199.998275,0.07,0.199208755372504,50,10.0003795430668,10.0003795430668,-0.000175188528373837,5,32,25,4369,0
,10318699.8549999,200.002146875,0.07,0.199208755372504,50,10.0003795430668,-5.5559131930261,-0.000676624337211252,5,116,25,4369,0
,10318734.893125,200.0015875,0.07,0.199208755372504,10,10.0004080549069,-3.82699047950326,0.000674022303428501,5,72,25,4369,0
,10318759.1721875,200.0037296875,0.07,0.199208755372504,30,10.0003985509341,9.80824369692192,-0.000451608729134831,5,28,25,4369,0
,10318762.64375,200.007568750001,0.07,0.199208755372504,30,10.0003985509341,-7.0713496299336,-0.000653814899528193,5,112,25,4369,0
,10318786.82875,199.997417187501,0.07,0.199208755372504,50,10.0003795430668,-1.95097726534041,0.000685537653043866,5,68,25,4369,0
,10318818.7821875,199.993425,0.07,0.199208755372504,10,10.0004080549069,9.23917231868949,-0.000624399399384856,5,24,25,4369,0
,10318822.4998437,199.9921125,0.07,0.199208755372504,10,10.0004080549069,-8.31503540828069,-0.000428974162787199,5,108,25,4369,0
,10318847.68,200.00605,0.07,0.199208755372504,30,10.0003985509341,1.22465516062299E-15,0.000684478824647764,5,64,25,4369,0
,10318872.33125,200.0024515625,0.07,0.199208755372504,50,10.0003795430668,8.31501170155209,-0.000657563982531428,5,20,25,4369,0
,10318875.8224999,200.001828124999,0.07,0.199208755372504,50,10.0003795430668,-9.23914597718402,-0.000265346420928837,5,104,25,4369,0
,10318909.8384375,200.00121875,0.07,0.199208755372504,10,10.0004080549069,1.95098282772447,0.000679627992212772,5,60,25,4369,0
,10318933.7375,199.99463125,0.07,0.199208755372504,30,10.0003985509341,7.0713496299336,-0.000682375587833425,5,16,25,4369,0
,10318937.1106251,199.998470312501,0.07,0.199208755372504,30,10.0003985509341,-9.80824369692192,-9.5391684832672E-5,5,100,25,4369,0
,10318960.2396875,199.994015624999,0.07,0.199208755372504,50,10.0003795430668,3.82697956849445,0.000661801127716899,5,56,25,4369,0
,10318993.1717187,200.0055234375,0.07,0.199208755372504,10,10.0004080549069,5.55592903335573,-0.00070048205088824,5,12,25,4369,0
,10318996.71875,200.011987499999,0.07,0.199208755372504,10,10.0004080549069,-10.0004080549069,0.000358082470484078,5,96,25,4369,0
,10319020.0323437,199.9910109375,0.07,0.199208755372504,30,10.0003985509341,5.55592375323133,0.000647693070479565,5,52,25,4369,0
,10319044.4584375,200.003440625,0.07,0.199208755372504,50,10.0003795430668,3.82697956849444,-0.000720317335799337,5,8,25,4369,0
,10319047.9595313,200.002817187499,0.07,0.199208755372504,50,10.0003795430668,-9.80822505428553,0.000526872789487243,5,92,25,4369,0
,10319080.17,199.9925125,0.07,0.199208755372504,10,10.0004080549069,7.07135635025724,0.000602028158027678,5,48,25,4369,0
,10319103.7075,199.9984296875,0.07,0.199208755372504,30,10.0003985509341,1.95098097359135,-0.000731051420896417,5,4,25,4369,0
,10319107.33,199.999053125001,0.07,0.199208755372504,30,10.0003985509341,-9.23916353816351,0.000577818460038138,5,88,25,4369,0
,10319131.098125,200.003703125001,0.07,0.199208755372504,50,10.0003795430668,8.31501170155208,0.000564010301604867,5,44,25,4369,0
,10319162.235,199.9969,0.07,0.199208755372504,10,10.0004080549069,0,-0.000725671416148543,5,0,25,4369,0
,10319166.0740624,199.999492187499,0.07,0.199208755372504,10,10.0004080549069,-8.31503540828069,0.000648858258500696,5,84,25,4369,0
,10319189.654375,199.993821875,0.07,0.199208755372504,30,10.0003985509341,9.23916353816351,0.00051740744513356,5,40,25,4369,0
,10319192.8765626,199.985257812499,0.07,0.199208755372504,30,10.0003985509341,-1.95098097359134,-0.000724778704655667,5,124,25,4369,0
,10319217.5037499,200.0009,0.07,0.199208755372504,50,10.0003795430668,-7.07133618934179,0.00064748558215797,5,80,25,4369,0
,10319249.161875,200.005053125,0.07,0.199208755372504,10,10.0004080549069,9.80825301827859,1.14645808935169E-5,5,36,25,4369,0
,10319252.8762501,200.010893750001,0.07,0.199208755372504,10,10.0004080549069,-3.82699047950326,-0.000699426745995879,5,120,25,4369,0
,10319275.8195313,199.99440625,0.07,0.199208755372504,30,10.0003985509341,-5.55592375323133,0.000662183867663973,5,76,25,4369,0
,10319299.71125,199.9954375,0.07,0.199208755372504,50,10.0003795430668,10.0003795430668,-0.000177676230669022,5,32,25,4369,0
,10319303.1664063,200.007742187499,0.07,0.199208755372504,50,10.0003795430668,-5.5559131930261,-0.000678034499287605,5,116,25,4369,0
,10319336.3196875,200.002521875001,0.07,0.199208755372504,10,10.0004080549069,-3.82699047950326,0.000687332067172974,5,72,25,4369,0
,10319360.9195312,200.00628125,0.07,0.199208755372504,30,10.0003985509341,9.80824369692192,-0.000459984682189922,5,28,25,4369,0
,10319364.473125,200.005625,0.07,0.199208755372504,30,10.0003985509341,-7.0713496299336,-0.000657921773381531,5,112,25,4369,0
,10319389.1540625,199.9967375,0.07,0.199208755372504,50,10.0003795430668,-1.95097726534041,0.000687867077067495,5,68,25,4369,0
,10319424.3221875,199.99676875,0.07,0.199208755372504,10,10.0004080549069,9.23917231868949,-0.00063813233282417,5,24,25,4369,0
,10319427.8298438,199.999984375,0.07,0.199208755372504,10,10.0004080549069,-8.31503540828069,-0.000429418287239969,5,108,25,4369,0
,10319451.8425,200.000775000001,0.07,0.199208755372504,30,10.0003985509341,1.22465516062299E-15,0.000685618207272556,5,64,25,4369,0
,10319476.3682813,200.0003671875,0.07,0.199208755372504,50,10.0003795430668,8.31501170155209,-0.000661021331325173,5,20,25,4369,0
,10319480.2040625,200.002959374999,0.07,0.199208755372504,50,10.0003795430668,-9.23914597718402,-0.000268363626673818,5,104,25,4369,0
,10319515.49875,200.000535937501,0.07,0.199208755372504,10,10.0004080549069,1.95098282772447,0.000698340882081538,5,60,25,4369,0
,10319539.406875,200.00415,0.07,0.199208755372504,30,10.0003985509341,7.0713496299336,-0.000683716886366407,5,16,25,4369,0
,10319543.1179687,199.9970625,0.07,0.199208755372504,30,10.0003985509341,-9.80824369692192,-9.35996003035038E-5,5,100,25,4369,0
,10319567.2375,199.994278125001,0.07,0.199208755372504,50,10.0003795430668,3.82697956849445,0.000667462917044759,5,56,25,4369,0
,10319603.6709375,200.001990625,0.07,0.199208755372504,10,10.0004080549069,5.55592903335573,-0.000711203319951892,5,12,25,4369,0
,10319607.4575,199.998775,0.07,0.199208755372504,10,10.0004080549069,-10.0004080549069,0.000364395091310143,5,96,25,4369,0
,10319632.0271875,199.995840625,0.07,0.199208755372504,30,10.0003985509341,5.55592375323133,0.000651310223879086,5,52,25,4369,0
,10319655.385625,200.008415625,0.07,0.199208755372504,50,10.0003795430668,3.82697956849444,-0.000726243807002902,5,8,25,4369,0
,10319659.1196875,200.006479687501,0.07,0.199208755372504,50,10.0003795430668,-9.80822505428553,0.000532533647492528,5,92,25,4369,0
,10319694.778125,200.006018750001,0.07,0.199208755372504,10,10.0004080549069,7.07135635025724,0.00058159843320027,5,48,25,4369,0
,10319719.3814062,199.9938859375,0.07,0.199208755372504,30,10.0003985509341,1.95098097359135,-0.000733414651929504,5,4,25,4369,0
,10319722.9809374,199.997790624999,0.07,0.199208755372504,30,10.0003985509341,-9.23916353816351,0.000577454726832608,5,88,25,4369,0
,10319747.464375,199.997823437501,0.07,0.199208755372504,50,10.0003795430668,8.31501170155208,0.000567157892510295,5,44,25,4369,0
,10319782.52,199.9996,0.07,0.199208755372504,10,10.0004080549069,0,-0.000731165928300471,5,0,25,4369,0
,10319786.0243749,200.002815625,0.07,0.199208755372504,10,10.0004080549069,-8.31503540828069,0.000636432378087193,5,84,25,4369,0
,10319808.8003125,199.99623125,0.07,0.199208755372504,30,10.0003985509341,9.23916353816351,0.000517276995297935,5,40,25,4369,0
,10319812.4654688,199.999446875,0.07,0.199208755372504,30,10.0003985509341,-1.95098097359134,-0.000724385802944501,5,124,25,4369,0
,10319836.34125,199.996181249999,0.07,0.199208755372504,50,10.0003795430668,-7.07133618934179,0.000652381265535951,5,80,25,4369,0
,10319869.34625,199.9985640625,0.07,0.199208755372504,10,10.0004080549069,9.80825301827859,9.29197994992085E-6,5,36,25,4369,0
,10319872.8374999,199.998596874999,0.07,0.199208755372504,10,10.0004080549069,-3.82699047950326,-0.000695061462465674,5,120,25,4369,0
,10319897.01,200.0028640625,0.07,0.199208755372504,30,10.0003985509341,-5.55592375323133,0.000665887362427182,5,76,25,4369,0
,10319920.785,199.9994,0.07,0.199208755372504,50,10.0003795430668,10.0003795430668,-0.000181894516572356,5,32,25,4369,0
,10319924.4599999,199.995200000001,0.07,0.199208755372504,50,10.0003795430668,-5.5559131930261,-0.000682341633364558,5,116,25,4369,0
,10319954.8090625,199.99428125,0.07,0.199208755372504,10,10.0004080549069,-3.82699047950326,0.00068432796979323,5,72,25,4369,0
,10319978.483125,200.0087453125,0.07,0.199208755372504,30,10.0003985509341,9.80824369692192,-0.00047553084894187,5,28,25,4369,0
,10319982.0925,200.012781250001,0.07,0.199208755372504,30,10.0003985509341,-7.0713496299336,-0.000658663015605675,5,112,25,4369,0
,10320007.2542187,199.998429687499,0.07,0.199208755372504,50,10.0003795430668,-1.95097726534041,0.000692275771871209,5,68,25,4369,0
,10320038.0853125,200.001534375,0.07,0.199208755372504,10,10.0004080549069,9.23917231868949,-0.000645593681838364,5,24,25,4369,0
,10320041.4814062,200.0007796875,0.07,0.199208755372504,10,10.0004080549069,-8.31503540828069,-0.000441106676589698,5,108,25,4369,0
,10320065.335,200.001574999999,0.07,0.199208755372504,30,10.0003985509341,1.22465516062299E-15,0.000690325460810628,5,64,25,4369,0
,10320089.3835937,199.9997984375,0.07,0.199208755372504,50,10.0003795430668,8.31501170155209,-0.000663437135517597,5,20,25,4369,0
,10320093.0946875,200.008821874999,0.07,0.199208755372504,50,10.0003795430668,-9.23914597718402,-0.000276370719075204,5,104,25,4369,0
,10320125.6367187,200.000301562501,0.07,0.199208755372504,10,10.0004080549069,1.95098282772447,0.000677076750434936,5,60,25,4369,0
,10320150.17125,199.9904375,0.07,0.199208755372504,30,10.0003985509341,7.0713496299336,-0.000688867940981355,5,16,25,4369,0
,10320153.7478125,199.994309375,0.07,0.199208755372504,30,10.0003985509341,-9.80824369692192,-9.40490281209352E-5,5,100,25,4369,0
,10320177.401875,200.002090625001,0.07,0.199208755372504,50,10.0003795430668,3.82697956849445,0.000666790874674916,5,56,25,4369,0
,10320213.5067187,200.0126328125,0.07,0.199208755372504,10,10.0004080549069,5.55592903335573,-0.00071424146881327,5,12,25,4369,0
,10320216.9487499,200.005512500001,0.07,0.199208755372504,10,10.0004080549069,-10.0004080549069,0.0003725805436261,5,96,25,4369,0
,10320240.7975,200.001253125,0.07,0.199208755372504,30,10.0003985509341,5.55592375323133,0.000650049575294058,5,52,25,4369,0
,10320265.9009375,200.00405,0.07,0.199208755372504,50,10.0003795430668,3.82697956849444,-0.000729329464957117,5,8,25,4369,0
,10320269.2182813,199.998275,0.07,0.199208755372504,50,10.0003795430668,-9.80822505428553,0.000536128925159574,5,92,25,4369,0
,10320304.92,200.006968750001,0.07,0.199208755372504,10,10.0004080549069,7.07135635025724,0.000577520695514976,5,48,25,4369,0
,10320330.0953125,200.004,0.07,0.199208755372504,30,10.0003985509341,1.95098097359135,-0.000737232621759176,5,4,25,4369,0
,10320333.671875,199.9956,0.07,0.199208755372504,30,10.0003985509341,-9.23916353816351,0.00058280381684502,5,88,25,4369,0
,10320357.3017187,199.997434375,0.07,0.199208755372504,50,10.0003795430668,8.31501170155208,0.000570444902405143,5,44,25,4369,0
,10320392.42,200.0026,0.07,0.199208755372504,10,10.0004080549069,0,-0.000749038299545646,5,0,25,4369,0
,10320395.8325,200.005192187499,0.07,0.199208755372504,10,10.0004080549069,-8.31503540828069,0.00064559979364276,5,84,25,4369,0
,10320419.8815625,199.9948,0.07,0.199208755372504,30,10.0003985509341,9.23916353816351,0.000526636140421033,5,40,25,4369,0
,10320423.4548437,199.992174999999,0.07,0.199208755372504,30,10.0003985509341,-1.95098097359134,-0.000734330387786031,5,124,25,4369,0
,10320447.931875,199.9968875,0.07,0.199208755372504,50,10.0003795430668,-7.07133618934179,0.000656107254326344,5,80,25,4369,0
,10320479.4510937,199.997578125,0.07,0.199208755372504,10,10.0004080549069,9.80825301827859,-3.86062311008619E-6,5,36,25,4369,0
,10320483.1753125,199.99239375,0.07,0.199208755372504,10,10.0004080549069,-3.82699047950326,-0.00070769601734355,5,120,25,4369,0
,10320508.4392187,200.007345312501,0.07,0.199208755372504,30,10.0003985509341,-5.55592375323133,0.000669130628618102,5,76,25,4369,0
,10320532.295,199.9878375,0.07,0.199208755372504,50,10.0003795430668,10.0003795430668,-0.000181041425094009,5,32,25,4369,0
,10320535.9568749,199.993054687499,0.07,0.199208755372504,50,10.0003795430668,-5.5559131930261,-0.000687138130888343,5,116,25,4369,0
,10320570.59375,199.999525,0.07,0.199208755372504,10,10.0004080549069,-3.82699047950326,0.000688813452143222,5,72,25,4369,0
,10320595.3814063,199.9976640625,0.07,0.199208755372504,30,10.0003985509341,9.80824369692192,-0.000476739886734221,5,28,25,4369,0
,10320598.895625,200.000256249999,0.07,0.199208755372504,30,10.0003985509341,-7.0713496299336,-0.000658778008073568,5,112,25,4369,0
,10320623.5553125,199.9959125,0.07,0.199208755372504,50,10.0003795430668,-1.95097726534041,0.00069456733763218,5,68,25,4369,0
,10320658.4659375,199.997409375,0.07,0.199208755372504,10,10.0004080549069,9.23917231868949,-0.000631615694146604,5,24,25,4369,0
,10320661.8817187,200.003217187499,0.07,0.199208755372504,10,10.0004080549069,-8.31503540828069,-0.000449639919679612,5,108,25,4369,0
,10320685.865,199.999674999999,0.07,0.199208755372504,30,10.0003985509341,1.22465516062299E-15,0.000699353210317592,5,64,25,4369,0
,10320709.6825,200.003071875,0.07,0.199208755372504,50,10.0003795430668,8.31501170155209,-0.000666293548420072,5,20,25,4369,0
,10320713.1999999,200.002743750001,0.07,0.199208755372504,50,10.0003795430668,-9.23914597718402,-0.000277929799631238,5,104,25,4369,0
,10320745.415625,200.000254687499,0.07,0.199208755372504,10,10.0004080549069,1.95098282772447,0.000695046037435531,5,60,25,4369,0
,10320770.815,200.0062125,0.07,0.199208755372504,30,10.0003985509341,7.0713496299336,-0.00069160201948964,5,16,25,4369,0
,10320774.5162501,200.003653125,0.07,0.199208755372504,30,10.0003985509341,-9.80824369692192,-9.80760928036442E-5,5,100,25,4369,0
,10320798.473125,199.993590625001,0.07,0.199208755372504,50,10.0003795430668,3.82697956849445,0.00067095342092216,5,56,25,4369,0
,10320833.685,199.9956734375,0.07,0.199208755372504,10,10.0004080549069,5.55592903335573,-0.000728628365322947,5,12,25,4369,0
,10320837.465,200.002137499999,0.07,0.199208755372504,10,10.0004080549069,-10.0004080549069,0.000379339326173067,5,96,25,4369,0
,10320861.7779687,200.004142187501,0.07,0.199208755372504,30,10.0003985509341,5.55592375323133,0.000662883459072974,5,52,25,4369,0
,10320885.7675,199.998103125,0.07,0.199208755372504,50,10.0003795430668,3.82697956849444,-0.000731490179896355,5,8,25,4369,0
,10320889.1537501,200.002335937501,0.07,0.199208755372504,50,10.0003795430668,-9.80822505428553,0.000538166426122189,5,92,25,4369,0
,10320924.915,200.0040875,0.07,0.199208755372504,10,10.0004080549069,7.07135635025724,0.000600638741161675,5,48,25,4369,0
,10320950.7295313,199.99581875,0.07,0.199208755372504,30,10.0003985509341,1.95098097359135,-0.000735276456301411,5,4,25,4369,0
,10320954.1846876,199.9951625,0.07,0.199208755372504,30,10.0003985509341,-9.23916353816351,0.000583155261766579,5,88,25,4369,0
,10320978.7540625,200.0033875,0.07,0.199208755372504,50,10.0003795430668,8.31501170155208,0.000571962213143707,5,44,25,4369,0
,10321012.475,199.9998,0.07,0.199208755372504,10,10.0004080549069,0,-0.000730494502931834,5,0,25,4369,0
,10321016.2845313,199.999767187501,0.07,0.199208755372504,10,10.0004080549069,-8.31503540828069,0.000650058500468731,5,84,25,4369,0
,10321041.2925,200.0010625,0.07,0.199208755372504,30,10.0003985509341,9.23916353816351,0.00052894096976767,5,40,25,4369,0
,10321045.20375,200.00171875,0.07,0.199208755372504,30,10.0003985509341,-1.95098097359134,-0.000734924817354316,5,124,25,4369,0
,10321069.73,200.005625,0.07,0.199208755372504,50,10.0003795430668,-7.07133618934179,0.000657507544383407,5,80,25,4369,0
,10321104.7128125,200.0095609375,0.07,0.199208755372504,10,10.0004080549069,9.80825301827859,7.97444954513911E-8,5,36,25,4369,0
,10321108.289375,200.012153124999,0.07,0.199208755372504,10,10.0004080549069,-3.82699047950326,-0.000705742859281599,5,120,25,4369,0
,10321133.279375,199.9955296875,0.07,0.199208755372504,30,10.0003985509341,-5.55592375323133,0.000673942914646533,5,76,25,4369,0
,10321156.60625,199.9902125,0.07,0.199208755372504,50,10.0003795430668,10.0003795430668,-0.000187849067151547,5,32,25,4369,0
,10321160.2057812,199.996020312498,0.07,0.199208755372504,50,10.0003795430668,-5.5559131930261,-0.000688988529145717,5,116,25,4369,0
,10321196.0656249,199.996350000001,0.07,0.199208755372504,10,10.0004080549069,-3.82699047950326,0.000694969785399736,5,72,25,4369,0
,10321220.6870312,200.0137078125,0.07,0.199208755372504,30,10.0003985509341,9.80824369692192,-0.000492779072374106,5,28,25,4369,0
,10321224.398125,200.005931250001,0.07,0.199208755372504,30,10.0003985509341,-7.0713496299336,-0.000663936241633362,5,112,25,4369,0
,10321248.7415625,199.992367187501,0.07,0.199208755372504,50,10.0003795430668,-1.95097726534041,0.000700692599639296,5,68,25,4369,0
,10321284.2221875,199.9939625,0.07,0.199208755372504,10,10.0004080549069,9.23917231868949,-0.000651060254313051,5,24,25,4369,0
,10321287.6773438,200.00170625,0.07,0.199208755372504,10,10.0004080549069,-8.31503540828069,-0.0004507479025051,5,108,25,4369,0
,10321311.61,199.992275,0.07,0.199208755372504,30,10.0003985509341,1.22465516062299E-15,0.000698973955069151,5,64,25,4369,0
,10321335.8985937,199.9978203125,0.07,0.199208755372504,50,10.0003795430668,8.31501170155209,-0.00066788736730814,5,20,25,4369,0
,10321339.2946875,199.993915625001,0.07,0.199208755372504,50,10.0003795430668,-9.23914597718402,-0.000282888859510421,5,104,25,4369,0
,10321369.4092187,199.998501562501,0.07,0.199208755372504,10,10.0004080549069,1.95098282772447,0.000675889896228909,5,60,25,4369,0
,10321393.276875,199.99585625,0.07,0.199208755372504,30,10.0003985509341,7.0713496299336,-0.000689430679712031,5,16,25,4369,0
,10321396.9354688,199.997201562499,0.07,0.199208755372504,30,10.0003985509341,-9.80824369692192,-9.59368319147163E-5,5,100,25,4369,0
,10321420.6090625,199.996746874999,0.07,0.199208755372504,50,10.0003795430668,3.82697956849445,0.000674652727320791,5,56,25,4369,0
,10321453.3423437,199.99195625,0.07,0.199208755372504,10,10.0004080549069,5.55592903335573,-0.000710733293090015,5,12,25,4369,0
,10321456.71875,199.9997,0.07,0.199208755372504,10,10.0004080549069,-10.0004080549069,0.000375837262254209,5,96,25,4369,0
,10321481.99375,200.001410937499,0.07,0.199208755372504,30,10.0003985509341,5.55592375323133,0.000666265582872762,5,52,25,4369,0
,10321506.3396875,199.995259375,0.07,0.199208755372504,50,10.0003795430668,3.82697956849444,-0.000736286537721753,5,8,25,4369,0
,10321510.1689063,199.998507812499,0.07,0.199208755372504,50,10.0003795430668,-9.80822505428553,0.000540407886728644,5,92,25,4369,0
,10321544.605,200.001218750001,0.07,0.199208755372504,10,10.0004080549069,7.07135635025724,0.000606975809205323,5,48,25,4369,0
,10321568.8701563,199.9978265625,0.07,0.199208755372504,30,10.0003985509341,1.95098097359135,-0.000740542956110503,5,4,25,4369,0
,10321572.8634375,200.003634374999,0.07,0.199208755372504,30,10.0003985509341,-9.23916353816351,0.000584806936482589,5,88,25,4369,0
,10321598.0890625,199.999907812499,0.07,0.199208755372504,50,10.0003795430668,8.31501170155208,0.000574904214590788,5,44,25,4369,0
,10321632.015,199.988,0.07,0.199208755372504,10,10.0004080549069,0,-0.000751099141780288,5,0,25,4369,0
,10321635.4603125,200.000895312499,0.07,0.199208755372504,10,10.0004080549069,-8.31503540828069,0.000655243347864599,5,84,25,4369,0
,10321659.51875,200.00585625,0.07,0.199208755372504,30,10.0003985509341,9.23916353816351,0.000530827415382697,5,40,25,4369,0
,10321662.655625,200.010384375,0.07,0.199208755372504,30,10.0003985509341,-1.95098097359134,-0.000736050941567454,5,124,25,4369,0
,10321686.65,200.001675,0.07,0.199208755372504,50,10.0003795430668,-7.07133618934179,0.000662155728787184,5,80,25,4369,0
,10321723.9675,200.00033125,0.07,0.199208755372504,10,10.0004080549069,9.80825301827859,-7.01867975294558E-6,5,36,25,4369,0
,10321727.4849999,200.0009875,0.07,0.199208755372504,10,10.0004080549069,-3.82699047950326,-0.000694920308887959,5,120,25,4369,0
,10321751.415625,200.007260937501,0.07,0.199208755372504,30,10.0003985509341,-5.55592375323133,0.000675831882593532,5,76,25,4369,0
,10321776.64,199.9927625,0.07,0.199208755372504,50,10.0003795430668,10.0003795430668,-0.000186220044270158,5,32,25,4369,0
,10321780.3281249,199.997914062502,0.07,0.199208755372504,50,10.0003795430668,-5.5559131930261,-0.000694514671340585,5,116,25,4369,0
,10321815.024375,199.99855,0.07,0.199208755372504,10,10.0004080549069,-3.82699047950326,0.000704592966940254,5,72,25,4369,0
,10321839.3765625,200.002696875,0.07,0.199208755372504,30,10.0003985509341,9.80824369692192,-0.00049639066370825,5,28,25,4369,0
,10321843.28125,200.003287499999,0.07,0.199208755372504,30,10.0003985509341,-7.0713496299336,-0.000662546889442536,5,112,25,4369,0
,10321867.7951562,200.011339062501,0.07,0.199208755372504,50,10.0003795430668,-1.95097726534041,0.000700865173712372,5,68,25,4369,0
,10321903.3228125,200.002359375,0.07,0.199208755372504,10,10.0004080549069,9.23917231868949,-0.000641396909486503,5,24,25,4369,0
,10321906.5876562,200.008167187499,0.07,0.199208755372504,10,10.0004080549069,-8.31503540828069,-0.000467025383841246,5,108,25,4369,0
,10321932.1725,200.000224999999,0.07,0.199208755372504,30,10.0003985509341,1.22465516062299E-15,0.000703821359719667,5,64,25,4369,0
,10321956.314375,199.993146875,0.07,0.199208755372504,50,10.0003795430668,8.31501170155209,-0.000672153849154711,5,20,25,4369,0
,10321959.92375,199.994393749999,0.07,0.199208755372504,50,10.0003795430668,-9.23914597718402,-0.000283933524042368,5,104,25,4369,0
,10321989.7445313,199.99628125,0.07,0.199208755372504,10,10.0004080549069,1.95098282772447,0.000671439920552075,5,60,25,4369,0
,10322014.51,200.011025,0.07,0.199208755372504,30,10.0003985509341,7.0713496299336,-0.000693169551798039,5,16,25,4369,0
,10322017.9225,200.00328125,0.07,0.199208755372504,30,10.0003985509341,-9.80824369692192,-0.00010019776204394,5,100,25,4369,0
,10322041.923125,200.00125625,0.07,0.199208755372504,50,10.0003795430668,3.82697956849445,0.000679200887680054,5,56,25,4369,0
,10322073.75,199.9981703125,0.07,0.199208755372504,10,10.0004080549069,5.55592903335573,-0.000725822756066919,5,12,25,4369,0
,10322077.32,200.000762499999,0.07,0.199208755372504,10,10.0004080549069,-10.0004080549069,0.000380086712539196,5,96,25,4369,0
,10322100.734375,199.998921875,0.07,0.199208755372504,30,10.0003985509341,5.55592375323133,0.00066973230180641,5,52,25,4369,0
,10322125.454375,199.998496875,0.07,0.199208755372504,50,10.0003795430668,3.82697956849444,-0.000737799005582929,5,8,25,4369,0
,10322129.2278125,200.006864062501,0.07,0.199208755372504,50,10.0003795430668,-9.80822505428553,0.000542846461758017,5,92,25,4369,0
,10322160.108125,200.000381250001,0.07,0.199208755372504,10,10.0004080549069,7.07135635025724,0.000583904911763966,5,48,25,4369,0
,10322184.9495313,199.98844375,0.07,0.199208755372504,30,10.0003985509341,1.95098097359135,-0.000736589750481976,5,4,25,4369,0
,10322188.6146875,199.998812500001,0.07,0.199208755372504,30,10.0003985509341,-9.23916353816351,0.000579100257406632,5,88,25,4369,0
,10322212.0545313,200.0010484375,0.07,0.199208755372504,50,10.0003795430668,8.31501170155208,0.000572287291288376,5,44,25,4369,0
,10322215.3453516,199.997838671876,0.07,0.199208755372504,50,10.0003795430668,-0.490695366569778,-0.000739568844437599,5,127,25,4369,0