File: dados/250k5p.raw
[Header]
; ACMS Raw Data File (default extension .raw)
; Copyright 1999, Quantum Design, Inc. All rights reserved.
TITLE,Xac-time_250K_5point_microfios-FeSiB_hac_10Oe_f_10Hz_29-04-24
FILEOPENTIME,10299660.39,04/29/2024,8:59 am
BYAPP,ACMS,1.0,1.1,RAW
INFO,PPMS ACMS Option Version: 1.0.9 Build 14,APPNAME
INFO,HARMONICS,1
DATATYPE,COMMENT,1
DATATYPE,TIME,2
STARTUPAXIS,X,2,LINEAR,AUTO
STARTUPAXIS,Y,7,LINEAR,AUTO
STARTUPAXIS,Y,8,LINEAR,AUTO
TIMEMODE,MINUTES,RELATIVE
PLOT_APPEARANCE,ALL,HORZ_GRID_ON,VERT_GRID_ON,MARKERS_AND_LINES
RECORDS,ALL_RECORDS
DATATYPE,TIME,2
DATATYPE,COMMENT,1
[Data]
Comment,Time Stamp (sec),Temperature (K),Magnetic Field (Oe),Position (cm),Frequency (Hz),Amplitude (Oe),Drive (Oe),Signal (mV),Measure Type,Bin,Gain,PPMS Status (code),DSP Status (code)
,10299637.18,250.02135,0.07,0.199208755372504,10,10.0004080549069,0,-0.00196953886188567,5,0,25,4369,0
,10299640.6296875,250.022160546876,0.07,0.199208755372504,10,10.0004080549069,-8.03240306758093,0.00178376591065899,5,83,25,4369,0
,10299664.6183594,250.02055703125,0.07,0.199208755372504,30,10.0003985509341,9.56978474678673,0.00162084011309263,5,38,25,4369,0
,10299667.967539,250.018060546874,0.07,0.199208755372504,30,10.0003985509341,-3.36903280168794,-0.00199236913532433,5,121,25,4369,0
,10299692.02125,250.0274484375,0.07,0.199208755372504,50,10.0003795430668,-5.55591319302611,0.00186118083074689,5,76,25,4369,0
,10299722.6901562,250.005153125,0.07,0.199208755372504,10,10.0004080549069,9.98836212543862,-0.00174080341821536,5,31,25,4369,0
,10299725.9971874,250.017343750001,0.07,0.199208755372504,10,10.0004080549069,-6.34419170892896,-0.00196044245967642,5,114,25,4369,0
,10299749.6047656,250.009174609376,0.07,0.199208755372504,30,10.0003985509341,-2.4298986390103,0.00188834751800944,5,69,25,4369,0
,10299774.589375,250.0156,0.07,0.199208755372504,50,10.0003795430668,9.23914597718402,-0.00194963510148227,5,24,25,4369,0
,10299777.9936719,250.011450000001,0.07,0.199208755372504,50,10.0003795430668,-8.57761164494987,-0.0018807118292898,5,107,25,4369,0
,10299809.7621874,250.0122796875,0.07,0.199208755372504,10,10.0004080549069,0.980211399670675,0.00191000348422676,5,62,25,4369,0
,10299834.1884765,250.013048046875,0.07,0.199208755372504,30,10.0003985509341,7.40980656031269,-0.00201836907460044,5,17,25,4369,0
,10299837.7451562,250.0071796875,0.07,0.199208755372504,30,10.0003985509341,-9.80824369692192,-0.000592251566963063,5,100,25,4369,0
,10299862.5029687,249.993901562501,0.07,0.199208755372504,50,10.0003795430668,4.27571320987422,0.00188898392952979,5,55,25,4369,0
,10299897.659375,250.01335703125,0.07,0.199208755372504,10,10.0004080549069,4.71415972401153,-0.00205873948289081,5,10,25,4369,0
,10299901.2646875,250.000550390625,0.07,0.199208755372504,10,10.0004080549069,-9.89216873797649,0.00178969465196133,5,93,25,4369,0
,10299926.079375,250.001437499999,0.07,0.199208755372504,30,10.0003985509341,7.0713496299336,0.00186463100059579,5,48,25,4369,0
,10299949.73375,250.010059765625,0.07,0.199208755372504,50,10.0003795430668,1.46736043508789,-0.00205679927021265,5,3,25,4369,0
,10299953.1575,250.007563281249,0.07,0.199208755372504,50,10.0003795430668,-8.81954737058493,0.00185197764076293,5,86,25,4369,0
,10299988.6431641,249.997218359375,0.07,0.199208755372504,10,10.0004080549069,9.04026180850127,0.00154081324581057,5,41,25,4369,0
,10299992.3035937,249.9896640625,0.07,0.199208755372504,10,10.0004080549069,-1.95098282772447,-0.00205972639378161,5,124,25,4369,0
,10300016.9098047,250.009533203125,0.07,0.199208755372504,30,10.0003985509341,-6.71585719891891,0.00188810427466201,5,79,25,4369,0
,10300040.7121094,249.99800859375,0.07,0.199208755372504,50,10.0003795430668,9.9522249821852,7.05546233803043E-5,5,34,25,4369,0
,10300044.1715235,250.007183984374,0.07,0.199208755372504,50,10.0003795430668,-5.14122256606442,-0.00202958714216947,5,117,25,4369,0
,10300075.804375,249.9995625,0.07,0.199208755372504,10,10.0004080549069,-3.82699047950326,0.00191325001651421,5,72,25,4369,0
,10300100.7380078,250.0124015625,0.07,0.199208755372504,30,10.0003985509341,9.70069913880747,-0.00190696200459368,5,27,25,4369,0
,10300104.2363281,250.010715625,0.07,0.199208755372504,30,10.0003985509341,-7.73041261766559,-0.00198773347720918,5,110,25,4369,0
,10300129.7676954,250.002665234375,0.07,0.199208755372504,50,10.0003795430668,-0.490695366569778,0.0019083074759692,5,65,25,4369,0
,10300163.210625,250.0048484375,0.07,0.199208755372504,10,10.0004080549069,8.31503540828069,-0.00202625029487535,5,20,25,4369,0
,10300166.5954688,250.002351953124,0.07,0.199208755372504,10,10.0004080549069,-9.41582485350606,-0.000691273889970035,5,103,25,4369,0
,10300190.3599219,249.997464843751,0.07,0.199208755372504,30,10.0003985509341,2.90296246577389,0.00190881611261931,5,58,25,4369,0
,10300214.1802344,250.00474609375,0.07,0.199208755372504,50,10.0003795430668,5.95721913846527,-0.00205123922787607,5,13,25,4369,0
,10300218.0125001,250.011425000001,0.07,0.199208755372504,50,10.0003795430668,-10.0003795430668,0.00168154239654541,5,96,25,4369,0
,10300248.8710547,249.992323828125,0.07,0.199208755372504,10,10.0004080549069,5.95723612294857,0.00188780628377572,5,51,25,4369,0
,10300272.2197656,250.0074015625,0.07,0.199208755372504,30,10.0003985509341,2.90296246577389,-0.00205967387753642,5,6,25,4369,0
,10300275.7440234,249.995664843749,0.07,0.199208755372504,30,10.0003985509341,-9.41581590509685,0.0018259095830015,5,89,25,4369,0
,10300299.805625,249.995618749999,0.07,0.199208755372504,50,10.0003795430668,8.31501170155208,0.0018241683486849,5,44,25,4369,0
,10300303.3720312,249.986410937499,0.07,0.199208755372504,50,10.0003795430668,-0.490695366569778,-0.00205716830678284,5,127,25,4369,0
,10300335.6719531,250.000166406251,0.07,0.199208755372504,10,10.0004080549069,-7.73041996433595,0.00189346174011007,5,82,25,4369,0
,10300360.0098047,250.00947109375,0.07,0.199208755372504,30,10.0003985509341,9.70069913880747,0.0017016174711494,5,37,25,4369,0
,10300363.4303126,250.001106249999,0.07,0.199208755372504,30,10.0003985509341,-3.82698684249031,-0.00204816939205759,5,120,25,4369,0
,10300387.9136718,250.001830859375,0.07,0.199208755372504,50,10.0003795430668,-5.14122256606441,0.00190641898661852,5,75,25,4369,0
,10300418.6241406,249.99570703125,0.07,0.199208755372504,10,10.0004080549069,9.95225335673296,-0.00186734832823277,5,30,25,4369,0
,10300422.3429296,249.999046484376,0.07,0.199208755372504,10,10.0004080549069,-6.71586358139698,-0.00198151916265488,5,113,25,4369,0
,10300447.3870312,249.9910234375,0.07,0.199208755372504,30,10.0003985509341,-1.95098097359135,0.00191440359534075,5,68,25,4369,0
,10300472.4548437,249.996526953125,0.07,0.199208755372504,50,10.0003795430668,9.04023603410313,-0.00198899218812585,5,23,25,4369,0
,10300476.0990624,250.013224218751,0.07,0.199208755372504,50,10.0003795430668,-8.81954737058493,-0.00187902133911848,5,106,25,4369,0
,10300509.8475,250.001905078126,0.07,0.199208755372504,10,10.0004080549069,1.46736461864371,0.00192154286196455,5,61,25,4369,0
,10300535.041875,249.9965375,0.07,0.199208755372504,30,10.0003985509341,7.0713496299336,-0.00203752838489082,5,16,25,4369,0
,10300538.6569141,250.01073828125,0.07,0.199208755372504,30,10.0003985509341,-9.89215933686981,0.00049507698147661,5,99,25,4369,0
,10300563.8691406,249.9894015625,0.07,0.199208755372504,50,10.0003795430668,4.71414628362317,0.00189221599139273,5,54,25,4369,0
,10300597.7962891,249.99954140625,0.07,0.199208755372504,10,10.0004080549069,4.27572540025666,-0.00207862496608868,5,9,25,4369,0
,10300601.4048438,250.004534374999,0.07,0.199208755372504,10,10.0004080549069,-9.80825301827858,0.00183372234459966,5,92,25,4369,0
,10300625.368125,249.9961359375,0.07,0.199208755372504,30,10.0003985509341,7.40980656031269,0.00187023950275034,5,47,25,4369,0
,10300649.6982813,249.99491875,0.07,0.199208755372504,50,10.0003795430668,0.980208605021649,-0.00205977838486433,5,2,25,4369,0
,10300653.3619532,249.987396874999,0.07,0.199208755372504,50,10.0003795430668,-8.57761164494987,0.0018698526546359,5,85,25,4369,0
,10300688.210625,249.98916875,0.07,0.199208755372504,10,10.0004080549069,9.23917231868949,0.00142263830639422,5,40,25,4369,0
,10300691.5111718,249.98495390625,0.07,0.199208755372504,10,10.0004080549069,-2.42990094828733,-0.00206451019039377,5,123,25,4369,0
,10300715.9425781,250.00523046875,0.07,0.199208755372504,30,10.0003985509341,-6.34418567967242,0.00190175397114621,5,78,25,4369,0
,10300740.3866406,249.995073828125,0.07,0.199208755372504,50,10.0003795430668,9.98833364794231,-0.000854713981971147,5,33,25,4369,0
,10300744.0503126,250.008464062499,0.07,0.199208755372504,50,10.0003795430668,-5.5559131930261,-0.00202552466653287,5,116,25,4369,0
,10300775.0366407,250.000772265625,0.07,0.199208755372504,10,10.0004080549069,-3.36903600347996,0.00190676015336066,5,71,25,4369,0
,10300799.3336719,250.013065625,0.07,0.199208755372504,30,10.0003985509341,9.56978474678673,-0.00192897840558241,5,26,25,4369,0
,10300802.793086,250.003857812499,0.07,0.199208755372504,30,10.0003985509341,-8.03239543391836,-0.00198192985004021,5,109,25,4369,0
,10300826.655,249.997674999999,0.07,0.199208755372504,50,10.0003795430668,1.2246528329075E-15,0.00191152105107904,5,64,25,4369,0
,10300857.8427734,249.998221484375,0.07,0.199208755372504,10,10.0004080549069,8.03240306758093,-0.00204231968382373,5,19,25,4369,0
,10300861.1530469,250.000717968751,0.07,0.199208755372504,10,10.0004080549069,-9.56979384152169,-0.000224629475269469,5,102,25,4369,0
,10300885.1927735,250.006801171874,0.07,0.199208755372504,30,10.0003985509341,3.36903280168794,0.00191333457931048,5,57,25,4369,0
,10300909.4610938,249.9951640625,0.07,0.199208755372504,50,10.0003795430668,5.5559131930261,-0.00205034781247378,5,12,25,4369,0
,10300912.9269922,250.007711328124,0.07,0.199208755372504,50,10.0003795430668,-9.98833364794231,0.00172275993973017,5,95,25,4369,0
,10300945.0003125,249.99871640625,0.07,0.199208755372504,10,10.0004080549069,6.34419170892896,0.0018713713507168,5,50,25,4369,0
,10300969.2951172,249.994599609375,0.07,0.199208755372504,30,10.0003985509341,2.4298986390103,-0.00206471466097153,5,5,25,4369,0
,10300972.9490625,249.996253125001,0.07,0.199208755372504,30,10.0003985509341,-9.23916353816351,0.0018386608765771,5,88,25,4369,0
,10300997.2107422,249.99844375,0.07,0.199208755372504,50,10.0003795430668,8.57761164494987,0.0018121549859643,5,43,25,4369,0
,10301000.7155468,250.001037500001,0.07,0.199208755372504,50,10.0003795430668,-0.980208605021648,-0.00205585658550262,5,126,25,4369,0
,10301035.6045702,249.99863203125,0.07,0.199208755372504,10,10.0004080549069,-7.40981360229206,0.00191287545021623,5,81,25,4369,0
,10301059.0328125,250.0122890625,0.07,0.199208755372504,30,10.0003985509341,9.80824369692192,0.00162503300493376,5,36,25,4369,0
,10301062.5667969,250.001427734376,0.07,0.199208755372504,30,10.0003985509341,-4.27572133678467,-0.00204608885623101,5,119,25,4369,0
,10301086.3323438,249.999925781251,0.07,0.199208755372504,50,10.0003795430668,-4.71414628362317,0.00190780558623373,5,74,25,4369,0
,10301118.7936719,250.001572265625,0.07,0.199208755372504,10,10.0004080549069,9.89216873797649,-0.001909400743898,5,29,25,4369,0
,10301122.49625,250.004068750001,0.07,0.199208755372504,10,10.0004080549069,-7.07135635025724,-0.00194899563211948,5,112,25,4369,0
,10301146.4245312,250.0033,0.07,0.199208755372504,30,10.0003985509341,-1.46736322412126,0.00191751020287888,5,67,25,4369,0
,10301170.6407813,249.98619921875,0.07,0.199208755372504,50,10.0003795430668,8.81954737058493,-0.00199951250106096,5,22,25,4369,0
,10301173.8505469,249.999589453124,0.07,0.199208755372504,50,10.0003795430668,-9.04023603410313,-0.00181578658521176,5,105,25,4369,0
,10301203.6771875,250.0044140625,0.07,0.199208755372504,10,10.0004080549069,1.95098282772447,0.00192964245798066,5,60,25,4369,0
,10301227.7628906,250.0054859375,0.07,0.199208755372504,30,10.0003985509341,6.71585719891891,-0.00203498057089746,5,15,25,4369,0
,10301231.5692187,249.996278124999,0.07,0.199208755372504,30,10.0003985509341,-9.95224389852435,0.00127251725643873,5,98,25,4369,0
,10301255.9105469,249.994396874999,0.07,0.199208755372504,50,10.0003795430668,5.14122256606442,0.00188659676350653,5,53,25,4369,0
,10301292.106875,250.00755625,0.07,0.199208755372504,10,10.0004080549069,3.82699047950326,-0.00207118486287073,5,8,25,4369,0
,10301295.5500781,250.000877343749,0.07,0.199208755372504,10,10.0004080549069,-9.70070835795815,0.00184527860255912,5,91,25,4369,0
,10301319.2300781,250.00679921875,0.07,0.199208755372504,30,10.0003985509341,7.7304126176656,0.00185835052333358,5,46,25,4369,0
,10301343.1118359,249.995679296875,0.07,0.199208755372504,50,10.0003795430668,0.490695366569777,-0.00205799206160009,5,1,25,4369,0
,10301346.5842188,249.9898109375,0.07,0.199208755372504,50,10.0003795430668,-8.31501170155209,0.00187306795269251,5,84,25,4369,0
,10301378.5413672,249.99280390625,0.07,0.199208755372504,10,10.0004080549069,9.41582485350606,0.00126733852084726,5,39,25,4369,0
,10301381.9813282,249.9919609375,0.07,0.199208755372504,10,10.0004080549069,-2.90296522463158,-0.00205778749659657,5,122,25,4369,0
,10301406.7900781,250.003205859376,0.07,0.199208755372504,30,10.0003985509341,-5.95723046143856,0.0019028936771469,5,77,25,4369,0
,10301431.42375,249.99415,0.07,0.199208755372504,50,10.0003795430668,10.0003795430668,-0.00150076076388359,5,32,25,4369,0
,10301435.1555079,249.986628124999,0.07,0.199208755372504,50,10.0003795430668,-5.95721913846527,-0.00201275935396552,5,115,25,4369,0
,10301469.9282812,250.003853906249,0.07,0.199208755372504,10,10.0004080549069,-2.90296522463158,0.00191207189345732,5,70,25,4369,0
,10301493.5970312,250.005494140625,0.07,0.199208755372504,30,10.0003985509341,9.41581590509685,-0.00194865699288332,5,25,25,4369,0
,10301497.189375,250.002154687499,0.07,0.199208755372504,30,10.0003985509341,-8.31502750601608,-0.00196838162891153,5,108,25,4369,0
,10301521.1222656,250.003884765625,0.07,0.199208755372504,50,10.0003795430668,0.490695366569776,0.00191323230974376,5,63,25,4369,0
,10301552.9171094,249.98863984375,0.07,0.199208755372504,10,10.0004080549069,7.73041996433595,-0.00202812399948016,5,18,25,4369,0
,10301556.2468359,249.993665234376,0.07,0.199208755372504,10,10.0004080549069,-9.70070835795815,0.000230060250032694,5,101,25,4369,0
,10301581.0671876,250.013275000001,0.07,0.199208755372504,30,10.0003985509341,3.82698684249032,0.00190237252455618,5,56,25,4369,0
,10301606.4610547,249.99668828125,0.07,0.199208755372504,50,10.0003795430668,5.14122256606442,-0.00204976215027273,5,11,25,4369,0
,10301609.9399219,249.9958453125,0.07,0.199208755372504,50,10.0003795430668,-9.9522249821852,0.00175491464324296,5,94,25,4369,0
,10301644.863164,249.997061718749,0.07,0.199208755372504,10,10.0004080549069,6.71586358139698,0.00186082732398063,5,49,25,4369,0
,10301669.1092188,250.005209375,0.07,0.199208755372504,30,10.0003985509341,1.95098097359135,-0.00206126818536884,5,4,25,4369,0
,10301672.9317578,250.00436640625,0.07,0.199208755372504,30,10.0003985509341,-9.04025321701159,0.00184961756329155,5,87,25,4369,0
,10301697.9172656,250.0055625,0.07,0.199208755372504,50,10.0003795430668,8.81954737058493,0.00179097587242723,5,42,25,4369,0
,10301701.5776953,250.016456250001,0.07,0.199208755372504,50,10.0003795430668,-1.46736043508789,-0.00205239006318152,5,125,25,4369,0
,10301735.67875,250.000306250001,0.07,0.199208755372504,10,10.0004080549069,-7.07135635025724,0.00189201382454485,5,80,25,4369,0
,10301760.4738282,250.00132265625,0.07,0.199208755372504,30,10.0003985509341,9.89215933686981,0.00144146880807562,5,35,25,4369,0
,10301763.9689063,249.9971078125,0.07,0.199208755372504,30,10.0003985509341,-4.71415524386975,-0.00204612850211561,5,118,25,4369,0
,10301788.4785938,250.013371484376,0.07,0.199208755372504,50,10.0003795430668,-4.27571320987422,0.00190991684794426,5,73,25,4369,0
,10301823.266875,250.00485625,0.07,0.199208755372504,10,10.0004080549069,9.80825301827858,-0.00191047671250999,5,28,25,4369,0
,10301826.8592187,250.014064062501,0.07,0.199208755372504,10,10.0004080549069,-7.40981360229206,-0.00192286941455677,5,111,25,4369,0
,10301851.9230468,250.001917187499,0.07,0.199208755372504,30,10.0003985509341,-0.980210468118438,0.00191299180086288,5,66,25,4369,0
,10301875.8474219,249.997896875,0.07,0.199208755372504,50,10.0003795430668,8.57761164494987,-0.00200354321859777,5,21,25,4369,0
,10301879.8093749,249.990374999999,0.07,0.199208755372504,50,10.0003795430668,-9.23914597718402,-0.00172257297672331,5,104,25,4369,0
,10301914.3651953,249.996775390625,0.07,0.199208755372504,10,10.0004080549069,2.42990094828733,0.00191425293451175,5,59,25,4369,0
,10301938.2176562,250.00698671875,0.07,0.199208755372504,30,10.0003985509341,6.34418567967242,-0.00203953021102481,5,14,25,4369,0
,10301941.9980468,250.003647265624,0.07,0.199208755372504,30,10.0003985509341,-9.98835263291373,0.00156482067217844,5,97,25,4369,0
,10301966.2095313,250.00095625,0.07,0.199208755372504,50,10.0003795430668,5.5559131930261,0.00188545547425747,5,52,25,4369,0
,10302002.5242188,249.9945421875,0.07,0.199208755372504,10,10.0004080549069,3.36903600347996,-0.00205749471206218,5,7,25,4369,0
,10302006.0128126,250.000378124999,0.07,0.199208755372504,10,10.0004080549069,-9.56979384152169,0.00184817210538313,5,90,25,4369,0
,10302031.5560938,249.995142187501,0.07,0.199208755372504,30,10.0003985509341,8.03239543391837,0.00185329984459612,5,45,25,4369,0
,10302056.765,249.9876,0.07,0.199208755372504,50,10.0003795430668,0,-0.00205617309547961,5,0,25,4369,0
,10302060.483789,250.004297265625,0.07,0.199208755372504,50,10.0003795430668,-8.03238016665625,0.00187890725210309,5,83,25,4369,0
,10302094.0553906,250.00095,0.07,0.199208755372504,10,10.0004080549069,9.56979384152169,0.00102304620668292,5,38,25,4369,0
,10302097.6055858,250.00095,0.07,0.199208755372504,10,10.0004080549069,-3.36903600347996,-0.0020289103849791,5,121,25,4369,0
,10302121.4892188,249.999740625,0.07,0.199208755372504,30,10.0003985509341,-5.55592375323133,0.00190900709842228,5,76,25,4369,0
,10302145.919961,250.0027890625,0.07,0.199208755372504,50,10.0003795430668,9.98833364794231,-0.00174666508100927,5,31,25,4369,0
,10302149.3469532,250.007846874999,0.07,0.199208755372504,50,10.0003795430668,-6.3441736212091,-0.00200535114854574,5,114,25,4369,0
,10302185.2028125,250.01044765625,0.07,0.199208755372504,10,10.0004080549069,-2.42990094828733,0.00192711944691837,5,69,25,4369,0
,10302209.9425,250.006896875,0.07,0.199208755372504,30,10.0003985509341,9.23916353816351,-0.00196541963507318,5,24,25,4369,0
,10302213.2884376,250.012246484374,0.07,0.199208755372504,30,10.0003985509341,-8.57762794854141,-0.00194850138440315,5,107,25,4369,0
,10302237.7771094,249.99639609375,0.07,0.199208755372504,50,10.0003795430668,0.980208605021647,0.00191017827019096,5,62,25,4369,0
,10302273.2827734,249.987661328125,0.07,0.199208755372504,10,10.0004080549069,7.40981360229206,-0.00202861905563623,5,17,25,4369,0
,10302276.8848438,249.990157812501,0.07,0.199208755372504,10,10.0004080549069,-9.80825301827858,0.000845364411361518,5,100,25,4369,0
,10302300.2369921,249.999873046874,0.07,0.199208755372504,30,10.0003985509341,4.27572133678467,0.00189117725110716,5,55,25,4369,0
,10302322.9599219,249.99105,0.07,0.199208755372504,50,10.0003795430668,4.71414628362317,-0.00204830118454993,5,10,25,4369,0
,10302326.4452734,249.99105,0.07,0.199208755372504,50,10.0003795430668,-9.89214053473404,0.00177525416947901,5,93,25,4369,0
,10302358.489375,250.00090625,0.07,0.199208755372504,10,10.0004080549069,7.07135635025724,0.00184259290108457,5,48,25,4369,0
,10302382.4989844,250.001398828125,0.07,0.199208755372504,30,10.0003985509341,1.46736322412127,-0.002057088422589,5,3,25,4369,0
,10302385.9292187,249.99721640625,0.07,0.199208755372504,30,10.0003985509341,-8.81956413402722,0.00185327746698426,5,86,25,4369,0
,10302410.6633985,250.004066015625,0.07,0.199208755372504,50,10.0003795430668,9.04023603410313,0.00177255901508033,5,41,25,4369,0
,10302414.3951564,250.008248437501,0.07,0.199208755372504,50,10.0003795430668,-1.95097726534041,-0.00205098111182451,5,124,25,4369,0
,10302451.1247657,249.99928828125,0.07,0.199208755372504,10,10.0004080549069,-6.71586358139698,0.00188010075362399,5,79,25,4369,0
,10302476.0146093,250.001340625,0.07,0.199208755372504,30,10.0003985509341,9.95224389852435,0.000960935722105207,5,34,25,4369,0
,10302479.5777733,250.0030265625,0.07,0.199208755372504,30,10.0003985509341,-5.14123233806112,-0.00203159586009052,5,117,25,4369,0
,10302504.65625,249.989565625,0.07,0.199208755372504,50,10.0003795430668,-3.82697956849444,0.00191215081140399,5,72,25,4369,0
,10302538.6033594,249.993539453125,0.07,0.199208755372504,10,10.0004080549069,9.70070835795815,-0.00194575579371303,5,27,25,4369,0
,10302541.8260938,249.989357031249,0.07,0.199208755372504,10,10.0004080549069,-7.73041996433595,-0.00188991922186688,5,110,25,4369,0
,10302565.913125,250.001929687501,0.07,0.199208755372504,30,10.0003985509341,-0.490696299241617,0.00191704350678871,5,65,25,4369,0
,10302589.2278125,249.997603125,0.07,0.199208755372504,50,10.0003795430668,8.31501170155209,-0.00201040785759687,5,20,25,4369,0
,10302592.4764844,250.002596093749,0.07,0.199208755372504,50,10.0003795430668,-9.41579800835226,-0.00155212199315429,5,103,25,4369,0
,10302624.3839844,249.9981671875,0.07,0.199208755372504,10,10.0004080549069,2.90296522463157,0.00191691244253889,5,58,25,4369,0
,10302648.5749609,250.011594921875,0.07,0.199208755372504,30,10.0003985509341,5.95723046143856,-0.00203790518248247,5,13,25,4369,0
,10302652.08625,250.003262500001,0.07,0.199208755372504,30,10.0003985509341,-10.0003985509341,0.00162489958003991,5,96,25,4369,0
,10302676.1182812,250.003889843751,0.07,0.199208755372504,50,10.0003795430668,5.95721913846527,0.00187816550023854,5,51,25,4369,0
,10302712.2159375,249.9978328125,0.07,0.199208755372504,10,10.0004080549069,2.90296522463157,-0.00205456366529688,5,6,25,4369,0
,10302715.9639062,250.00036171875,0.07,0.199208755372504,10,10.0004080549069,-9.41582485350607,0.00183948752237484,5,89,25,4369,0
,10302739.7565625,249.993256250001,0.07,0.199208755372504,30,10.0003985509341,8.31502750601608,0.00183936887575934,5,44,25,4369,0
,10302743.070078,249.987420312502,0.07,0.199208755372504,30,10.0003985509341,-0.490696299241616,-0.00205638559742107,5,127,25,4369,0
,10302767.3620313,249.999565625,0.07,0.199208755372504,50,10.0003795430668,-7.73039792438554,0.00188615657389164,5,82,25,4369,0
,10302799.0182813,250.009138671875,0.07,0.199208755372504,10,10.0004080549069,9.70070835795815,0.000724379206076266,5,37,25,4369,0
,10302802.55875,250.008328124999,0.07,0.199208755372504,10,10.0004080549069,-3.82699047950326,-0.00203601084649563,5,120,25,4369,0
,10302826.5135937,250.003997265625,0.07,0.199208755372504,30,10.0003985509341,-5.14123233806112,0.00190808185531447,5,75,25,4369,0
,10302850.0158594,250.00146875,0.07,0.199208755372504,50,10.0003795430668,9.9522249821852,-0.00181291121989488,5,30,25,4369,0
,10302853.3520703,250.004840625,0.07,0.199208755372504,50,10.0003795430668,-6.71584443401547,-0.00199368577450514,5,113,25,4369,0
,10302884.4503125,249.998248437501,0.07,0.199208755372504,10,10.0004080549069,-1.95098282772447,0.00191318686120212,5,68,25,4369,0
,10302909.2725391,249.993108203125,0.07,0.199208755372504,30,10.0003985509341,9.04025321701159,-0.00197560177184641,5,23,25,4369,0
,10302912.9264844,249.990611718749,0.07,0.199208755372504,30,10.0003985509341,-8.81956413402722,-0.00193109871664395,5,106,25,4369,0
,10302938.0760157,249.99334140625,0.07,0.199208755372504,50,10.0003795430668,1.46736043508789,0.00191077538765967,5,61,25,4369,0
,10302972.399375,250.01100625,0.07,0.199208755372504,10,10.0004080549069,7.07135635025724,-0.00205152726266533,5,16,25,4369,0
,10302975.9236328,250.007666796874,0.07,0.199208755372504,10,10.0004080549069,-9.89216873797649,0.00129911320982501,5,99,25,4369,0
,10302999.448125,250.00266484375,0.07,0.199208755372504,30,10.0003985509341,4.71415524386975,0.00190343992370698,5,54,25,4369,0
,10303023.4835547,249.99315703125,0.07,0.199208755372504,50,10.0003795430668,4.27571320987422,-0.00205057985149324,5,9,25,4369,0
,10303027.0207812,249.997371875,0.07,0.199208755372504,50,10.0003795430668,-9.80822505428553,0.00179447238333523,5,92,25,4369,0
,10303059.6674219,250.000275,0.07,0.199208755372504,10,10.0004080549069,7.40981360229206,0.00182727671926841,5,47,25,4369,0
,10303084.0630469,249.99806015625,0.07,0.199208755372504,30,10.0003985509341,0.980210468118438,-0.00206009213191768,5,2,25,4369,0
,10303087.5094922,249.996406640624,0.07,0.199208755372504,30,10.0003985509341,-8.57762794854141,0.00186185158478717,5,85,25,4369,0
,10303111.5146875,250.002212499999,0.07,0.199208755372504,50,10.0003795430668,9.23914597718402,0.00174302407540381,5,40,25,4369,0
,10303115.207539,250.008048437498,0.07,0.199208755372504,50,10.0003795430668,-2.4298940204753,-0.00204356117174029,5,123,25,4369,0
,10303149.8059375,250.00576484375,0.07,0.199208755372504,10,10.0004080549069,-6.34419170892896,0.00190398335689679,5,78,25,4369,0
,10303173.5094531,250.002933203125,0.07,0.199208755372504,30,10.0003985509341,9.98835263291373,-5.14667610534354E-5,5,33,25,4369,0
,10303176.9915624,250.012951562499,0.07,0.199208755372504,30,10.0003985509341,-5.55592375323133,-0.00202691512337575,5,116,25,4369,0
,10303200.7730859,249.9984078125,0.07,0.199208755372504,50,10.0003795430668,-3.36902639813034,0.00191368707455695,5,71,25,4369,0
,10303233.5025781,250.00080546875,0.07,0.199208755372504,10,10.0004080549069,9.56979384152169,-0.00195658125448972,5,26,25,4369,0
,10303236.9425391,249.987415234376,0.07,0.199208755372504,10,10.0004080549069,-8.03240306758092,-0.00183868309250101,5,109,25,4369,0
,10303261.105,250.0037,0.07,0.199208755372504,30,10.0003985509341,1.22465516062299E-15,0.00191222662882259,5,64,25,4369,0
,10303285.5160938,249.987257421875,0.07,0.199208755372504,50,10.0003795430668,8.03238016665625,-0.00201421300880611,5,19,25,4369,0
,10303289.2121875,249.991439843751,0.07,0.199208755372504,50,10.0003795430668,-9.56976655739189,-0.0012625087518245,5,102,25,4369,0
,10303324.7730078,249.999215625001,0.07,0.199208755372504,10,10.0004080549069,3.36903600347996,0.00190374470548704,5,57,25,4369,0
,10303348.48125,249.9928265625,0.07,0.199208755372504,30,10.0003985509341,5.55592375323133,-0.00204061481377317,5,12,25,4369,0
,10303352.1903125,249.993701953124,0.07,0.199208755372504,30,10.0003985509341,-9.98835263291373,0.00168360349360026,5,95,25,4369,0
,10303375.4292969,250.00118359375,0.07,0.199208755372504,50,10.0003795430668,6.34417362120911,0.0018722141161561,5,50,25,4369,0
,10303406.7511328,250.010297265625,0.07,0.199208755372504,10,10.0004080549069,2.42990094828733,-0.00205427466426045,5,5,25,4369,0
,10303410.2559375,250.005271875,0.07,0.199208755372504,10,10.0004080549069,-9.23917231868949,0.00186566758202389,5,88,25,4369,0
,10303434.3501953,249.999860156251,0.07,0.199208755372504,30,10.0003985509341,8.57762794854141,0.00183521614720424,5,43,25,4369,0
,10303437.7188281,250.006539062502,0.07,0.199208755372504,30,10.0003985509341,-0.980210468118437,-0.00205838748823023,5,126,25,4369,0
,10303462.6269141,250.006009375,0.07,0.199208755372504,50,10.0003795430668,-7.40979247641208,0.00189392892643809,5,81,25,4369,0
,10303499.3346875,250.0007328125,0.07,0.199208755372504,10,10.0004080549069,9.80825301827859,0.000336718221660703,5,36,25,4369,0
,10303503.2188281,250.003229296876,0.07,0.199208755372504,10,10.0004080549069,-4.27572540025666,-0.00203651754418388,5,119,25,4369,0
,10303527.9439063,249.996651562501,0.07,0.199208755372504,30,10.0003985509341,-4.71415524386975,0.00190579565241933,5,74,25,4369,0
,10303551.9643359,249.989366796875,0.07,0.199208755372504,50,10.0003795430668,9.89214053473404,-0.00185502306558192,5,29,25,4369,0
,10303555.6831249,249.992706250001,0.07,0.199208755372504,50,10.0003795430668,-7.07133618934179,-0.00199016104452312,5,112,25,4369,0
,10303589.4960156,250.002278125,0.07,0.199208755372504,10,10.0004080549069,-1.46736461864371,0.00191503728274256,5,67,25,4369,0
,10303613.9275781,250.01354453125,0.07,0.199208755372504,30,10.0003985509341,8.81956413402722,-0.00198166675141288,5,22,25,4369,0
,10303617.4648046,250.007676171875,0.07,0.199208755372504,30,10.0003985509341,-9.04025321701159,-0.00190976431541559,5,105,25,4369,0
,10303641.5892187,249.9927265625,0.07,0.199208755372504,50,10.0003795430668,1.95097726534041,0.00191363287158311,5,60,25,4369,0
,10303677.4691016,249.9901,0.07,0.199208755372504,10,10.0004080549069,6.71586358139698,-0.00204618903808296,5,15,25,4369,0
,10303681.2267969,249.994249999999,0.07,0.199208755372504,10,10.0004080549069,-9.95225335673296,0.00157007045345381,5,98,25,4369,0
,10303704.8710547,249.999944140625,0.07,0.199208755372504,30,10.0003985509341,5.14123233806112,0.00190207417795642,5,53,25,4369,0
,10303728.745625,249.99801875,0.07,0.199208755372504,50,10.0003795430668,3.82697956849444,-0.00204928270541132,5,8,25,4369,0
,10303732.3314844,249.99717578125,0.07,0.199208755372504,50,10.0003795430668,-9.7006807005822,0.00181221729144454,5,91,25,4369,0
,10303768.8003906,250.005484375,0.07,0.199208755372504,10,10.0004080549069,7.73041996433595,0.00181066861841828,5,46,25,4369,0
,10303792.3783594,250.0032296875,0.07,0.199208755372504,30,10.0003985509341,0.490696299241615,-0.00206004194397893,5,1,25,4369,0
,10303795.9771875,250.00154375,0.07,0.199208755372504,30,10.0003985509341,-8.31502750601608,0.00187368073966354,5,84,25,4369,0
,10303820.2448047,250.00497734375,0.07,0.199208755372504,50,10.0003795430668,9.41579800835227,0.00169500005431473,5,39,25,4369,0
,10303823.6069531,249.994926562499,0.07,0.199208755372504,50,10.0003795430668,-2.90295694808129,-0.00204172399826348,5,122,25,4369,0
,10303855.4291406,249.998583984376,0.07,0.199208755372504,10,10.0004080549069,-5.95723612294857,0.00191151775652543,5,77,25,4369,0
,10303879.2525,250.0022125,0.07,0.199208755372504,30,10.0003985509341,10.0003985509341,-0.0011506606824696,5,32,25,4369,0
,10303882.6697656,250.015602734374,0.07,0.199208755372504,30,10.0003985509341,-5.95723046143856,-0.002019723243494,5,115,25,4369,0
,10303907.5334375,249.988228125001,0.07,0.199208755372504,50,10.0003795430668,-2.90295694808129,0.00191369936801493,5,70,25,4369,0
,10303943.6711719,250.007390234375,0.07,0.199208755372504,10,10.0004080549069,9.41582485350606,-0.00198025023564696,5,25,25,4369,0
,10303947.2440625,250.003207812499,0.07,0.199208755372504,10,10.0004080549069,-8.31503540828069,-0.00175253226188943,5,108,25,4369,0
,10303971.5132812,250.003123828124,0.07,0.199208755372504,30,10.0003985509341,0.490696299241615,0.00192607060954389,5,63,25,4369,0
,10303996.1110156,250.004834375,0.07,0.199208755372504,50,10.0003795430668,7.73039792438553,-0.00201987829059362,5,18,25,4369,0
,10303999.7584766,250.0031484375,0.07,0.199208755372504,50,10.0003795430668,-9.7006807005822,-0.000743823498487472,5,101,25,4369,0
,10304033.920625,249.9863875,0.07,0.199208755372504,10,10.0004080549069,3.82699047950326,0.00189518585102633,5,56,25,4369,0
,10304058.3942188,249.988904296875,0.07,0.199208755372504,30,10.0003985509341,5.14123233806112,-0.00204408476646576,5,11,25,4369,0
,10304061.9346875,249.997236718749,0.07,0.199208755372504,30,10.0003985509341,-9.95224389852435,0.00172173901874986,5,94,25,4369,0
,10304086.1132813,250.00035390625,0.07,0.199208755372504,50,10.0003795430668,6.71584443401547,0.00187026998028159,5,49,25,4369,0
,10304116.9625,250.0060578125,0.07,0.199208755372504,10,10.0004080549069,1.95098282772447,-0.00204994343221188,5,4,25,4369,0
,10304120.645625,250.001032421875,0.07,0.199208755372504,10,10.0004080549069,-9.04026180850128,0.0018743725377135,5,87,25,4369,0
,10304146.0484375,250.00300703125,0.07,0.199208755372504,30,10.0003985509341,8.81956413402722,0.00182228971324447,5,42,25,4369,0
,10304149.7704688,250.004206640626,0.07,0.199208755372504,30,10.0003985509341,-1.46736322412126,-0.00205118681252417,5,125,25,4369,0
,10304173.6425,249.99593125,0.07,0.199208755372504,50,10.0003795430668,-7.07133618934179,0.00189363895915449,5,80,25,4369,0
,10304208.1919531,250.00587109375,0.07,0.199208755372504,10,10.0004080549069,9.89216873797649,-0.000176722533069551,5,35,25,4369,0
,10304211.6351562,250.008529687498,0.07,0.199208755372504,10,10.0004080549069,-4.71415972401154,-0.00200763461180031,5,118,25,4369,0
,10304235.5254297,250.005885546875,0.07,0.199208755372504,30,10.0003985509341,-4.27572133678467,0.00191557369867547,5,73,25,4369,0
,10304260.1671875,249.9895984375,0.07,0.199208755372504,50,10.0003795430668,9.80822505428553,-0.00189209883101284,5,28,25,4369,0
,10304263.5974218,250.001302734374,0.07,0.199208755372504,50,10.0003795430668,-7.40979247641208,-0.00197409014217556,5,111,25,4369,0
,10304294.8652344,250.000620312501,0.07,0.199208755372504,10,10.0004080549069,-0.980211399670677,0.00191326515050605,5,66,25,4369,0
,10304318.457461,250.0063203125,0.07,0.199208755372504,30,10.0003985509341,8.57762794854141,-0.00199250049061245,5,21,25,4369,0
,10304322.2021876,249.9929625,0.07,0.199208755372504,30,10.0003985509341,-9.23916353816351,-0.00187490872728328,5,104,25,4369,0
,10304347.1970704,249.997727734375,0.07,0.199208755372504,50,10.0003795430668,2.4298940204753,0.00190988117828965,5,59,25,4369,0
,10304383.0615625,250.00446875,0.07,0.199208755372504,10,10.0004080549069,6.34419170892896,-0.00204639480216429,5,14,25,4369,0
,10304386.8354687,250.007840625,0.07,0.199208755372504,10,10.0004080549069,-9.98836212543862,0.00168087106430903,5,97,25,4369,0
,10304411.716875,249.994,0.07,0.199208755372504,30,10.0003985509341,5.55592375323133,0.0018963429869877,5,52,25,4369,0
,10304436.4030469,250.008726171875,0.07,0.199208755372504,50,10.0003795430668,3.36902639813034,-0.00204911264590919,5,7,25,4369,0
,10304439.9370313,249.999550781251,0.07,0.199208755372504,50,10.0003795430668,-9.56976655739189,0.00182671435177326,5,90,25,4369,0
,10304474.2214453,250.0011640625,0.07,0.199208755372504,10,10.0004080549069,8.03240306758093,0.00179239781573415,5,45,25,4369,0
,10304499.49,250.00545,0.07,0.199208755372504,30,10.0003985509341,0,-0.0020546264325579,5,0,25,4369,0
,10304503.0726172,250.008789453126,0.07,0.199208755372504,30,10.0003985509341,-8.03239543391837,0.00187567784450948,5,83,25,4369,0
,10304527.7304688,249.99529375,0.07,0.199208755372504,50,10.0003795430668,9.56976655739189,0.00161648467183113,5,38,25,4369,0
,10304530.9532032,250.002815625002,0.07,0.199208755372504,50,10.0003795430668,-3.36902639813034,-0.00203756620176136,5,121,25,4369,0
,10304565.5770313,249.9898984375,0.07,0.199208755372504,10,10.0004080549069,-5.55592903335573,0.00189738551853225,5,76,25,4369,0
,10304590.5046094,250.001108203125,0.07,0.199208755372504,30,10.0003985509341,9.98835263291373,-0.00166649212284634,5,31,25,4369,0
,10304594.0645313,249.99523984375,0.07,0.199208755372504,30,10.0003985509341,-6.34418567967242,-0.00202154158614576,5,114,25,4369,0
,10304618.0123438,250.003548437501,0.07,0.199208755372504,50,10.0003795430668,-2.4298940204753,0.00191612634807825,5,69,25,4369,0
,10304652.5615625,250.003784375,0.07,0.199208755372504,10,10.0004080549069,9.23917231868949,-0.00198858528165147,5,24,25,4369,0
,10304655.9042578,250.000444921874,0.07,0.199208755372504,10,10.0004080549069,-8.57763610037082,-0.00165724399266765,5,107,25,4369,0
,10304679.6996875,249.986321874999,0.07,0.199208755372504,30,10.0003985509341,0.980210468118436,0.00191872072820034,5,62,25,4369,0
,10304704.0360937,249.9990546875,0.07,0.199208755372504,50,10.0003795430668,7.40979247641208,-0.00202319188974798,5,17,25,4369,0
,10304707.6543749,249.99736875,0.07,0.199208755372504,50,10.0003795430668,-9.80822505428553,3.20431776344794E-5,5,100,25,4369,0
,10304739.4788281,250.008814453125,0.07,0.199208755372504,10,10.0004080549069,4.27572540025666,0.00188928592251614,5,55,25,4369,0
,10304763.5672656,249.9936984375,0.07,0.199208755372504,30,10.0003985509341,4.71415524386975,-0.00204734213184565,5,10,25,4369,0
,10304766.8645703,249.99285546875,0.07,0.199208755372504,30,10.0003985509341,-9.89215933686981,0.00175934220250282,5,93,25,4369,0
,10304791.160625,249.998662500001,0.07,0.199208755372504,50,10.0003795430668,7.07133618934179,0.00186468190513551,5,48,25,4369,0
,10304822.5585547,250.019418359375,0.07,0.199208755372504,10,10.0004080549069,1.46736461864371,-0.0020563168800436,5,3,25,4369,0
,10304826.1152343,250.01439296875,0.07,0.199208755372504,10,10.0004080549069,-8.81957251578296,0.00187871570233256,5,86,25,4369,0
,10304849.8427735,249.995782421875,0.07,0.199208755372504,30,10.0003985509341,9.04025321701159,0.00181177307644652,5,41,25,4369,0
,10304853.1076563,250.004957812499,0.07,0.199208755372504,30,10.0003985509341,-1.95098097359134,-0.00204572221264243,5,124,25,4369,0
,10304877.800625,249.998738281249,0.07,0.199208755372504,50,10.0003795430668,-6.71584443401547,0.00190413612872362,5,79,25,4369,0
,10304913.2920313,249.99755078125,0.07,0.199208755372504,10,10.0004080549069,9.95225335673296,-0.000739527749828993,5,34,25,4369,0
,10304916.8000782,249.990839453125,0.07,0.199208755372504,10,10.0004080549069,-5.14123722407964,-0.00202249269932508,5,117,25,4369,0
,10304941.49125,249.997637500001,0.07,0.199208755372504,30,10.0003985509341,-3.82698684249031,0.00191870054954456,5,72,25,4369,0
,10304965.5371875,249.996441015625,0.07,0.199208755372504,50,10.0003795430668,9.7006807005822,-0.00191492717713118,5,27,25,4369,0
,10304968.9868749,249.99057265625,0.07,0.199208755372504,50,10.0003795430668,-7.73039792438553,-0.00196327609010041,5,110,25,4369,0
,10305005.2223438,249.998575390625,0.07,0.199208755372504,10,10.0004080549069,-0.490696765579461,0.0019224314019084,5,65,25,4369,0
,10305029.3384375,249.994740625,0.07,0.199208755372504,30,10.0003985509341,8.31502750601608,-0.00200199965749764,5,20,25,4369,0
,10305033.1707032,249.99221171875,0.07,0.199208755372504,30,10.0003985509341,-9.41581590509684,-0.00182357422697047,5,103,25,4369,0
,10305057.9966406,250.002542187501,0.07,0.199208755372504,50,10.0003795430668,2.90295694808128,0.00190775576047599,5,58,25,4369,0
,10305093.3125391,249.990594921875,0.07,0.199208755372504,10,10.0004080549069,5.95723612294857,-0.00203502975637093,5,13,25,4369,0
,10305097.0637501,249.986412499999,0.07,0.199208755372504,10,10.0004080549069,-10.0004080549069,0.00173158710822463,5,96,25,4369,0
,10305120.8679688,249.997266796874,0.07,0.199208755372504,30,10.0003985509341,5.95723046143856,0.00189454689259744,5,51,25,4369,0
,10305144.5232031,249.99315625,0.07,0.199208755372504,50,10.0003795430668,2.90295694808128,-0.00205193762667477,5,6,25,4369,0
,10305147.9566797,249.989784375,0.07,0.199208755372504,50,10.0003795430668,-9.41579800835227,0.00184074733406305,5,89,25,4369,0
,10305178.9973437,249.99971875,0.07,0.199208755372504,10,10.0004080549069,8.31503540828069,0.00176234636455774,5,44,25,4369,0
,10305182.6707422,250.001923437501,0.07,0.199208755372504,10,10.0004080549069,-0.49069676557946,-0.0020466951536946,5,127,25,4369,0
,10305207.0622657,250.0095984375,0.07,0.199208755372504,30,10.0003985509341,-7.7304126176656,0.00188639064112471,5,82,25,4369,0
,10305229.8192187,249.99555,0.07,0.199208755372504,50,10.0003795430668,9.7006807005822,0.00147627824917436,5,37,25,4369,0
,10305233.1262499,249.99555,0.07,0.199208755372504,50,10.0003795430668,-3.82697956849444,-0.00203285505995154,5,120,25,4369,0
,10305265.0675782,249.994947265625,0.07,0.199208755372504,10,10.0004080549069,-5.14123722407963,0.00192249397514388,5,75,25,4369,0
,10305289.4778906,250.007140625,0.07,0.199208755372504,30,10.0003985509341,9.95224389852435,-0.00176168790656245,5,30,25,4369,0
,10305293.2485547,250.001304687502,0.07,0.199208755372504,30,10.0003985509341,-6.71585719891892,-0.00200718473125663,5,113,25,4369,0
,10305318.9553125,250.000418750001,0.07,0.199208755372504,50,10.0003795430668,-1.95097726534041,0.00191945508122444,5,68,25,4369,0
,10305352.8083594,250.001724609375,0.07,0.199208755372504,10,10.0004080549069,9.04026180850127,-0.00199603207875043,5,23,25,4369,0
,10305356.6276563,249.998385156249,0.07,0.199208755372504,10,10.0004080549069,-8.81957251578297,-0.00152579421410337,5,106,25,4369,0
,10305380.9839844,249.998508593751,0.07,0.199208755372504,30,10.0003985509341,1.46736322412127,0.00191853763276918,5,61,25,4369,0
,10305405.503125,249.9998875,0.07,0.199208755372504,50,10.0003795430668,7.07133618934179,-0.00202870885841549,5,16,25,4369,0
,10305409.0727735,249.99904453125,0.07,0.199208755372504,50,10.0003795430668,-9.89214053473404,0.000889961235225199,5,99,25,4369,0
,10305444.4950782,249.99877109375,0.07,0.199208755372504,10,10.0004080549069,4.71415972401154,0.00190499762538821,5,54,25,4369,0
,10305468.3211719,250.000436328125,0.07,0.199208755372504,30,10.0003985509341,4.27572133678467,-0.00204389054690384,5,9,25,4369,0
,10305472.2053125,250.0063046875,0.07,0.199208755372504,30,10.0003985509341,-9.80824369692192,0.00178212364618149,5,92,25,4369,0
,10305496.0767578,249.997835937499,0.07,0.199208755372504,50,10.0003795430668,7.40979247641208,0.0018590247258544,5,47,25,4369,0
,10305531.9528125,249.99789921875,0.07,0.199208755372504,10,10.0004080549069,0.980211399670678,-0.00204226846108213,5,2,25,4369,0
,10305535.1820313,249.997866796876,0.07,0.199208755372504,10,10.0004080549069,-8.57763610037082,0.00187274941708893,5,85,25,4369,0
,10305558.88875,250.004228125001,0.07,0.199208755372504,30,10.0003985509341,9.23916353816351,0.0017945098483728,5,40,25,4369,0
,10305562.4032813,249.988308984377,0.07,0.199208755372504,30,10.0003985509341,-2.4298986390103,-0.00204939317579071,5,123,25,4369,0
,10305587.0009375,249.99467421875,0.07,0.199208755372504,50,10.0003795430668,-6.34417362120911,0.00190508142113686,5,78,25,4369,0
,10305623.4132812,250.0051984375,0.07,0.199208755372504,10,10.0004080549069,9.98836212543862,-0.00130248779896647,5,33,25,4369,0
,10305627.005625,249.98846875,0.07,0.199208755372504,10,10.0004080549069,-5.55592903335573,-0.00201222515897825,5,116,25,4369,0
,10305650.936914,250.0027078125,0.07,0.199208755372504,30,10.0003985509341,-3.36903280168795,0.00191887834161106,5,71,25,4369,0
,10305675.3169531,250.00936171875,0.07,0.199208755372504,50,10.0003795430668,9.56976655739189,-0.00193789578042924,5,26,25,4369,0
,10305678.8347265,249.999343359376,0.07,0.199208755372504,50,10.0003795430668,-8.03238016665625,-0.00194681030698121,5,109,25,4369,0
,10305714.9075,249.997699999999,0.07,0.199208755372504,10,10.0004080549069,1.22465632448555E-15,0.0019100506324321,5,64,25,4369,0
,10305738.3509375,249.99236484375,0.07,0.199208755372504,30,10.0003985509341,8.03239543391837,-0.00200219012589918,5,19,25,4369,0
,10305741.6968751,249.9965796875,0.07,0.199208755372504,30,10.0003985509341,-9.56978474678674,-0.0017291962608902,5,102,25,4369,0
,10305765.9085547,250.000165625,0.07,0.199208755372504,50,10.0003795430668,3.36902639813034,0.00190608450211584,5,57,25,4369,0
,10305803.1296875,249.98718125,0.07,0.199208755372504,10,10.0004080549069,5.55592903335573,-0.00203867326490581,5,12,25,4369,0
,10305806.7933594,250.0005390625,0.07,0.199208755372504,10,10.0004080549069,-9.98836212543862,0.00175148190464824,5,95,25,4369,0
,10305831.5165625,249.995660937499,0.07,0.199208755372504,30,10.0003985509341,6.34418567967242,0.00189348680174185,5,50,25,4369,0
,10305857.30625,250.01029921875,0.07,0.199208755372504,50,10.0003795430668,2.4298940204753,-0.00205007311888039,5,5,25,4369,0
,10305861.1450001,250.005306250001,0.07,0.199208755372504,50,10.0003795430668,-9.23914597718402,0.00185268162749708,5,88,25,4369,0
,10305893.5563672,250.00155,0.07,0.199208755372504,10,10.0004080549069,8.57763610037082,0.00171477033291012,5,43,25,4369,0
,10305897.2167969,250.00155,0.07,0.199208755372504,10,10.0004080549069,-0.980211399670677,-0.00206101511139423,5,126,25,4369,0
,10305921.0401953,250.002313671876,0.07,0.199208755372504,30,10.0003985509341,-7.4098065603127,0.00189313574487136,5,81,25,4369,0
,10305946.3114062,249.9930796875,0.07,0.199208755372504,50,10.0003795430668,9.80822505428553,0.00122160813771188,5,36,25,4369,0
,10305950.1533984,250.002255078124,0.07,0.199208755372504,50,10.0003795430668,-4.27571320987422,-0.00202611042186618,5,119,25,4369,0
,10305985.0589063,250.001336718749,0.07,0.199208755372504,10,10.0004080549069,-4.71415972401153,0.00191163009731099,5,74,25,4369,0
,10306008.9003125,249.9970953125,0.07,0.199208755372504,30,10.0003985509341,9.89215933686981,-0.00181999225686822,5,29,25,4369,0
,10306012.3499999,250.009675000001,0.07,0.199208755372504,30,10.0003985509341,-7.0713496299336,-0.00200284496208446,5,112,25,4369,0
,10306036.1488671,250.006049609376,0.07,0.199208755372504,50,10.0003795430668,-1.46736043508789,0.0019210975151509,5,67,25,4369,0
,10306068.0092188,250.00837109375,0.07,0.199208755372504,10,10.0004080549069,8.81957251578297,-0.00199178582988679,5,22,25,4369,0
,10306071.2319531,250.001659765625,0.07,0.199208755372504,10,10.0004080549069,-9.04026180850127,-0.00136461138026789,5,105,25,4369,0
,10306094.4965625,249.998803125,0.07,0.199208755372504,30,10.0003985509341,1.95098097359135,0.0019151926971972,5,60,25,4369,0
,10306118.6710547,250.0062953125,0.07,0.199208755372504,50,10.0003795430668,6.71584443401547,-0.00202891589142382,5,15,25,4369,0
,10306122.1628906,250.000459375001,0.07,0.199208755372504,50,10.0003795430668,-9.9522249821852,0.00143624194897711,5,98,25,4369,0
,10306154.86375,249.9863078125,0.07,0.199208755372504,10,10.0004080549069,5.14123722407964,0.00189182872418314,5,53,25,4369,0
,10306179.0440625,250.000171875,0.07,0.199208755372504,30,10.0003985509341,3.82698684249032,-0.00205047357465244,5,8,25,4369,0
,10306182.5618359,249.999361328124,0.07,0.199208755372504,30,10.0003985509341,-9.70069913880747,0.00180572814618548,5,91,25,4369,0
,10306207.0591407,250.00416484375,0.07,0.199208755372504,50,10.0003795430668,7.73039792438553,0.0018516190815717,5,46,25,4369,0
,10306241.4370703,250.006369140625,0.07,0.199208755372504,10,10.0004080549069,0.490696765579459,-0.00205302319955081,5,1,25,4369,0
,10306244.9289062,249.995507812501,0.07,0.199208755372504,10,10.0004080549069,-8.31503540828069,0.00189096695976332,5,84,25,4369,0
,10306268.9637891,249.999019140625,0.07,0.199208755372504,30,10.0003985509341,9.41581590509684,0.00177629634789708,5,39,25,4369,0
,10306272.4621094,250.002358593751,0.07,0.199208755372504,30,10.0003985509341,-2.90296246577389,-0.00204501667111698,5,122,25,4369,0
,10306296.1733593,250.006148046875,0.07,0.199208755372504,50,10.0003795430668,-5.95721913846527,0.00190702248364687,5,77,25,4369,0
,10306328.46,250.005925,0.07,0.199208755372504,10,10.0004080549069,10.0004080549069,-0.00165872887009755,5,32,25,4369,0
,10306332.1560938,250.01013984375,0.07,0.199208755372504,10,10.0004080549069,-5.95723612294856,-0.00201315298909321,5,115,25,4369,0
,10306355.9238281,250.001383593751,0.07,0.199208755372504,30,10.0003985509341,-2.90296246577389,0.00191705877013091,5,70,25,4369,0
,10306379.95375,250.000415625,0.07,0.199208755372504,50,10.0003795430668,9.41579800835227,-0.00195421706885099,5,25,25,4369,0
,10306383.5849999,250.0037875,0.07,0.199208755372504,50,10.0003795430668,-8.31501170155209,-0.00192791540175677,5,108,25,4369,0
,10306419.4117187,250.010060937499,0.07,0.199208755372504,10,10.0004080549069,0.490696765579459,0.0019062141655013,5,63,25,4369,0
,10306443.2719531,249.99827578125,0.07,0.199208755372504,30,10.0003985509341,7.73041261766559,-0.00201846227153308,5,18,25,4369,0
,10306447.0620703,249.994936328124,0.07,0.199208755372504,30,10.0003985509341,-9.70069913880747,-0.00149050999122361,5,101,25,4369,0
,10306471.94875,250.004293749999,0.07,0.199208755372504,50,10.0003795430668,3.82697956849445,0.00190179562196135,5,56,25,4369,0
,10306507.4917578,249.99623515625,0.07,0.199208755372504,10,10.0004080549069,5.14123722407964,-0.00204019102966413,5,11,25,4369,0
,10306510.9382032,249.9987640625,0.07,0.199208755372504,10,10.0004080549069,-9.95225335673296,0.00178994960151613,5,94,25,4369,0
,10306535.9235156,249.99068828125,0.07,0.199208755372504,30,10.0003985509341,6.71585719891891,0.0018832961925202,5,49,25,4369,0
,10306559.8401562,250.006740625,0.07,0.199208755372504,50,10.0003795430668,1.95097726534041,-0.00204364093951881,5,4,25,4369,0
,10306563.6821484,250.011733593749,0.07,0.199208755372504,50,10.0003795430668,-9.04023603410313,0.00185491489246487,5,87,25,4369,0
,10306599.2370312,249.992459375,0.07,0.199208755372504,10,10.0004080549069,8.81957251578296,0.00164289027452469,5,42,25,4369,0
,10306602.7191405,250.001667187501,0.07,0.199208755372504,10,10.0004080549069,-1.46736461864371,-0.00205583055503667,5,125,25,4369,0
,10306627.011875,250.006681250001,0.07,0.199208755372504,30,10.0003985509341,-7.0713496299336,0.00190031229673574,5,80,25,4369,0
,10306650.9349219,250.001686328125,0.07,0.199208755372504,50,10.0003795430668,9.89214053473404,0.000770138250663876,5,35,25,4369,0
,10306654.5985938,249.997503906249,0.07,0.199208755372504,50,10.0003795430668,-4.71414628362317,-0.00202355608344078,5,118,25,4369,0
,10306690.5959766,249.998914453126,0.07,0.199208755372504,10,10.0004080549069,-4.27572540025667,0.00193865154869854,5,73,25,4369,0
,10306714.6448437,249.994896875,0.07,0.199208755372504,30,10.0003985509341,9.80824369692192,-0.00185890058572921,5,28,25,4369,0
,10306717.9940234,249.99236796875,0.07,0.199208755372504,30,10.0003985509341,-7.40980656031269,-0.00199158481943111,5,111,25,4369,0
,10306742.2753907,249.99459609375,0.07,0.199208755372504,50,10.0003795430668,-0.980208605021649,0.00192052228376269,5,66,25,4369,0
,10306778.3739453,250.00048984375,0.07,0.199208755372504,10,10.0004080549069,8.57763610037082,-0.00202625727979466,5,21,25,4369,0
,10306782.1640625,250.007168750001,0.07,0.199208755372504,10,10.0004080549069,-9.23917231868949,-0.00109028565930203,5,104,25,4369,0
,10306807.4122656,249.988953906249,0.07,0.199208755372504,30,10.0003985509341,2.4298986390103,0.00191806841434704,5,59,25,4369,0
,10306833.4201562,249.99597109375,0.07,0.199208755372504,50,10.0003795430668,6.34417362120911,-0.00203247223980725,5,14,25,4369,0
,10306836.8892968,249.998467578126,0.07,0.199208755372504,50,10.0003795430668,-9.98833364794231,0.0016193700954318,5,97,25,4369,0
,10306867.2475,250.0011578125,0.07,0.199208755372504,10,10.0004080549069,5.55592903335573,0.00190020626178011,5,52,25,4369,0
,10306891.1079687,250.000181640625,0.07,0.199208755372504,30,10.0003985509341,3.36903280168794,-0.00205192281605883,5,7,25,4369,0
,10306894.7003125,249.999371093749,0.07,0.199208755372504,30,10.0003985509341,-9.56978474678673,0.00181905711845805,5,90,25,4369,0
,10306919.9355078,249.992832421875,0.07,0.199208755372504,50,10.0003795430668,8.03238016665625,0.0018379726447165,5,45,25,4369,0
,10306923.526211,249.988700390624,0.07,0.199208755372504,50,10.0003795430668,-0.490695366569778,-0.00204540556296706,5,127,25,4369,0