File: dados/5k5p.raw
[Header]
; ACMS Raw Data File (default extension .raw)
; Copyright 1999, Quantum Design, Inc. All rights reserved.
TITLE,Xac-time_5K_5point_microfios-FeSiB_hac_10Oe_f_10Hz_28-04-24
FILEOPENTIME,10251963.58,04/28/2024,7:44 pm
BYAPP,ACMS,1.0,1.1,RAW
INFO,PPMS ACMS Option Version: 1.0.9 Build 14,APPNAME
INFO,HARMONICS,1
DATATYPE,COMMENT,1
DATATYPE,TIME,2
STARTUPAXIS,X,2,LINEAR,AUTO
STARTUPAXIS,Y,7,LINEAR,AUTO
STARTUPAXIS,Y,8,LINEAR,AUTO
TIMEMODE,MINUTES,RELATIVE
PLOT_APPEARANCE,ALL,HORZ_GRID_ON,VERT_GRID_ON,MARKERS_AND_LINES
RECORDS,ALL_RECORDS
DATATYPE,TIME,2
DATATYPE,COMMENT,1
[Data]
Comment,Time Stamp (sec),Temperature (K),Magnetic Field (Oe),Position (cm),Frequency (Hz),Amplitude (Oe),Drive (Oe),Signal (mV),Measure Type,Bin,Gain,PPMS Status (code),DSP Status (code)
,10251939.205,4.9798,0.07,0.199208755372504,10,10.0004080549069,0,-0.000376784591935575,5,0,25,4369,0
,10251942.8200391,4.99186093749999,0.07,0.199208755372504,10,10.0004080549069,-8.03240306758093,0.000309214228764176,5,83,25,4369,0
,10251968.4446875,4.99088750000001,0.07,0.199208755372504,30,10.0003985509341,9.56978474678673,0.000114585596343709,5,38,25,4369,0
,10251972.0370312,4.98725625000004,0.07,0.199208755372504,30,10.0003985509341,-3.36903280168794,-0.000361081393849518,5,121,25,4369,0
,10251996.5304688,4.99139374999997,0.07,0.199208755372504,50,10.0003795430668,-5.55591319302611,0.000314012821763754,5,76,25,4369,0
,10252030.0399219,4.983601953125,0.07,0.199208755372504,10,10.0004080549069,9.98836212543862,-9.08167567104101E-5,5,31,25,4369,0
,10252033.5739063,4.98240234375001,0.07,0.199208755372504,10,10.0004080549069,-6.34419170892896,-0.000239613873418421,5,114,25,4369,0
,10252057.2685547,4.96416601562503,0.07,0.199208755372504,30,10.0003985509341,-2.4298986390103,0.000319512263457808,5,69,25,4373,0
,10252081.5090625,5.07037812500001,0.07,0.199208755372504,50,10.0003795430668,9.23914597718402,-0.000200378429144621,5,24,25,4374,0
,10252085.0851954,5.07203164062504,0.07,0.199208755372504,50,10.0003795430668,-8.57761164494987,-0.000130452681332827,5,107,25,4374,0
,10252181.6869531,5.00140781250001,0.07,0.199208755372504,10,10.0004080549069,0.980211399670675,0.000323061249218881,5,62,25,4369,0
,10252205.1157422,5.00056679687499,0.07,0.199208755372504,30,10.0003985509341,7.40980656031269,-0.00034075023399459,5,17,25,4369,0
,10252208.7567188,5.00040468749996,0.07,0.199208755372504,30,10.0003985509341,-9.80824369692192,-2.64363673826058E-5,5,100,25,4369,0
,10252232.4178125,4.99997070312502,0.07,0.199208755372504,50,10.0003795430668,4.27571320987422,0.000311334058642387,5,55,25,4369,0
,10252264.0403125,5.00051484375,0.07,0.199208755372504,10,10.0004080549069,4.71415972401153,-0.000373447546735406,5,10,25,4369,0
,10252267.5289063,5.000223046875,0.07,0.199208755372504,10,10.0004080549069,-9.89216873797649,0.000176850298885256,5,93,25,4369,0
,10252291.281875,5.00003749999999,0.07,0.199208755372504,30,10.0003985509341,7.0713496299336,0.000294167677768403,5,48,25,4369,0
,10252315.4075391,5.0001953125,0.07,0.199208755372504,50,10.0003795430668,1.46736043508789,-0.000368419336155057,5,3,25,4369,0
,10252319.0744531,5.00006562500003,0.07,0.199208755372504,50,10.0003795430668,-8.81954737058493,0.000288052298128605,5,86,25,4369,0
,10252355.1753125,5.00041992187498,0.07,0.199208755372504,10,10.0004080549069,9.04026180850127,0.000120133627206088,5,41,25,4369,0
,10252358.72875,5.00025781249995,0.07,0.199208755372504,10,10.0004080549069,-1.95098282772447,-0.000360993435606361,5,124,25,4369,0
,10252381.8483985,5.00095624999998,0.07,0.199208755372504,30,10.0003985509341,-6.71585719891891,0.000310735582994918,5,79,25,4369,0
,10252404.4826563,5.00034375,0.07,0.199208755372504,50,10.0003795430668,9.9522249821852,1.22680794447662E-5,5,34,25,4369,0
,10252408.0166407,5.00008437499999,0.07,0.199208755372504,50,10.0003795430668,-5.14122256606442,-0.000337381893768907,5,117,25,4369,0
,10252441.6865626,4.999603125,0.07,0.199208755372504,10,10.0004080549069,-3.82699047950326,0.000333877978846431,5,72,25,4369,0
,10252465.793125,5.00007148437499,0.07,0.199208755372504,30,10.0003985509341,9.70069913880747,-0.00011711847037077,5,27,25,4369,0
,10252469.4762501,5.00075234374997,0.07,0.199208755372504,30,10.0003985509341,-7.73041261766559,-0.000215249731101924,5,110,25,4369,0
,10252494.0834765,5.00095078124999,0.07,0.199208755372504,50,10.0003795430668,-0.490695366569778,0.000323020666837692,5,65,25,4369,0
,10252524.8890625,5.000684375,0.07,0.199208755372504,10,10.0004080549069,8.31503540828069,-0.000328069436363876,5,20,25,4369,0
,10252528.3711718,5.00061953125002,0.07,0.199208755372504,10,10.0004080549069,-9.41582485350606,-1.58449984155598E-5,5,103,25,4369,0
,10252553.3473438,4.99991406249998,0.07,0.199208755372504,30,10.0003985509341,2.90296246577389,0.000313459701525668,5,58,25,4369,0
,10252577.8328125,4.99949140625,0.07,0.199208755372504,50,10.0003795430668,5.95721913846527,-0.000360645446926356,5,13,25,4369,0
,10252581.4900001,5.000075,0.07,0.199208755372504,50,10.0003795430668,-10.0003795430668,6.12634234130386E-5,5,96,25,4369,0
,10252615.9960546,5.00014101562502,0.07,0.199208755372504,10,10.0004080549069,5.95723612294857,0.000285701826214791,5,51,25,4369,0
,10252640.5680469,4.999709375,0.07,0.199208755372504,30,10.0003985509341,2.90296246577389,-0.000365526583563123,5,6,25,4369,0
,10252643.9301953,4.99983906249996,0.07,0.199208755372504,30,10.0003985509341,-9.41581590509685,0.000192461367179122,5,89,25,4369,0
,10252667.9751563,4.99966250000001,0.07,0.199208755372504,50,10.0003795430668,8.31501170155208,0.000227765366435051,5,44,25,4369,0
,10252671.4086329,5.00044062500004,0.07,0.199208755372504,50,10.0003795430668,-0.490695366569778,-0.000366502068936825,5,127,25,4369,0
,10252702.5077344,5.0002234375,0.07,0.199208755372504,10,10.0004080549069,-7.73041996433595,0.000324088905472309,5,82,25,4369,0
,10252727.3548047,5.00138671875001,0.07,0.199208755372504,30,10.0003985509341,9.70069913880747,9.50924327803981E-5,5,37,25,4369,0
,10252731.1903125,5.00158125000004,0.07,0.199208755372504,30,10.0003985509341,-3.82698684249031,-0.000357508672297829,5,120,25,4369,0
,10252755.0126562,4.99951210937502,0.07,0.199208755372504,50,10.0003795430668,-5.14122256606441,0.000315812835469842,5,75,25,4369,0
,10252789.7469531,5.00035390625001,0.07,0.199208755372504,10,10.0004080549069,9.95225335673296,-0.000131001870613546,5,30,25,4369,0
,10252793.3490235,4.99967304687503,0.07,0.199208755372504,10,10.0004080549069,-6.71586358139698,-0.000240070221479982,5,113,25,4369,0
,10252816.8207812,5.00116250000001,0.07,0.199208755372504,30,10.0003985509341,-1.95098097359135,0.000322702884053191,5,68,25,4369,0
,10252841.696211,5.00124609374999,0.07,0.199208755372504,50,10.0003795430668,9.04023603410313,-0.000217147823423147,5,23,25,4369,0
,10252845.6160157,5.00105156249997,0.07,0.199208755372504,50,10.0003795430668,-8.81954737058493,-0.000114606413990259,5,106,25,4369,0
,10252876.2636329,5.00075976562498,0.07,0.199208755372504,10,10.0004080549069,1.46736461864371,0.000324300490319729,5,61,25,4369,0
,10252901.208125,5.0009625,0.07,0.199208755372504,30,10.0003985509341,7.0713496299336,-0.000351097421824104,5,16,25,4369,0
,10252904.9074609,5.00128671874999,0.07,0.199208755372504,30,10.0003985509341,-9.89215933686981,-1.17822006965678E-5,5,99,25,4369,0
,10252928.6025781,4.99967265624999,0.07,0.199208755372504,50,10.0003795430668,4.71414628362317,0.000310766045004129,5,54,25,4369,0
,10252958.9060547,5.0012,0.07,0.199208755372504,10,10.0004080549069,4.27572540025666,-0.00037472287658602,5,9,25,4369,0
,10252962.2357812,5.0012,0.07,0.199208755372504,10,10.0004080549069,-9.80825301827858,0.000191669969353825,5,92,25,4369,0
,10252985.2673437,5.00046249999998,0.07,0.199208755372504,30,10.0003985509341,7.40980656031269,0.000295166650580036,5,47,25,4369,0
,10253010.4750781,4.99985703125,0.07,0.199208755372504,50,10.0003795430668,0.980208605021649,-0.000367061840370298,5,2,25,4369,0
,10253014.0058203,5.000148828125,0.07,0.199208755372504,50,10.0003795430668,-8.57761164494987,0.000296231079846621,5,85,25,4369,0
,10253045.5653125,4.99990000000001,0.07,0.199208755372504,10,10.0004080549069,9.23917231868949,9.87658859230578E-5,5,40,25,4369,0
,10253049.0830859,5.00041875000003,0.07,0.199208755372504,10,10.0004080549069,-2.42990094828733,-0.000347966270055621,5,123,25,4369,0
,10253073.6685937,5.00068906250002,0.07,0.199208755372504,30,10.0003985509341,-6.34418567967242,0.000314340189409753,5,78,25,4369,0
,10253098.0560937,5.000801953125,0.07,0.199208755372504,50,10.0003795430668,9.98833364794231,-2.85399146378048E-6,5,33,25,4369,0
,10253101.466875,4.9999265625,0.07,0.199208755372504,50,10.0003795430668,-5.5559131930261,-0.000333405518904329,5,116,25,4369,0
,10253137.0516796,5.00028867187503,0.07,0.199208755372504,10,10.0004080549069,-3.36903600347996,0.000343224382959306,5,71,25,4369,0
,10253161.7201563,5.0006640625,0.07,0.199208755372504,30,10.0003985509341,9.56978474678673,-0.000143550892567469,5,26,25,4369,0
,10253165.2800781,4.99943203125002,0.07,0.199208755372504,30,10.0003985509341,-8.03239543391836,-0.000182939240605467,5,109,25,4369,0
,10253189.7225,5.00037500000002,0.07,0.199208755372504,50,10.0003795430668,1.2246528329075E-15,0.000323591381311417,5,64,25,4369,0
,10253224.3403516,5.00056640625,0.07,0.199208755372504,10,10.0004080549069,8.03240306758093,-0.000361617421731353,5,19,25,4369,0
,10253228.0332031,4.9999828125,0.07,0.199208755372504,10,10.0004080549069,-9.56979384152169,4.4325133785583E-7,5,102,25,4369,0
,10253252.5678516,5.00040507812501,0.07,0.199208755372504,30,10.0003985509341,3.36903280168794,0.000320214829925034,5,57,25,4369,0
,10253276.9682812,4.9995546875,0.07,0.199208755372504,50,10.0003795430668,5.5559131930261,-0.000360750779509545,5,12,25,4369,0
,10253280.3109765,5.00062460937503,0.07,0.199208755372504,50,10.0003795430668,-9.98833364794231,8.30129720270635E-5,5,95,25,4369,0
,10253311.0826562,5.00011718750001,0.07,0.199208755372504,10,10.0004080549069,6.34419170892896,0.00028802955057472,5,50,25,4369,0
,10253334.5002734,5.000328515625,0.07,0.199208755372504,30,10.0003985509341,2.4298986390103,-0.000370840037552019,5,5,25,4369,0
,10253337.9078126,4.99997187500002,0.07,0.199208755372504,30,10.0003985509341,-9.23916353816351,0.000214816472079191,5,88,25,4369,0
,10253361.4533594,4.99995312500001,0.07,0.199208755372504,50,10.0003795430668,8.57761164494987,0.000202918937429786,5,43,25,4369,0
,10253365.1948437,5.00073125000004,0.07,0.199208755372504,50,10.0003795430668,-0.980208605021648,-0.00036740517243743,5,126,25,4369,0
,10253397.7916016,5.00118164062499,0.07,0.199208755372504,10,10.0004080549069,-7.40981360229206,0.000317436060868203,5,81,25,4369,0
,10253422.1175,5.0006734375,0.07,0.199208755372504,30,10.0003985509341,9.80824369692192,7.29052893196543E-5,5,36,25,4369,0
,10253425.5931249,5.000381640625,0.07,0.199208755372504,30,10.0003985509341,-4.27572133678467,-0.000364597718645301,5,119,25,4369,0
,10253449.3458594,5.00071874999999,0.07,0.199208755372504,50,10.0003795430668,-4.71414628362317,0.000320661859586835,5,74,25,4369,0
,10253479.2117578,4.999665234375,0.07,0.199208755372504,10,10.0004080549069,9.89216873797649,-0.000157731410581619,5,29,25,4369,0
,10253482.379375,5.00028124999999,0.07,0.199208755372504,10,10.0004080549069,-7.07135635025724,-0.000197905173990876,5,112,25,4369,0
,10253506.6120313,5.00083828125001,0.07,0.199208755372504,30,10.0003985509341,-1.46736322412126,0.000324510167249375,5,67,25,4369,0
,10253531.8410156,5.00038125,0.07,0.199208755372504,50,10.0003795430668,8.81954737058493,-0.000241877278313041,5,22,25,4369,0
,10253535.3912109,5.00012187499999,0.07,0.199208755372504,50,10.0003795430668,-9.04023603410313,-9.76309645920991E-5,5,105,25,4369,0
,10253571.9889063,5.00060468749998,0.07,0.199208755372504,10,10.0004080549069,1.95098282772447,0.000311575713567436,5,60,25,4369,0
,10253596.9446875,5.000638671875,0.07,0.199208755372504,30,10.0003985509341,6.71585719891891,-0.000357444126469394,5,15,25,4369,0
,10253600.705625,5.00002265625001,0.07,0.199208755372504,30,10.0003985509341,-9.95224389852435,5.61076578580716E-6,5,98,25,4369,0
,10253625.8223438,5.00011093750001,0.07,0.199208755372504,50,10.0003795430668,5.14122256606442,0.000309651857241988,5,53,25,4369,0
,10253659.0290625,5.00149375,0.07,0.199208755372504,10,10.0004080549069,3.82699047950326,-0.000352482311427593,5,8,25,4369,0
,10253662.2355859,5.00039140624998,0.07,0.199208755372504,10,10.0004080549069,-9.70070835795815,0.000206065305974334,5,91,25,4369,0
,10253686.4322656,5.00032031250001,0.07,0.199208755372504,30,10.0003985509341,7.7304126176656,0.000284239132371214,5,46,25,4369,0
,10253710.7359375,4.99966171875,0.07,0.199208755372504,50,10.0003795430668,0.490695366569777,-0.000369779812172055,5,1,25,4369,0
,10253714.13375,5.00063437499998,0.07,0.199208755372504,50,10.0003795430668,-8.31501170155209,0.000301400059834123,5,84,25,4369,0
,10253750.5804688,5.00049062500001,0.07,0.199208755372504,10,10.0004080549069,9.41582485350606,7.68149038776758E-5,5,39,25,4369,0
,10253753.9653125,4.99919375000005,0.07,0.199208755372504,10,10.0004080549069,-2.90296522463158,-0.000344662694260478,5,122,25,4369,0
,10253778.1799219,5.00045937499999,0.07,0.199208755372504,30,10.0003985509341,-5.95723046143856,0.000317193852323625,5,77,25,4369,0
,10253802.975,5.00024999999999,0.07,0.199208755372504,50,10.0003795430668,10.0003795430668,-2.34229024499654E-5,5,32,25,4369,0
,10253806.5414062,5.00063906249997,0.07,0.199208755372504,50,10.0003795430668,-5.95721913846527,-0.000317856669425965,5,115,25,4369,0
,10253841.7371876,5.00055390625,0.07,0.199208755372504,10,10.0004080549069,-2.90296522463158,0.000329178292304277,5,70,25,4369,0
,10253865.6205859,4.99948906249999,0.07,0.199208755372504,30,10.0003985509341,9.41581590509685,-0.000160530067255928,5,25,25,4369,0
,10253869.2745312,4.99961874999996,0.07,0.199208755372504,30,10.0003985509341,-8.31502750601608,-0.000172091143516203,5,108,25,4369,0
,10253893.6563281,5.00034765625002,0.07,0.199208755372504,50,10.0003795430668,0.490695366569776,0.000322260847315192,5,63,25,4369,0
,10253929.5901562,5.00068124999999,0.07,0.199208755372504,10,10.0004080549069,7.73041996433595,-0.000367118627764285,5,18,25,4369,0
,10253933.0722655,4.99990312499997,0.07,0.199208755372504,10,10.0004080549069,-9.70070835795815,1.6062404029072E-5,5,101,25,4369,0
,10253956.619375,5.00068437500002,0.07,0.199208755372504,30,10.0003985509341,3.82698684249032,0.000322308300787376,5,56,25,4369,0
,10253980.3992578,5.001068359375,0.07,0.199208755372504,50,10.0003795430668,5.14122256606442,-0.000367183331400156,5,11,25,4369,0
,10253983.638203,5.00045234375001,0.07,0.199208755372504,50,10.0003795430668,-9.9522249821852,0.000102785229682922,5,94,25,4369,0
,10254016.0768359,5.00055507812499,0.07,0.199208755372504,10,10.0004080549069,6.71586358139698,0.00026547844754532,5,49,25,4369,0
,10254040.3984375,5.00066875,0.07,0.199208755372504,30,10.0003985509341,1.95098097359135,-0.000374625734467473,5,4,25,4369,0
,10254043.8935157,5.00002031250002,0.07,0.199208755372504,30,10.0003985509341,-9.04025321701159,0.000253583615024884,5,87,25,4369,0
,10254067.3030468,5.0002953125,0.07,0.199208755372504,50,10.0003795430668,8.81954737058493,0.000182925816625357,5,42,25,4369,0
,10254070.8662108,5.00087890625,0.07,0.199208755372504,50,10.0003795430668,-1.46736043508789,-0.000368005735799671,5,125,25,4369,0
,10254106.784375,4.99933124999998,0.07,0.199208755372504,10,10.0004080549069,-7.07135635025724,0.000326564768329262,5,80,25,4369,0
,10254130.842539,5.00013164062499,0.07,0.199208755372504,30,10.0003985509341,9.89215933686981,5.71271327013772E-5,5,35,25,4369,0
,10254134.405703,4.99996953124995,0.07,0.199208755372504,30,10.0003985509341,-4.71415524386975,-0.000356472123207318,5,118,25,4369,0
,10254157.3258203,5.00038593750003,0.07,0.199208755372504,50,10.0003795430668,-4.27571320987422,0.000320595409721136,5,73,25,4369,0
,10254190.0914063,5.000009375,0.07,0.199208755372504,10,10.0004080549069,9.80825301827858,-0.000174142478499561,5,28,25,4369,0
,10254193.6675392,5.00033359374999,0.07,0.199208755372504,10,10.0004080549069,-7.40981360229206,-0.000170105486176908,5,111,25,4369,0
,10254217.7040625,5.00094453125001,0.07,0.199208755372504,30,10.0003985509341,-0.980210468118438,0.000329993910984032,5,66,25,4369,0
,10254241.1458984,5.000139453125,0.07,0.199208755372504,50,10.0003795430668,8.57761164494987,-0.000266687059774995,5,21,25,4369,0
,10254244.4496875,5.00069062500001,0.07,0.199208755372504,50,10.0003795430668,-9.23914597718402,-7.88491684943436E-5,5,104,25,4369,0
,10254275.3773437,4.99993515625,0.07,0.199208755372504,10,10.0004080549069,2.42990094828733,0.000319425889756531,5,59,25,4369,0
,10254299.09125,4.9998890625,0.07,0.199208755372504,30,10.0003985509341,6.34418567967242,-0.000361978567929731,5,14,25,4369,0
,10254302.5668749,4.99982421875002,0.07,0.199208755372504,30,10.0003985509341,-9.98835263291373,2.94096147020655E-5,5,97,25,4369,0
,10254326.3525,4.99989218750001,0.07,0.199208755372504,50,10.0003795430668,5.5559131930261,0.000309260515496135,5,52,25,4369,0
,10254358.7762891,5.000346484375,0.07,0.199208755372504,10,10.0004080549069,3.36903600347996,-0.000383907754439861,5,7,25,4369,0
,10254362.1708593,5.00089765625001,0.07,0.199208755372504,10,10.0004080549069,-9.56979384152169,0.000241253583226353,5,90,25,4369,0
,10254384.6817187,5.00058359375,0.07,0.199208755372504,30,10.0003985509341,8.03239543391837,0.000276525259121425,5,45,25,4369,0
,10254409.415,5.00045,0.07,0.199208755372504,50,10.0003795430668,0,-0.000368786696344614,5,0,25,4369,0
,10254412.7479688,5.00028789062497,0.07,0.199208755372504,50,10.0003795430668,-8.03238016665625,0.000305115105584264,5,83,25,4369,0
,10254445.4471093,4.99998671875001,0.07,0.199208755372504,10,10.0004080549069,9.56979384152169,5.59660838916898E-5,5,38,25,4369,0
,10254448.848164,4.99963007812502,0.07,0.199208755372504,10,10.0004080549069,-3.36903600347996,-0.000354561489075423,5,121,25,4369,0
,10254472.1518749,5.0010015625,0.07,0.199208755372504,30,10.0003985509341,-5.55592375323133,0.000316137447953224,5,76,25,4369,0
,10254497.4496484,5.000158984375,0.07,0.199208755372504,50,10.0003795430668,9.98833364794231,-4.52927313745024E-5,5,31,25,4369,0
,10254501.317578,5.00045078125,0.07,0.199208755372504,50,10.0003795430668,-6.3441736212091,-0.000300702033564448,5,114,25,4369,0
,10254531.1552734,5.00073828124998,0.07,0.199208755372504,10,10.0004080549069,-2.42990094828733,0.000317450612783432,5,69,25,4369,0
,10254555.1659375,5.001075,0.07,0.199208755372504,30,10.0003985509341,9.23916353816351,-0.000186602766108182,5,24,25,4369,0
,10254558.5929298,5.00081562499999,0.07,0.199208755372504,30,10.0003985509341,-8.57762794854141,-0.000147423189547327,5,107,25,4369,0
,10254582.6996093,4.99940624999999,0.07,0.199208755372504,50,10.0003795430668,0.980208605021647,0.000326071586459875,5,62,25,4369,0
,10254619.3222656,5.00055625,0.07,0.199208755372504,10,10.0004080549069,7.40981360229206,-0.000374864903278649,5,17,25,4369,0
,10254622.7265625,5.00107500000002,0.07,0.199208755372504,10,10.0004080549069,-9.80825301827858,3.18553065881137E-5,5,100,25,4369,0
,10254647.0977734,5.00023515625001,0.07,0.199208755372504,30,10.0003985509341,4.27572133678467,0.00031937554012984,5,55,25,4369,0
,10254671.8983594,5.0006921875,0.07,0.199208755372504,50,10.0003795430668,4.71414628362317,-0.000368523551151156,5,10,25,4369,0
,10254675.3707422,5.00062734375002,0.07,0.199208755372504,50,10.0003795430668,-9.89214053473404,0.000124963559210301,5,93,25,4369,0
,10254710.68875,5.00018125,0.07,0.199208755372504,10,10.0004080549069,7.07135635025724,0.000256651837844402,5,48,25,4369,0
,10254734.9159766,5.000269921875,0.07,0.199208755372504,30,10.0003985509341,1.46736322412127,-0.000374133750382397,5,3,25,4369,0
,10254738.8163282,5.00082109375001,0.07,0.199208755372504,30,10.0003985509341,-8.81956413402722,0.000280028778231806,5,86,25,4369,0
,10254762.4772656,5.00080351562502,0.07,0.199208755372504,50,10.0003795430668,9.04023603410313,0.000161619763821363,5,41,25,4369,0
,10254765.9334374,4.99979843750005,0.07,0.199208755372504,50,10.0003795430668,-1.95097726534041,-0.000368892401456833,5,124,25,4369,0
,10254802.0662891,5.00044882812503,0.07,0.199208755372504,10,10.0004080549069,-6.71586358139698,0.000322293781209737,5,79,25,4369,0
,10254827.5317188,5.00097265624999,0.07,0.199208755372504,30,10.0003985509341,9.95224389852435,3.26958252117039E-5,5,34,25,4369,0
,10254831.026797,5.00139414062495,0.07,0.199208755372504,30,10.0003985509341,-5.14123233806112,-0.000354617239079542,5,117,25,4369,0
,10254855.1471876,4.99996562500001,0.07,0.199208755372504,50,10.0003795430668,-3.82697956849444,0.000324262632057071,5,72,25,4369,0
,10254889.491289,4.999534375,0.07,0.199208755372504,10,10.0004080549069,9.70070835795815,-0.000181358482223004,5,27,25,4369,0
,10254893.1841406,4.99979375000001,0.07,0.199208755372504,10,10.0004080549069,-7.73041996433595,-0.000148480175994337,5,110,25,4369,0
,10254916.4811719,5.00019062499998,0.07,0.199208755372504,30,10.0003985509341,-0.490696299241617,0.000325970403436157,5,65,25,4369,0
,10254940.013125,5.00071875000001,0.07,0.199208755372504,50,10.0003795430668,8.31501170155209,-0.000290741352364421,5,20,25,4369,0
,10254943.4498437,5.00058906250004,0.07,0.199208755372504,50,10.0003795430668,-9.41579800835226,-6.30718190222977E-5,5,103,25,4369,0
,10254976.3098438,4.99982734375001,0.07,0.199208755372504,10,10.0004080549069,2.90296522463157,0.000312305055558682,5,58,25,4369,0
,10254999.9961719,5.000026953125,0.07,0.199208755372504,30,10.0003985509341,5.95723046143856,-0.00036705673361818,5,13,25,4369,0
,10255003.8024999,5.00083750000002,0.07,0.199208755372504,30,10.0003985509341,-10.0003985509341,4.60258969623178E-5,5,96,25,4369,0
,10255027.2906641,5.00174921875,0.07,0.199208755372504,50,10.0003795430668,5.95721913846527,0.000306756189092994,5,51,25,4369,0
,10255059.4540625,4.99937734375,0.07,0.199208755372504,10,10.0004080549069,2.90296522463157,-0.000379928387701511,5,6,25,4369,0
,10255062.9685938,5.00044726562503,0.07,0.199208755372504,10,10.0004080549069,-9.41582485350607,0.00025581190129742,5,89,25,4369,0
,10255087.6578125,5.00068593750002,0.07,0.199208755372504,30,10.0003985509341,8.31502750601608,0.000247461980001794,5,44,25,4369,0
,10255091.1528907,5.00084804687505,0.07,0.199208755372504,30,10.0003985509341,-0.490696299241616,-0.000368636230834656,5,127,25,4369,0
,10255115.3333594,5.00020546874999,0.07,0.199208755372504,50,10.0003795430668,-7.73039792438554,0.000308652361854911,5,82,25,4369,0
,10255145.9671094,4.99997773437498,0.07,0.199208755372504,10,10.0004080549069,9.70070835795815,3.48431058228018E-5,5,37,25,4369,0
,10255149.695625,4.99981562499995,0.07,0.199208755372504,10,10.0004080549069,-3.82699047950326,-0.000332891941070557,5,120,25,4369,0
,10255175.6764453,5.00028437500001,0.07,0.199208755372504,30,10.0003985509341,-5.14123233806112,0.000321192912653916,5,75,25,4369,0
,10255198.9571094,4.99993671875001,0.07,0.199208755372504,50,10.0003795430668,9.9522249821852,-7.29626975953578E-5,5,30,25,4369,0
,10255202.4489453,5.00100664062504,0.07,0.199208755372504,50,10.0003795430668,-6.71584443401547,-0.000274907611310482,5,113,25,4369,0
,10255236.800625,5.00053749999999,0.07,0.199208755372504,10,10.0004080549069,-1.95098282772447,0.000330141338054091,5,68,25,4369,0
,10255261.6058203,4.99973476562501,0.07,0.199208755372504,30,10.0003985509341,9.04025321701159,-0.000202744526581632,5,23,25,4369,0
,10255265.0911719,5.00022109375003,0.07,0.199208755372504,30,10.0003985509341,-8.81956413402722,-0.000134164260493384,5,106,25,4369,0
,10255289.1435547,5.000906640625,0.07,0.199208755372504,50,10.0003795430668,1.46736043508789,0.000321243610233068,5,61,25,4369,0
,10255324.571875,5.0011,0.07,0.199208755372504,10,10.0004080549069,7.07135635025724,-0.000379750854335725,5,16,25,4369,0
,10255327.9534765,5.00161875000002,0.07,0.199208755372504,10,10.0004080549069,-9.89216873797649,5.82655775360767E-5,5,99,25,4369,0
,10255353.3497656,4.99959218749999,0.07,0.199208755372504,30,10.0003985509341,4.71415524386975,0.000311830727797416,5,54,25,4369,0
,10255376.7186719,5.00040703125,0.07,0.199208755372504,50,10.0003795430668,4.27571320987422,-0.000368323037400842,5,9,25,4369,0
,10255380.3953126,5.00047187499998,0.07,0.199208755372504,50,10.0003795430668,-9.80822505428553,0.000144896144047379,5,92,25,4369,0
,10255415.9146484,5.00026718749999,0.07,0.199208755372504,10,10.0004080549069,7.40981360229206,0.000248169817496091,5,47,25,4369,0
,10255440.3905469,5.000821875,0.07,0.199208755372504,30,10.0003985509341,0.980210468118438,-0.000371349677960906,5,2,25,4369,0
,10255443.9407421,4.9996546875,0.07,0.199208755372504,30,10.0003985509341,-8.57762794854141,0.000297872142659294,5,85,25,4369,0
,10255468.2725,5.00025625,0.07,0.199208755372504,50,10.0003795430668,9.23914597718402,0.000140631757676601,5,40,25,4369,0
,10255471.6703125,5.00058046874999,0.07,0.199208755372504,50,10.0003795430668,-2.4298940204753,-0.00036454601213336,5,123,25,4369,0
,10255507.0615625,5.00161093749998,0.07,0.199208755372504,10,10.0004080549069,-6.34419170892896,0.000329972535837442,5,78,25,4369,0
,10255531.0157813,5.000516015625,0.07,0.199208755372504,30,10.0003985509341,9.98835263291373,1.41994355039461E-5,5,33,25,4369,0
,10255534.400625,5.0008078125,0.07,0.199208755372504,30,10.0003985509341,-5.55592375323133,-0.000352661461672849,5,116,25,4369,0
,10255558.6399218,5.00018789062503,0.07,0.199208755372504,50,10.0003795430668,-3.36902639813034,0.000325536634773016,5,71,25,4369,0
,10255594.670625,4.99990468749999,0.07,0.199208755372504,10,10.0004080549069,9.56979384152169,-0.000206483236979693,5,26,25,4369,0
,10255598.5353125,4.99880234374998,0.07,0.199208755372504,10,10.0004080549069,-8.03240306758092,-0.000129085092339665,5,109,25,4369,0
,10255623.6725001,4.99915000000001,0.07,0.199208755372504,30,10.0003985509341,1.22465516062299E-15,0.000331693186631633,5,64,25,4369,0
,10255648.2158984,5.000333203125,0.07,0.199208755372504,50,10.0003795430668,8.03238016665625,-0.000312874186784029,5,19,25,4369,0
,10255651.8892968,5.00004140625,0.07,0.199208755372504,50,10.0003795430668,-9.56976655739189,-5.03185205161574E-5,5,102,25,4369,0
,10255686.1310157,5.00026835937498,0.07,0.199208755372504,10,10.0004080549069,3.36903600347996,0.000305243884213269,5,57,25,4369,0
,10255709.266875,5.0010625,0.07,0.199208755372504,30,10.0003985509341,5.55592375323133,-0.000364135873193542,5,12,25,4369,0
,10255712.7035937,5.00287812499998,0.07,0.199208755372504,30,10.0003985509341,-9.98835263291373,6.17798650637264E-5,5,95,25,4369,0
,10255736.3045313,5.00107734375,0.07,0.199208755372504,50,10.0003795430668,6.34417362120911,0.000303760357201099,5,50,25,4369,0
,10255768.5923047,5.001809765625,0.07,0.199208755372504,10,10.0004080549069,2.42990094828733,-0.00036194600397721,5,5,25,4369,0
,10255771.7015626,5.00197187500003,0.07,0.199208755372504,10,10.0004080549069,-9.23917231868949,0.000278067018371076,5,88,25,4369,0
,10255794.6452343,5.00059843750001,0.07,0.199208755372504,30,10.0003985509341,8.57762794854141,0.00022570182207144,5,43,25,4369,0
,10255798.4385937,5.00020937500004,0.07,0.199208755372504,30,10.0003985509341,-0.980210468118437,-0.00037048160771115,5,126,25,4369,0
,10255822.2446875,5.00057031250002,0.07,0.199208755372504,50,10.0003795430668,-7.40979247641208,0.000309191504493356,5,81,25,4369,0
,10255855.180625,4.999940625,0.07,0.199208755372504,10,10.0004080549069,9.80825301827859,1.47847458720216E-6,5,36,25,4369,0
,10255858.7210938,5.00026484374999,0.07,0.199208755372504,10,10.0004080549069,-4.27572540025666,-0.000330714392475784,5,119,25,4369,0
,10255882.8089063,4.99949218750001,0.07,0.199208755372504,30,10.0003985509341,-4.71415524386975,0.00032514954606692,5,74,25,4369,0
,10255907.7560156,5.00067187500001,0.07,0.199208755372504,50,10.0003795430668,9.89214053473404,-9.41765494644639E-5,5,29,25,4369,0
,10255911.3937499,5.00145000000004,0.07,0.199208755372504,50,10.0003795430668,-7.07133618934179,-0.000254114158451557,5,112,25,4369,0
,10255941.0669922,5.00657578124997,0.07,0.199208755372504,10,10.0004080549069,-1.46736461864371,0.000318484089802951,5,67,25,4369,0
,10255965.16625,5.002328125,0.07,0.199208755372504,30,10.0003985509341,8.81956413402722,-0.000225558113824163,5,22,25,4369,0
,10255968.8493751,5.00167968750002,0.07,0.199208755372504,30,10.0003985509341,-9.04025321701159,-0.000113928108476102,5,105,25,4369,0
,10255993.4689063,5.00084531250002,0.07,0.199208755372504,50,10.0003795430668,1.95097726534041,0.000323907565325499,5,60,25,4369,0
,10256029.4611328,4.999755078125,0.07,0.199208755372504,10,10.0004080549069,6.71586358139698,-0.000370824418496341,5,15,25,4369,0
,10256032.8427343,5.00088984375001,0.07,0.199208755372504,10,10.0004080549069,-9.95225335673296,6.70229201205076E-5,5,98,25,4369,0
,10256057.0905469,5.00063242187499,0.07,0.199208755372504,30,10.0003985509341,5.14123233806112,0.000317149937877225,5,53,25,4369,0
,10256081.694375,5.00089375,0.07,0.199208755372504,50,10.0003795430668,3.82697956849444,-0.000368954939767718,5,8,25,4369,0
,10256085.4228906,5.00031015625,0.07,0.199208755372504,50,10.0003795430668,-9.7006807005822,0.000168542237952352,5,91,25,4369,0
,10256121.3867969,5.00068281249999,0.07,0.199208755372504,10,10.0004080549069,7.73041996433595,0.000233249738812447,5,46,25,4369,0
,10256144.0094531,4.999459375,0.07,0.199208755372504,30,10.0003985509341,0.490696299241615,-0.000377025895027651,5,1,25,4369,0
,10256147.6990625,5.00023750000003,0.07,0.199208755372504,30,10.0003985509341,-8.31502750601608,0.000304018483600683,5,84,25,4369,0
,10256171.9426562,4.99978671874998,0.07,0.199208755372504,50,10.0003795430668,9.41579800835227,0.000114704016596079,5,39,25,4369,0
,10256175.3534375,4.99933281249995,0.07,0.199208755372504,50,10.0003795430668,-2.90295694808129,-0.000365972798317671,5,122,25,4369,0
,10256206.9758203,5.00045039062503,0.07,0.199208755372504,10,10.0004080549069,-5.95723612294857,0.000319372338708491,5,77,25,4369,0
,10256230.53375,4.99989999999999,0.07,0.199208755372504,30,10.0003985509341,10.0003985509341,-9.11350879404291E-6,5,32,25,4369,0
,10256233.8505078,5.00145624999997,0.07,0.199208755372504,30,10.0003985509341,-5.95723046143856,-0.000333711052209967,5,115,25,4369,0
,10256258.3346875,5.00006875000001,0.07,0.199208755372504,50,10.0003795430668,-2.90295694808129,0.000325074279680848,5,70,25,4369,0
,10256289.6071094,5.00027578125,0.07,0.199208755372504,10,10.0004080549069,9.41582485350606,-0.000219136709347367,5,25,25,4369,0
,10256293.0503125,5.000859375,0.07,0.199208755372504,10,10.0004080549069,-8.31503540828069,-0.000108492386061698,5,108,25,4369,0
,10256316.0165234,4.99990390625001,0.07,0.199208755372504,30,10.0003985509341,0.490696299241615,0.000330755008488065,5,63,25,4369,0
,10256341.4014063,5.00033515625001,0.07,0.199208755372504,50,10.0003795430668,7.73039792438553,-0.000336203444749117,5,18,25,4369,0
,10256344.9353907,5.00049726562504,0.07,0.199208755372504,50,10.0003795430668,-9.7006807005822,-2.90805473923684E-5,5,101,25,4369,0
,10256381.4784375,4.99995625000001,0.07,0.199208755372504,10,10.0004080549069,3.82699047950326,0.000294189667329192,5,56,25,4369,0
,10256404.8636719,5.00114140625,0.07,0.199208755372504,30,10.0003985509341,5.14123233806112,-0.000363019902983474,5,11,25,4369,0
,10256408.4754687,5.00107656250002,0.07,0.199208755372504,30,10.0003985509341,-9.95224389852435,8.31799115985633E-5,5,94,25,4369,0
,10256432.3971484,5.00064062499998,0.07,0.199208755372504,50,10.0003795430668,6.71584443401547,0.000296656833961606,5,49,25,4369,0
,10256463.385,5.0006515625,0.07,0.199208755372504,10,10.0004080549069,1.95098282772447,-0.000373694929294288,5,4,25,4369,0
,10256466.60125,5.00068398437499,0.07,0.199208755372504,10,10.0004080549069,-9.04026180850128,0.000287960574496537,5,87,25,4369,0
,10256489.9592969,5.00018906250001,0.07,0.199208755372504,30,10.0003985509341,8.81956413402722,0.000199671679486831,5,42,25,4369,0
,10256493.366836,5.00155078125004,0.07,0.199208755372504,30,10.0003985509341,-1.46736322412126,-0.000368378047520916,5,125,25,4369,0
,10256516.8268749,5.00064999999999,0.07,0.199208755372504,50,10.0003795430668,-7.07133618934179,0.000314434338361025,5,80,25,4369,0
,10256550.6743359,4.99979101562499,0.07,0.199208755372504,10,10.0004080549069,9.89216873797649,-8.28702468425019E-6,5,35,25,4369,0
,10256554.2180468,4.99988828124996,0.07,0.199208755372504,10,10.0004080549069,-4.71415972401154,-0.000331892224494368,5,118,25,4369,0
,10256578.671875,5.00027031249999,0.07,0.199208755372504,30,10.0003985509341,-4.27572133678467,0.000324644174219834,5,73,25,4369,0
,10256604.3714063,5.0012546875,0.07,0.199208755372504,50,10.0003795430668,9.80822505428553,-0.000121958833187819,5,28,25,4369,0
,10256607.8437891,5.000379296875,0.07,0.199208755372504,50,10.0003795430668,-7.40979247641208,-0.000223630852997303,5,111,25,4369,0
,10256642.0372656,5.00039140624998,0.07,0.199208755372504,10,10.0004080549069,-0.980211399670677,0.000326204462908208,5,66,25,4369,0
,10256665.8697266,5.00079765625,0.07,0.199208755372504,30,10.0003985509341,8.57762794854141,-0.000240814859151012,5,21,25,4369,0
,10256669.4653126,5.00138125,0.07,0.199208755372504,30,10.0003985509341,-9.23916353816351,-9.7864410943455E-5,5,104,25,4369,0
,10256692.3415234,5.00048437500001,0.07,0.199208755372504,50,10.0003795430668,2.4298940204753,0.000319190043956041,5,59,25,4369,0
,10256724.1963281,5.00120703125,0.07,0.199208755372504,10,10.0004080549069,6.34419170892896,-0.000370633497368544,5,14,25,4369,0
,10256728.0577734,5.00065585937499,0.07,0.199208755372504,10,10.0004080549069,-9.98836212543862,9.09570371732107E-5,5,97,25,4369,0
,10256752.6895313,5.0005828125,0.07,0.199208755372504,30,10.0003985509341,5.55592375323133,0.000313896905734307,5,52,25,4369,0
,10256777.0996875,5.000530078125,0.07,0.199208755372504,50,10.0003795430668,3.36902639813034,-0.000368454586714506,5,7,25,4369,0
,10256780.653125,5.00088671874998,0.07,0.199208755372504,50,10.0003795430668,-9.56976655739189,0.000188962509855628,5,90,25,4369,0
,10256810.7121484,5.00049570312498,0.07,0.199208755372504,10,10.0004080549069,8.03240306758093,0.000200323120225221,5,45,25,4369,0
,10256835.86,5.0011,0.07,0.199208755372504,30,10.0003985509341,0,-0.000373318002352284,5,0,25,4369,0
,10256839.2545702,5.00122968749997,0.07,0.199208755372504,30,10.0003985509341,-8.03239543391837,0.000306785934501224,5,83,25,4369,0
,10256862.890625,5.00090937499998,0.07,0.199208755372504,50,10.0003795430668,9.56976655739189,9.59459226578476E-5,5,38,25,4369,0
,10256866.4959374,5.00103906249995,0.07,0.199208755372504,50,10.0003795430668,-3.36902639813034,-0.000363359600305557,5,121,25,4369,0
,10256902.3303125,5.00053593749998,0.07,0.199208755372504,10,10.0004080549069,-5.55592903335573,0.000322097330354154,5,76,25,4369,0
,10256925.1573438,5.00072148437499,0.07,0.199208755372504,30,10.0003985509341,9.98835263291373,-2.8761116684311E-5,5,31,25,4369,0
,10256928.6978125,4.99997578124995,0.07,0.199208755372504,30,10.0003985509341,-6.34418567967242,-0.000320831572430001,5,114,25,4369,0
,10256953.235039,5.000507421875,0.07,0.199208755372504,50,10.0003795430668,-2.4298940204753,0.000328294932842255,5,69,25,4369,0
,10256985.2825,5.00098437499999,0.07,0.199208755372504,10,10.0004080549069,9.23917231868949,-0.000249296426773071,5,24,25,4369,0
,10256988.6803125,5.00075742187498,0.07,0.199208755372504,10,10.0004080549069,-8.57763610037082,-0.000105072394944727,5,107,25,4369,0
,10257013.7217188,5.00116171875001,0.07,0.199208755372504,30,10.0003985509341,0.980210468118436,0.000324954744428396,5,62,25,4369,0
,10257038.5464844,5.00005625,0.07,0.199208755372504,50,10.0003795430668,7.40979247641208,-0.000350407091900706,5,17,25,4369,0
,10257042.0934375,5.00057500000002,0.07,0.199208755372504,50,10.0003795430668,-9.80822505428553,-1.07298605144026E-5,5,100,25,4369,0
,10257076.0209375,4.99985820312499,0.07,0.199208755372504,10,10.0004080549069,4.27572540025666,0.000300211540888995,5,55,25,4369,0
,10257100.0195312,5.00005703125,0.07,0.199208755372504,30,10.0003985509341,4.71415524386975,-0.00037320624364333,5,10,25,4369,0
,10257103.5016405,4.99970039062502,0.07,0.199208755372504,30,10.0003985509341,-9.89215933686981,0.000107585025640826,5,93,25,4369,0
,10257127.5725,5.0000125,0.07,0.199208755372504,50,10.0003795430668,7.07133618934179,0.000294932257384062,5,48,25,4369,0
,10257159.0945312,5.000410546875,0.07,0.199208755372504,10,10.0004080549069,1.46736461864371,-0.000378216209355742,5,3,25,4369,0
,10257162.4015624,5.00070234375,0.07,0.199208755372504,10,10.0004080549069,-8.81957251578296,0.000302950502373278,5,86,25,4369,0
,10257186.7653906,5.00013789062499,0.07,0.199208755372504,30,10.0003985509341,9.04025321701159,0.000180014434994923,5,41,25,4369,0
,10257190.4809375,4.99991093749998,0.07,0.199208755372504,30,10.0003985509341,-1.95098097359134,-0.000372090014732547,5,124,25,4369,0
,10257215.5289453,5.00050664062497,0.07,0.199208755372504,50,10.0003795430668,-6.71584443401547,0.000313682574778795,5,79,25,4369,0
,10257250.7039844,5.00078359374999,0.07,0.199208755372504,10,10.0004080549069,9.95225335673296,-2.9778457246721E-5,5,34,25,4369,0
,10257254.656211,5.00062148437495,0.07,0.199208755372504,10,10.0004080549069,-5.14123722407964,-0.000311298063024878,5,117,25,4369,0
,10257279.7865624,5.00027187499997,0.07,0.199208755372504,30,10.0003985509341,-3.82698684249031,0.000327897659089003,5,72,25,4369,0
,10257303.9865625,4.999884375,0.07,0.199208755372504,50,10.0003795430668,9.7006807005822,-0.000141474604606629,5,27,25,4369,0
,10257307.2806249,5.00014375000001,0.07,0.199208755372504,50,10.0003795430668,-7.73039792438553,-0.000195983238518238,5,110,25,4369,0
,10257341.3361328,5.000178515625,0.07,0.199208755372504,10,10.0004080549069,-0.490696765579461,0.000334368378389627,5,65,25,4369,0
,10257365.6892187,4.99962656250001,0.07,0.199208755372504,30,10.0003985509341,8.31502750601608,-0.000268604942700929,5,20,25,4369,0
,10257368.9022265,4.99952929687503,0.07,0.199208755372504,30,10.0003985509341,-9.41581590509684,-7.99453765567804E-5,5,103,25,4369,0
,10257392.9473438,4.99941093749999,0.07,0.199208755372504,50,10.0003795430668,2.90295694808128,0.000323745282366872,5,58,25,4369,0
,10257429.6556641,4.99991171875,0.07,0.199208755372504,10,10.0004080549069,5.95723612294857,-0.000354606308974326,5,13,25,4369,0
,10257433.0437499,5.00062499999996,0.07,0.199208755372504,10,10.0004080549069,-10.0004080549069,0.000102374469861388,5,96,25,4369,0
,10257457.3440625,5.00051054687499,0.07,0.199208755372504,30,10.0003985509341,5.95723046143856,0.0003158944633065,5,51,25,4369,0
,10257481.6767187,5.00008125,0.07,0.199208755372504,50,10.0003795430668,2.90295694808128,-0.000371008925139904,5,6,25,4369,0
,10257485.158828,4.99982187499999,0.07,0.199208755372504,50,10.0003795430668,-9.41579800835227,0.000214027240872383,5,89,25,4369,0
,10257520.9885937,4.999471875,0.07,0.199208755372504,10,10.0004080549069,8.31503540828069,0.00019412545952946,5,44,25,4369,0
,10257524.8435546,4.99979609374999,0.07,0.199208755372504,10,10.0004080549069,-0.49069676557946,-0.000384351296816021,5,127,25,4369,0
,10257550.04625,5.00024765625001,0.07,0.199208755372504,30,10.0003985509341,-7.7304126176656,0.000314163820197185,5,82,25,4369,0
,10257574.4919922,5.00000781249999,0.07,0.199208755372504,50,10.0003795430668,9.7006807005822,7.69709236919881E-5,5,37,25,4369,0
,10257578.1978124,5.00013749999995,0.07,0.199208755372504,50,10.0003795430668,-3.82697956849444,-0.000362251419574022,5,120,25,4369,0
,10257611.8351172,5.00061171875001,0.07,0.199208755372504,10,10.0004080549069,-5.14123722407963,0.000323491985909641,5,75,25,4369,0
,10257636.6349219,5.00072968749999,0.07,0.199208755372504,30,10.0003985509341,9.95224389852435,-4.94908696661394E-5,5,30,25,4369,0
,10257640.4250391,5.00053515624997,0.07,0.199208755372504,30,10.0003985509341,-6.71585719891892,-0.000301006107798053,5,113,25,4369,0
,10257664.648125,5.00122187500003,0.07,0.199208755372504,50,10.0003795430668,-1.95097726534041,0.000327762076631188,5,68,25,4369,0
,10257699.3807031,4.99960039062499,0.07,0.199208755372504,10,10.0004080549069,9.04026180850127,-0.000268318981397897,5,23,25,4369,0
,10257702.9017188,5.00086484374997,0.07,0.199208755372504,10,10.0004080549069,-8.81957251578297,-7.58245005272326E-5,5,106,25,4369,0
,10257725.683125,5.000068359375,0.07,0.199208755372504,30,10.0003985509341,1.46736322412127,0.000322350469003949,5,61,25,4369,0
,10257750.14125,5.00058125000001,0.07,0.199208755372504,50,10.0003795430668,7.07133618934179,-0.000360069470480084,5,16,25,4369,0
,10257754.1421094,5.00074335937504,0.07,0.199208755372504,50,10.0003795430668,-9.89214053473404,6.25685788691061E-6,5,99,25,4369,0
,10257786.1280469,5.00034296874999,0.07,0.199208755372504,10,10.0004080549069,4.71415972401154,0.000319242826662957,5,54,25,4369,0
,10257810.3729687,5.000295703125,0.07,0.199208755372504,30,10.0003985509341,4.27572133678467,-0.000373549022090932,5,9,25,4369,0
,10257813.628125,5.00071718749996,0.07,0.199208755372504,30,10.0003985509341,-9.80824369692192,0.000124076872857081,5,92,25,4369,0
,10257838.3926172,5.00085624999999,0.07,0.199208755372504,50,10.0003795430668,7.40979247641208,0.000289180688560009,5,47,25,4369,0
,10257874.2800781,5.00009453125,0.07,0.199208755372504,10,10.0004080549069,0.980211399670678,-0.000387544278055429,5,2,25,4369,0
,10257877.8108203,4.99986757812498,0.07,0.199208755372504,10,10.0004080549069,-8.57763610037082,0.000312919728457928,5,85,25,4369,0
,10257902.53375,4.99968125,0.07,0.199208755372504,30,10.0003985509341,9.23916353816351,0.000152030325908628,5,40,25,4369,0
,10257905.9964062,5.00026484375,0.07,0.199208755372504,30,10.0003985509341,-2.4298986390103,-0.000370456707767314,5,123,25,4369,0
,10257930.0229687,5.00032734375,0.07,0.199208755372504,50,10.0003795430668,-6.34417362120911,0.000317714270204306,5,78,25,4369,0
,10257965.265,5.00034843750001,0.07,0.199208755372504,10,10.0004080549069,9.98836212543862,-4.68469806946813E-5,5,33,25,4369,0
,10257968.5849999,5.00021875000005,0.07,0.199208755372504,10,10.0004080549069,-5.55592903335573,-0.000308065500576049,5,116,25,4369,0
,10257992.6132421,5.00087773437499,0.07,0.199208755372504,30,10.0003985509341,-3.36903280168795,0.000322186905476782,5,71,25,4369,0
,10258015.6684375,5.00132812500001,0.07,0.199208755372504,50,10.0003795430668,9.56976655739189,-0.000163284037262201,5,26,25,4369,0
,10258019.0792187,5.00093906250003,0.07,0.199208755372504,50,10.0003795430668,-8.03238016665625,-0.00017100153490901,5,109,25,4369,0
,10258051.795,5.00012500000003,0.07,0.199208755372504,10,10.0004080549069,1.22465632448555E-15,0.000326932640746236,5,64,25,4369,0
,10258076.4486719,5.00050507812499,0.07,0.199208755372504,30,10.0003985509341,8.03239543391837,-0.000288583752181795,5,19,25,4369,0
,10258080.1123438,4.99943515624997,0.07,0.199208755372504,30,10.0003985509341,-9.56978474678674,-6.8851901839177E-5,5,102,25,4369,0
,10258105.536836,5.00100585937501,0.07,0.199208755372504,50,10.0003795430668,3.36902639813034,0.000316511979326606,5,57,25,4369,0
,10258139.28125,5.000846875,0.07,0.199208755372504,10,10.0004080549069,5.55592903335573,-0.000363720755558461,5,12,25,4369,0
,10258142.7828126,5.00013359375004,0.07,0.199208755372504,10,10.0004080549069,-9.98836212543862,0.000133938447106629,5,95,25,4369,0
,10258167.5935156,5.00042031250002,0.07,0.199208755372504,30,10.0003985509341,6.34418567967242,0.000307357275030679,5,50,25,4369,0
,10258192.2569922,4.999479296875,0.07,0.199208755372504,50,10.0003795430668,2.4298940204753,-0.000369580322876572,5,5,25,4369,0
,10258195.8590625,4.99996562500003,0.07,0.199208755372504,50,10.0003795430668,-9.23914597718402,0.000243523437529802,5,88,25,4369,0
,10258230.3334375,5.00026757812501,0.07,0.199208755372504,10,10.0004080549069,8.57763610037082,0.000159128685481847,5,43,25,4369,0
,10258234.094375,5.00049453125002,0.07,0.199208755372504,10,10.0004080549069,-0.980211399670677,-0.000355225056409836,5,126,25,4369,0
,10258258.0742969,5.00081015624998,0.07,0.199208755372504,30,10.0003985509341,-7.4098065603127,0.000310567298179699,5,81,25,4369,0
,10258282.0807813,5.00005156250001,0.07,0.199208755372504,50,10.0003795430668,9.80822505428553,5.7131517678499E-5,5,36,25,4369,0
,10258285.4948048,5.00086210937503,0.07,0.199208755372504,50,10.0003795430668,-4.27571320987422,-0.000360927591100335,5,119,25,4369,0
,10258321.2753126,5.00018984375,0.07,0.199208755372504,10,10.0004080549069,-4.71415972401153,0.000324665161315352,5,74,25,4369,0
,10258344.9125,5.00056328125,0.07,0.199208755372504,30,10.0003985509341,9.89215933686981,-7.92235368862745E-5,5,29,25,4369,0
,10258348.025,5.00088749999999,0.07,0.199208755372504,30,10.0003985509341,-7.0713496299336,-0.000283830773292317,5,112,25,4369,0
,10258371.883086,5.00048867187503,0.07,0.199208755372504,50,10.0003795430668,-1.46736043508789,0.000326908007264137,5,67,25,4369,0
,10258404.7782031,4.999478125,0.07,0.199208755372504,10,10.0004080549069,8.81957251578297,-0.000296366633847356,5,22,25,4369,0
,10258408.3932422,4.99882968750002,0.07,0.199208755372504,10,10.0004080549069,-9.04026180850127,-5.6779244914651E-5,5,105,25,4369,0
,10258431.694375,5.00045156250002,0.07,0.199208755372504,30,10.0003985509341,1.95098097359135,0.000324509132446514,5,60,25,4369,0
,10258456.2529688,5.000196875,0.07,0.199208755372504,50,10.0003795430668,6.71584443401547,-0.000360965961590409,5,15,25,4369,0
,10258459.9490625,5.00045625000001,0.07,0.199208755372504,50,10.0003795430668,-9.9522249821852,2.48811673372988E-5,5,98,25,4369,0
,10258491.3577344,5.00018984375002,0.07,0.199208755372504,10,10.0004080549069,5.14123722407964,0.00030517956474796,5,53,25,4369,0
,10258515.2746875,5.000565625,0.07,0.199208755372504,30,10.0003985509341,3.82698684249032,-0.000371518092126482,5,8,25,4369,0
,10258518.4358203,5.00020898437502,0.07,0.199208755372504,30,10.0003985509341,-9.70069913880747,0.000145259869491889,5,91,25,4369,0
,10258541.8323437,5.00056796875,0.07,0.199208755372504,50,10.0003795430668,7.73039792438553,0.000272574461996555,5,46,25,4369,0
,10258574.1421875,4.999366015625,0.07,0.199208755372504,10,10.0004080549069,0.490696765579459,-0.000355017546098679,5,1,25,4369,0
,10258577.6437501,5.00069531250004,0.07,0.199208755372504,10,10.0004080549069,-8.31503540828069,0.000310114410240203,5,84,25,4369,0
,10258601.3227344,5.00042773437501,0.07,0.199208755372504,30,10.0003985509341,9.41581590509684,0.000143101788125932,5,39,25,4369,0
,10258604.8826563,4.99942265625005,0.07,0.199208755372504,30,10.0003985509341,-2.90296246577389,-0.0003694610333898,5,122,25,4369,0
,10258629.9826953,4.99965078124999,0.07,0.199208755372504,50,10.0003795430668,-5.95721913846527,0.000318274972960353,5,77,25,4369,0
,10258665.29875,5.00071250000001,0.07,0.199208755372504,10,10.0004080549069,10.0004080549069,-8.41033761389557E-5,5,32,25,4369,0
,10258668.7970703,5.00035585937502,0.07,0.199208755372504,10,10.0004080549069,-5.95723612294856,-0.000263052643276751,5,115,25,4369,0
,10258692.1285156,5.00076953124999,0.07,0.199208755372504,30,10.0003985509341,-2.90296246577389,0.000326240034256545,5,70,25,4369,0
,10258716.1914063,5.0006265625,0.07,0.199208755372504,50,10.0003795430668,9.41579800835227,-0.000181794306263328,5,25,25,4369,0
,10258719.731875,4.99971875000001,0.07,0.199208755372504,50,10.0003795430668,-8.31501170155209,-0.00015297275967896,5,108,25,4369,0
,10258751.9057422,5.00054687500001,0.07,0.199208755372504,10,10.0004080549069,0.490696765579459,0.000337760429829359,5,63,25,4369,0
,10258776.0896094,5.00035546875001,0.07,0.199208755372504,30,10.0003985509341,7.73041261766559,-0.000324446850249337,5,18,25,4369,0
,10258779.7305859,5.00084179687503,0.07,0.199208755372504,30,10.0003985509341,-9.70069913880747,-4.0954263466928E-5,5,101,25,4369,0
,10258802.95125,5.00017812499998,0.07,0.199208755372504,50,10.0003795430668,3.82697956849445,0.000319693796336651,5,56,25,4369,0
,10258833.9224609,4.999871484375,0.07,0.199208755372504,10,10.0004080549069,5.14123722407964,-0.00037299731047824,5,11,25,4369,0
,10258837.3364845,5.00003359375004,0.07,0.199208755372504,10,10.0004080549069,-9.95225335673296,0.000143079669214785,5,94,25,4369,0
,10258861.6641797,4.99999570312502,0.07,0.199208755372504,30,10.0003985509341,6.71585719891891,0.000309466526636647,5,49,25,4369,0
,10258885.3382813,5.0007015625,0.07,0.199208755372504,50,10.0003795430668,1.95097726534041,-0.000372780114412308,5,4,25,4369,0
,10258888.9338672,5.00073398437499,0.07,0.199208755372504,50,10.0003795430668,-9.04023603410313,0.000268956366926431,5,87,25,4369,0
,10258920.4780469,5.00014843750001,0.07,0.199208755372504,10,10.0004080549069,8.81957251578296,0.000142486242111772,5,42,25,4369,0
,10258924.248711,5.00034296875004,0.07,0.199208755372504,10,10.0004080549069,-1.46736461864371,-0.00037618272472173,5,125,25,4369,0
,10258948.1824999,4.99944374999998,0.07,0.199208755372504,30,10.0003985509341,-7.0713496299336,0.000315126510233515,5,80,25,4369,0
,10258972.4557422,4.99989140625001,0.07,0.199208755372504,50,10.0003795430668,9.89214053473404,3.82063910365103E-5,5,35,25,4369,0
,10258976.0383595,5.00034531250005,0.07,0.199208755372504,50,10.0003795430668,-4.71414628362317,-0.000356256775557995,5,118,25,4369,0
,10259006.8677734,5.00002226562498,0.07,0.199208755372504,10,10.0004080549069,-4.27572540025667,0.000326350855175406,5,73,25,4369,0
,10259030.7275,4.9999859375,0.07,0.199208755372504,30,10.0003985509341,9.80824369692192,-0.000100640140266882,5,28,25,4369,0
,10259034.2031249,5.00053710937501,0.07,0.199208755372504,30,10.0003985509341,-7.40980656031269,-0.000250110493248535,5,111,25,4369,0
,10259058.160625,4.99978203125,0.07,0.199208755372504,50,10.0003795430668,-0.980208605021649,0.000324010755866766,5,66,25,4369,0
,10259089.7598047,5.00163749999999,0.07,0.199208755372504,10,10.0004080549069,8.57763610037082,-0.00031498639145866,5,21,25,4369,0
,10259093.3359376,5.00059999999996,0.07,0.199208755372504,10,10.0004080549069,-9.23917231868949,-3.35069489665333E-5,5,104,25,4369,0
,10259118.0135937,4.999627734375,0.07,0.199208755372504,30,10.0003985509341,2.4298986390103,0.000321329118580454,5,59,25,4369,0
,10259141.9160937,5.00004921875,0.07,0.199208755372504,50,10.0003795430668,6.34417362120911,-0.000364381354302168,5,14,25,4369,0
,10259145.6575781,5.000341015625,0.07,0.199208755372504,50,10.0003795430668,-9.98833364794231,4.41798008978363E-5,5,97,25,4369,0
,10259176.1804688,5.00007031249999,0.07,0.199208755372504,10,10.0004080549069,5.55592903335573,0.000300333194900305,5,52,25,4369,0
,10259200.5851562,5.000168359375,0.07,0.199208755372504,30,10.0003985509341,3.36903280168794,-0.000374812904434899,5,7,25,4369,0
,10259204.2034374,5.00097890625002,0.07,0.199208755372504,30,10.0003985509341,-9.56978474678673,0.000169992498639557,5,90,25,4369,0
,10259227.7996875,5.00050273437499,0.07,0.199208755372504,50,10.0003795430668,8.03238016665625,0.000252391118556261,5,45,25,4369,0
,10259230.9515626,5.00059882812496,0.07,0.199208755372504,50,10.0003795430668,-0.490695366569778,-0.00037072915583849,5,127,25,4369,0