File: dados/Xac-time_300K_5pointR2_microfios-FeSiB_hac_10Oe_f_10Hz_26-04-24.raw
[Header]
; ACMS Raw Data File (default extension .raw)
; Copyright 1999, Quantum Design, Inc. All rights reserved.
TITLE,Xac-time_300K_5pointR2_microfios-FeSiB_hac_10Oe_f_10Hz_26-04-24
FILEOPENTIME,10059470.22,04/26/2024,2:16 pm
BYAPP,ACMS,1.0,1.1,RAW
INFO,PPMS ACMS Option Version: 1.0.9 Build 14,APPNAME
INFO,HARMONICS,1
DATATYPE,COMMENT,1
DATATYPE,TIME,2
STARTUPAXIS,X,2,LINEAR,AUTO
STARTUPAXIS,Y,7,LINEAR,AUTO
STARTUPAXIS,Y,8,LINEAR,AUTO
TIMEMODE,MINUTES,RELATIVE
PLOT_APPEARANCE,ALL,HORZ_GRID_ON,VERT_GRID_ON,MARKERS_AND_LINES
RECORDS,ALL_RECORDS
DATATYPE,TIME,2
DATATYPE,COMMENT,1
[Data]
Comment,Time Stamp (sec),Temperature (K),Magnetic Field (Oe),Position (cm),Frequency (Hz),Amplitude (Oe),Drive (Oe),Signal (mV),Measure Type,Bin,Gain,PPMS Status (code),DSP Status (code)
,10059447.25,299.9908,0.07,0.199208755372504,10,10.0004080549069,0,-0.00259345193626359,5,0,25,4369,0
,10059450.8855468,300.00473359375,0.07,0.199208755372504,10,10.0004080549069,-7.73041996433595,0.00122752535389736,5,82,25,4369,0
,10059474.4740625,300.005601562499,0.07,0.199208755372504,30,10.0003985509341,9.80824369692192,0.0011620140220556,5,36,25,4369,0
,10059477.8885937,300.014602343748,0.07,0.199208755372504,30,10.0003985509341,-4.71415524386975,-0.00253701091019644,5,118,25,4369,0
,10059501.76625,300.011003125001,0.07,0.199208755372504,50,10.0003795430668,-3.82697956849444,0.00123422350734472,5,72,25,4369,0
,10059534.189375,300.00213515625,0.07,0.199208755372504,10,10.0004080549069,9.56979384152169,-0.000197929621208459,5,26,25,4369,0
,10059537.54625,300.001142187499,0.07,0.199208755372504,10,10.0004080549069,-8.31503540828069,0.000977472809609025,5,108,25,4369,0
,10059562.8389062,300.003847656249,0.07,0.199208755372504,30,10.0003985509341,0.980210468118436,0.0012332976459422,5,62,25,4369,0
,10059587.40125,300.00745625,0.07,0.199208755372504,50,10.0003795430668,7.07133618934179,-0.00251483819447458,5,16,25,4369,0
,10059590.6876563,300.006463281249,0.07,0.199208755372504,50,10.0003795430668,-9.9522249821852,0.00114638297818601,5,98,25,4369,0
,10059625.5284375,300.007571875001,0.07,0.199208755372504,10,10.0004080549069,5.55592903335573,0.00120174314361066,5,52,25,4369,0
,10059650.048125,299.99572734375,0.07,0.199208755372504,30,10.0003985509341,2.90296246577389,-0.00259012481870337,5,6,25,4369,0
,10059653.5075001,299.994734374999,0.07,0.199208755372504,30,10.0003985509341,-9.23916353816351,0.00120064806348334,5,88,25,4369,0
,10059677.1072656,300.001257812501,0.07,0.199208755372504,50,10.0003795430668,8.81954737058493,0.0011909871827811,5,42,25,4369,0
,10059680.7235937,299.998246875002,0.07,0.199208755372504,50,10.0003795430668,-1.95097726534041,-0.00257321936078369,5,124,25,4369,0
,10059715.9676563,300.005789843751,0.07,0.199208755372504,10,10.0004080549069,-6.34419170892896,0.00123500183690339,5,78,25,4369,0
,10059739.365,300.0112,0.07,0.199208755372504,30,10.0003985509341,10.0003985509341,0.0011216519245257,5,32,25,4369,0
,10059742.6193749,300.001206250001,0.07,0.199208755372504,30,10.0003985509341,-6.34418567967242,-0.00243481442642709,5,114,25,4369,0
,10059766.5975,300.003689062502,0.07,0.199208755372504,50,10.0003795430668,-1.95097726534041,0.00123769585043192,5,68,25,4369,0
,10059799.6514844,300.01321875,0.07,0.199208755372504,10,10.0004080549069,8.81957251578297,-0.00218993431190029,5,22,25,4369,0
,10059803.2165625,300.005275,0.07,0.199208755372504,10,10.0004080549069,-9.23917231868949,0.0010837204172276,5,104,25,4369,0
,10059827.2467188,300.00970546875,0.07,0.199208755372504,30,10.0003985509341,2.90296246577389,0.00123656348377052,5,58,25,4369,0
,10059851.6075,299.9918359375,0.07,0.199208755372504,50,10.0003795430668,5.5559131930261,-0.00256590475328267,5,12,25,4369,0
,10059854.83625,299.995839843749,0.07,0.199208755372504,50,10.0003795430668,-9.9522249821852,0.00117355263791978,5,94,25,4369,0
,10059891.395625,299.9944,0.07,0.199208755372504,10,10.0004080549069,7.07135635025724,0.00120459619211033,5,48,25,4369,0
,10059916.1324219,299.9988515625,0.07,0.199208755372504,30,10.0003985509341,0.980210468118438,-0.0025976702131124,5,2,25,4369,0
,10059919.9217187,299.996865624999,0.07,0.199208755372504,30,10.0003985509341,-8.31502750601608,0.00121705046492732,5,84,25,4369,0
,10059946.1204687,299.995835156249,0.07,0.199208755372504,50,10.0003795430668,9.56976655739189,0.00116019481793046,5,38,25,4369,0
,10059949.7143749,299.995803124998,0.07,0.199208755372504,50,10.0003795430668,-3.82697956849444,-0.00253571588546038,5,120,25,4369,0
,10059982.523125,300.000998437499,0.07,0.199208755372504,10,10.0004080549069,-4.71415972401153,0.00124543439596891,5,74,25,4369,0
,10060008.1134375,299.99939375,0.07,0.199208755372504,30,10.0003985509341,9.80824369692192,0.00104607270461404,5,28,25,4369,0
,10060011.5792188,299.994396875001,0.07,0.199208755372504,30,10.0003985509341,-7.73041261766559,-0.000332527884489132,5,110,25,4369,0
,10060034.9,299.982150000001,0.07,0.199208755372504,50,10.0003795430668,1.2246528329075E-15,0.00123411761596799,5,64,25,4369,0
,10060069.6078906,300.00706015625,0.07,0.199208755372504,10,10.0004080549069,7.73041996433595,-0.00251072982791811,5,18,25,4369,0
,10060073.0832812,300.000045312497,0.07,0.199208755372504,10,10.0004080549069,-9.80825301827858,0.00113797606900335,5,100,25,4369,0
,10060097.7673438,299.992061718751,0.07,0.199208755372504,30,10.0003985509341,4.71415524386975,0.0012292544124648,5,54,25,4369,0
,10060121.6690625,300.010396875,0.07,0.199208755372504,50,10.0003795430668,3.82697956849444,-0.00258485660888255,5,8,25,4369,0
,10060125.1444531,300.011389843751,0.07,0.199208755372504,50,10.0003795430668,-9.56976655739189,0.00119889336638153,5,90,25,4369,0
,10060160.68625,300.005146875,0.07,0.199208755372504,10,10.0004080549069,8.31503540828069,0.0012037274427712,5,44,25,4369,0
,10060164.043125,300.012129687501,0.07,0.199208755372504,10,10.0004080549069,-0.980211399670677,-0.00257981417234987,5,126,25,4369,0
,10060187.6425,299.997931250002,0.07,0.199208755372504,30,10.0003985509341,-7.0713496299336,0.00122815765078283,5,80,25,4369,0
,10060211.2140625,299.990920312499,0.07,0.199208755372504,50,10.0003795430668,9.9522249821852,0.00113078020513058,5,34,25,4369,0
,10060214.6606251,299.996878124998,0.07,0.199208755372504,50,10.0003795430668,-5.5559131930261,-0.00242650900036097,5,116,25,4369,0
,10060245.8564844,299.999060937501,0.07,0.199208755372504,10,10.0004080549069,-2.90296522463158,0.00122816243674606,5,70,25,4369,0
,10060270.2484375,299.987946875,0.07,0.199208755372504,30,10.0003985509341,9.23916353816351,0.00049331820466452,5,24,25,4369,0
,10060273.7110156,300.000919531251,0.07,0.199208755372504,30,10.0003985509341,-8.81956413402722,0.00096808407559163,5,106,25,4369,0
,10060297.0426562,299.997884375001,0.07,0.199208755372504,50,10.0003795430668,1.95097726534041,0.00123421093448996,5,60,25,4369,0
,10060329.2253125,300.00619296875,0.07,0.199208755372504,10,10.0004080549069,6.34419170892896,-0.00256208732025698,5,14,25,4369,0
,10060332.7999999,299.996487500001,0.07,0.199208755372504,10,10.0004080549069,-10.0004080549069,0.00116693176096305,5,96,25,4369,0
,10060356.3180469,300.011010937501,0.07,0.199208755372504,30,10.0003985509341,6.34418567967242,0.00121918565127998,5,50,25,4369,0
,10060380.025625,299.992796875,0.07,0.199208755372504,50,10.0003795430668,1.95097726534041,-0.00258884080685675,5,4,25,4369,0
,10060383.1134375,299.994782812501,0.07,0.199208755372504,50,10.0003795430668,-8.81954737058493,0.00121009997092187,5,86,25,4369,0
,10060415.9025,299.994840625,0.07,0.199208755372504,10,10.0004080549069,9.23917231868949,0.00117078277980909,5,40,25,4369,0
,10060419.618125,300.001791406249,0.07,0.199208755372504,10,10.0004080549069,-2.90296522463158,-0.00251261721132323,5,122,25,4369,0
,10060444.2215625,299.992776562501,0.07,0.199208755372504,30,10.0003985509341,-5.55592375323133,0.00122904900409695,5,76,25,4369,0
,10060468.5925782,300.00098125,0.07,0.199208755372504,50,10.0003795430668,9.9522249821852,0.001052380586043,5,30,25,4369,0
,10060472.1256251,300.012000000002,0.07,0.199208755372504,50,10.0003795430668,-7.07133618934179,-0.00137706003151834,5,112,25,4369,0
,10060506.5060156,300.000776562501,0.07,0.199208755372504,10,10.0004080549069,-0.980211399670677,0.00123414443805814,5,66,25,4369,0
,10060530.7045313,299.99753125,0.07,0.199208755372504,30,10.0003985509341,8.31502750601608,-0.00236175456343012,5,20,25,4369,0
,10060534.2696094,299.992534375,0.07,0.199208755372504,30,10.0003985509341,-9.56978474678674,0.00108783372626123,5,102,25,4369,0
,10060558.87375,299.994778125,0.07,0.199208755372504,50,10.0003795430668,3.82697956849445,0.00122694256715477,5,56,25,4369,0
,10060594.4544531,299.99523203125,0.07,0.199208755372504,10,10.0004080549069,4.71415972401153,-0.00259170425124466,5,10,25,4369,0
,10060597.8529688,300.008204687501,0.07,0.199208755372504,10,10.0004080549069,-9.80825301827858,0.00119420932605863,5,92,25,4369,0
,10060623.3600781,299.99528671875,0.07,0.199208755372504,30,10.0003985509341,7.7304126176656,0.00121294165081862,5,46,25,4369,0
,10060646.61,300.01105,0.07,0.199208755372504,50,10.0003795430668,0,-0.00258593265898526,5,0,25,4369,0
,10060650.1142188,300.001088281252,0.07,0.199208755372504,50,10.0003795430668,-7.73039792438554,0.00122153605334461,5,82,25,4369,0
,10060685.8434375,299.9990359375,0.07,0.199208755372504,10,10.0004080549069,9.80825301827859,0.00109565095044672,5,36,25,4369,0
,10060689.5526562,300.000028906251,0.07,0.199208755372504,10,10.0004080549069,-4.71415972401154,-0.00226358301006258,5,118,25,4369,0
,10060714.5859374,300.011674999998,0.07,0.199208755372504,30,10.0003985509341,-3.82698684249031,0.00123594383088251,5,72,25,4369,0
,10060739.8846875,300.004,0.07,0.199208755372504,50,10.0003795430668,9.56976655739189,0.000656234100461006,5,26,25,4369,0
,10060743.5106251,300.004,0.07,0.199208755372504,50,10.0003795430668,-8.31501170155209,0.000910879578441382,5,108,25,4369,0
,10060776.8285937,299.983136718751,0.07,0.199208755372504,10,10.0004080549069,0.980211399670675,0.00123723788419738,5,62,25,4369,0
,10060800.708125,300.0070375,0.07,0.199208755372504,30,10.0003985509341,7.0713496299336,-0.00249332205081979,5,16,25,4369,0
,10060804.4141407,300.007998437499,0.07,0.199208755372504,30,10.0003985509341,-9.95224389852435,0.00113690854050219,5,98,25,4369,0
,10060828.7279688,300.0175015625,0.07,0.199208755372504,50,10.0003795430668,5.5559131930261,0.00122259226627648,5,52,25,4369,0
,10060864.2589063,299.98923359375,0.07,0.199208755372504,10,10.0004080549069,2.90296522463157,-0.00261308799963444,5,6,25,4369,0
,10060868.070625,299.997209375001,0.07,0.199208755372504,10,10.0004080549069,-9.23917231868949,0.00122553843539208,5,88,25,4369,0
,10060892.3403906,300.003192968749,0.07,0.199208755372504,30,10.0003985509341,8.81956413402722,0.0011981428704328,5,42,25,4369,0
,10060895.9823437,300.008157812497,0.07,0.199208755372504,30,10.0003985509341,-1.95098097359134,-0.00259025695009364,5,124,25,4369,0
,10060920.3710937,300.005322656248,0.07,0.199208755372504,50,10.0003795430668,-6.34417362120911,0.00122663425281644,5,78,25,4369,0
,10060955.2725,300.00575,0.07,0.199208755372504,10,10.0004080549069,10.0004080549069,0.000955811119638384,5,32,25,4369,0
,10060958.9560938,300.00575,0.07,0.199208755372504,10,10.0004080549069,-6.34419170892896,-0.00140263000503183,5,114,25,4369,0
,10060983.14875,300.003518749999,0.07,0.199208755372504,30,10.0003985509341,-1.95098097359135,0.00123824102855805,5,68,25,4369,0
,10061007.7153125,300.0031265625,0.07,0.199208755372504,50,10.0003795430668,8.81954737058493,-0.00200740238651633,5,22,25,4369,0
,10061011.0337501,299.996143749999,0.07,0.199208755372504,50,10.0003795430668,-9.23914597718402,0.00105661638081074,5,104,25,4369,0
,10061046.1803906,299.998922656251,0.07,0.199208755372504,10,10.0004080549069,2.90296522463157,0.00122843106510118,5,58,25,4369,0
,10061070.151875,300.0125328125,0.07,0.199208755372504,30,10.0003985509341,5.55592375323133,-0.00256364330804597,5,12,25,4369,0
,10061073.7521874,300.004557031249,0.07,0.199208755372504,30,10.0003985509341,-9.95224389852435,0.00117130053695291,5,94,25,4369,0
,10061098.93625,299.996762499999,0.07,0.199208755372504,50,10.0003795430668,7.07133618934179,0.00121172266080976,5,48,25,4369,0
,10061133.6796875,299.98527421875,0.07,0.199208755372504,10,10.0004080549069,0.980211399670678,-0.00261251261690632,5,2,25,4369,0
,10061137.151875,299.986267187501,0.07,0.199208755372504,10,10.0004080549069,-8.31503540828069,0.00123491830890998,5,84,25,4369,0
,10061161.1125781,300.0031828125,0.07,0.199208755372504,30,10.0003985509341,9.56978474678673,0.00117513325272335,5,38,25,4369,0
,10061164.7865624,299.988256249999,0.07,0.199208755372504,30,10.0003985509341,-3.82698684249031,-0.00256119283019668,5,120,25,4369,0
,10061188.5816406,299.989909375,0.07,0.199208755372504,50,10.0003795430668,-4.71414628362317,0.00122898509725928,5,74,25,4369,0
,10061219.0667188,300.0007671875,0.07,0.199208755372504,10,10.0004080549069,9.80825301827858,0.000421842851210387,5,28,25,4369,0
,10061222.3371094,300.004771093749,0.07,0.199208755372504,10,10.0004080549069,-7.73041996433595,0.000616607430856675,5,110,25,4369,0
,10061246.3725,299.99465,0.07,0.199208755372504,30,10.0003985509341,1.22465516062299E-15,0.0012398934793762,5,64,25,4369,0
,10061271.1809375,300.0015828125,0.07,0.199208755372504,50,10.0003795430668,7.73039792438553,-0.00247033978812396,5,18,25,4369,0
,10061274.6018749,300.008565625001,0.07,0.199208755372504,50,10.0003795430668,-9.80822505428553,0.00112467384897173,5,100,25,4369,0
,10061310.9817969,300.0080015625,0.07,0.199208755372504,10,10.0004080549069,4.71415972401154,0.00122856581583619,5,54,25,4369,0
,10061334.7234375,300.011334375,0.07,0.199208755372504,30,10.0003985509341,3.82698684249032,-0.0025823907667978,5,8,25,4369,0
,10061338.089922,299.998361718749,0.07,0.199208755372504,30,10.0003985509341,-9.56978474678673,0.00118806376121938,5,90,25,4369,0
,10061362.4670312,299.997782812499,0.07,0.199208755372504,50,10.0003795430668,8.31501170155208,0.00119498241692782,5,44,25,4369,0
,10061365.7694531,299.997750781248,0.07,0.199208755372504,50,10.0003795430668,-0.980208605021648,-0.00258205747231841,5,126,25,4369,0
,10061401.271875,299.988050000001,0.07,0.199208755372504,10,10.0004080549069,-7.07135635025724,0.0012210282147862,5,80,25,4369,0
,10061425.2885157,299.999664843749,0.07,0.199208755372504,30,10.0003985509341,9.95224389852435,0.00114137591380212,5,34,25,4369,0
,10061428.6614063,299.996685937498,0.07,0.199208755372504,30,10.0003985509341,-5.55592375323133,-0.00250397767457697,5,116,25,4369,0
,10061452.0646094,300.003420312499,0.07,0.199208755372504,50,10.0003795430668,-2.90295694808129,0.00123350783251226,5,70,25,4369,0
,10061484.3003125,299.9964625,0.07,0.199208755372504,10,10.0004080549069,9.23917231868949,-0.00118263356853277,5,24,25,4369,0
,10061487.9742968,300.001459374999,0.07,0.199208755372504,10,10.0004080549069,-8.81957251578297,0.00103632861282676,5,106,25,4369,0
,10061512.8264062,299.994903125001,0.07,0.199208755372504,30,10.0003985509341,1.95098097359135,0.00123205006174329,5,60,25,4369,0
,10061535.8103125,300.002140625,0.07,0.199208755372504,50,10.0003795430668,6.34417362120911,-0.00254268944263459,5,14,25,4369,0
,10061539.3849999,299.989200000001,0.07,0.199208755372504,50,10.0003795430668,-10.0003795430668,0.00116432905197144,5,96,25,4369,0
,10061575.5200781,299.989324218749,0.07,0.199208755372504,10,10.0004080549069,6.34419170892896,0.00120572949526831,5,50,25,4369,0
,10061599.6253125,299.9996796875,0.07,0.199208755372504,30,10.0003985509341,1.95098097359135,-0.00259596343514406,5,4,25,4369,0
,10061603.1167188,300.018738281251,0.07,0.199208755372504,30,10.0003985509341,-8.81956413402722,0.00121627423343145,5,86,25,4369,0
,10061627.8290625,299.998915625001,0.07,0.199208755372504,50,10.0003795430668,9.23914597718402,0.00118036353960633,5,40,25,4369,0
,10061631.4966405,299.998947656252,0.07,0.199208755372504,50,10.0003795430668,-2.90295694808129,-0.00256230160593987,5,122,25,4369,0
,10061666.8232812,299.992301562502,0.07,0.199208755372504,10,10.0004080549069,-5.55592903335573,0.00122420373372733,5,76,25,4369,0
,10061691.2111719,299.987338281249,0.07,0.199208755372504,30,10.0003985509341,9.95224389852435,0.00109313004132774,5,30,25,4369,0
,10061694.9043751,299.989356249997,0.07,0.199208755372504,30,10.0003985509341,-7.0713496299336,-0.00210716311509411,5,112,25,4369,0
,10061719.3088281,300.003845312499,0.07,0.199208755372504,50,10.0003795430668,-0.980208605021649,0.00123623730614782,5,66,25,4369,0
,10061754.1982813,300.00340625,0.07,0.199208755372504,10,10.0004080549069,8.31503540828069,-0.0024480713182129,5,20,25,4369,0
,10061757.7377345,300.015321875002,0.07,0.199208755372504,10,10.0004080549069,-9.56979384152169,0.00113269634312019,5,102,25,4369,0
,10061782.496875,300.00056875,0.07,0.199208755372504,30,10.0003985509341,3.82698684249032,0.00123346276167366,5,56,25,4369,0
,10061806.4417969,299.99713046875,0.07,0.199208755372504,50,10.0003795430668,4.71414628362317,-0.00257786186411977,5,10,25,4369,0
,10061810.0645312,300.0031203125,0.07,0.199208755372504,50,10.0003795430668,-9.80822505428553,0.00118622994050384,5,92,25,4369,0
,10061845.8998437,299.994513281249,0.07,0.199208755372504,10,10.0004080549069,7.73041996433595,0.00121614604722708,5,46,25,4369,0
,10061870.375,300.0129,0.07,0.199208755372504,30,10.0003985509341,0,-0.00259648193605244,5,0,25,4369,0
,10061873.9464844,300.002938281252,0.07,0.199208755372504,30,10.0003985509341,-7.7304126176656,0.00121956303094824,5,82,25,4369,0
,10061898.7351563,300.018312499999,0.07,0.199208755372504,50,10.0003795430668,9.80822505428553,0.00114818890579045,5,36,25,4369,0
,10061901.9927344,300.009343749997,0.07,0.199208755372504,50,10.0003795430668,-4.71414628362317,-0.00250143702141941,5,118,25,4369,0
,10061936.2340625,300.000962499998,0.07,0.199208755372504,10,10.0004080549069,-3.82699047950326,0.00124854559544474,5,72,25,4369,0
,10061960.4185156,300.0162515625,0.07,0.199208755372504,30,10.0003985509341,9.56978474678673,0.000966055409258438,5,26,25,4369,0
,10061964.0092188,300.004271874999,0.07,0.199208755372504,30,10.0003985509341,-8.31502750601608,0.000851448534780906,5,108,25,4369,0
,10061987.8767187,299.994922656251,0.07,0.199208755372504,50,10.0003795430668,0.980208605021647,0.00123719358816743,5,62,25,4369,0
,10062019.458125,299.99111875,0.07,0.199208755372504,10,10.0004080549069,7.07135635025724,-0.00254357524681836,5,16,25,4369,0
,10062023.1385155,299.988139843748,0.07,0.199208755372504,10,10.0004080549069,-9.95225335673296,0.00117452524136752,5,98,25,4369,0
,10062047.6582813,300.0088640625,0.07,0.199208755372504,30,10.0003985509341,5.55592375323133,0.00122525858589344,5,52,25,4369,0
,10062072.4114844,299.99350625,0.07,0.199208755372504,50,10.0003795430668,2.90295694808128,-0.00258376481942833,5,6,25,4369,0
,10062076.0534375,300.002475000002,0.07,0.199208755372504,50,10.0003795430668,-9.23914597718402,0.00120288119651377,5,88,25,4369,0
,10062110.1380468,300.009407031251,0.07,0.199208755372504,10,10.0004080549069,8.81957251578296,0.00117280113045126,5,42,25,4369,0
,10062113.6582811,300.004442187503,0.07,0.199208755372504,10,10.0004080549069,-1.95098282772447,-0.00254635990131646,5,124,25,4369,0
,10062137.1540624,299.99194375,0.07,0.199208755372504,30,10.0003985509341,-6.34418567967242,0.00122738413564447,5,78,25,4369,0
,10062161.365,300.004487499999,0.07,0.199208755372504,50,10.0003795430668,10.0003795430668,0.00110362591221929,5,32,25,4369,0
,10062164.59375,300.014449218747,0.07,0.199208755372504,50,10.0003795430668,-6.3441736212091,-0.00219722604379058,5,114,25,4369,0
,10062196.9043749,300.0029265625,0.07,0.199208755372504,10,10.0004080549069,-1.95098282772447,0.00123178586363793,5,68,25,4369,0
,10062221.6511719,299.989340625,0.07,0.199208755372504,30,10.0003985509341,8.81956413402722,-0.00154500380934527,5,22,25,4369,0
,10062224.9728125,299.9922875,0.07,0.199208755372504,30,10.0003985509341,-9.23916353816351,0.00103096742855592,5,104,25,4369,0
,10062249.8789063,299.99942890625,0.07,0.199208755372504,50,10.0003795430668,2.90295694808128,0.00123143852688372,5,58,25,4369,0
,10062283.6715625,300.008640625,0.07,0.199208755372504,10,10.0004080549069,5.55592903335573,-0.00257739913649857,5,12,25,4369,0
,10062287.2014062,300.010626562501,0.07,0.199208755372504,10,10.0004080549069,-9.95225335673296,0.00118331634439528,5,94,25,4369,0
,10062311.74875,300.002306249999,0.07,0.199208755372504,30,10.0003985509341,7.0713496299336,0.00121805681070934,5,48,25,4369,0
,10062336.839375,300.008128125,0.07,0.199208755372504,50,10.0003795430668,0.980208605021649,-0.00258997902274132,5,2,25,4369,0
,10062340.09375,300.00313125,0.07,0.199208755372504,50,10.0003795430668,-8.31501170155209,0.00121568385511637,5,84,25,4369,0
,10062370.39,299.992496875,0.07,0.199208755372504,10,10.0004080549069,9.56979384152169,0.00114277383545414,5,38,25,4369,0
,10062374.2849999,300.005437499999,0.07,0.199208755372504,10,10.0004080549069,-3.82699047950326,-0.00241325440583751,5,120,25,4369,0
,10062399.5327344,300.006825000002,0.07,0.199208755372504,30,10.0003985509341,-4.71415524386975,0.00123077427916643,5,74,25,4369,0
,10062424.6882813,299.999349999999,0.07,0.199208755372504,50,10.0003795430668,9.80822505428553,0.00095502967014909,5,28,25,4369,0
,10062428.2853906,299.998324999997,0.07,0.199208755372504,50,10.0003795430668,-7.73039792438553,0.000287569966167212,5,110,25,4369,0
,10062462.1525,300.004200000002,0.07,0.199208755372504,10,10.0004080549069,1.22465632448555E-15,0.00122562720207497,5,64,25,4369,0
,10062486.6685938,300.0123640625,0.07,0.199208755372504,30,10.0003985509341,7.73041261766559,-0.00245070447110468,5,18,25,4369,0
,10062490.3521875,300.010378124999,0.07,0.199208755372504,30,10.0003985509341,-9.80824369692192,0.00111785820788807,5,100,25,4369,0
,10062514.9710156,299.969384375001,0.07,0.199208755372504,50,10.0003795430668,4.71414628362317,0.00122576239518821,5,54,25,4369,0
,10062548.8221875,300.006996875,0.07,0.199208755372504,10,10.0004080549069,3.82699047950326,-0.00261282722931355,5,8,25,4369,0
,10062552.0733594,299.990052343752,0.07,0.199208755372504,10,10.0004080549069,-9.56979384152169,0.00121499586384743,5,90,25,4369,0
,10062576.809375,300.015882812499,0.07,0.199208755372504,30,10.0003985509341,8.31502750601608,0.00120782422729664,5,44,25,4369,0
,10062580.4609375,300.017900781247,0.07,0.199208755372504,30,10.0003985509341,-0.980210468118437,-0.00259198778722849,5,126,25,4369,0
,10062604.73125,299.995937499999,0.07,0.199208755372504,50,10.0003795430668,-7.07133618934179,0.00122483703307807,5,80,25,4369,0
,10062640.2698437,299.980314062499,0.07,0.199208755372504,10,10.0004080549069,9.95225335673296,0.00105999293737113,5,34,25,4369,0
,10062643.8509374,299.996265624997,0.07,0.199208755372504,10,10.0004080549069,-5.55592903335573,-0.00195548171177506,5,116,25,4369,0
,10062669.3595312,300.005024218751,0.07,0.199208755372504,30,10.0003985509341,-2.90296246577389,0.00124201689484633,5,70,25,4369,0
,10062694.115625,300.006396874999,0.07,0.199208755372504,50,10.0003795430668,9.23914597718402,-0.000327988993376494,5,24,25,4369,0
,10062697.8248437,300.006557031248,0.07,0.199208755372504,50,10.0003795430668,-8.81954737058493,0.000999192334711549,5,106,25,4369,0
,10062731.0529687,300.004664062501,0.07,0.199208755372504,10,10.0004080549069,1.95098282772447,0.00123140460345894,5,60,25,4369,0
,10062755.6785156,299.9846578125,0.07,0.199208755372504,30,10.0003985509341,6.34418567967242,-0.00253406799553583,5,14,25,4369,0
,10062759.30125,299.989975000001,0.07,0.199208755372504,30,10.0003985509341,-10.0003985509341,0.00115548629158487,5,96,25,4369,0
,10062784.7871875,300.003914062501,0.07,0.199208755372504,50,10.0003795430668,6.34417362120911,0.00121986893936992,5,50,25,4369,0
,10062819.0064062,300.0119984375,0.07,0.199208755372504,10,10.0004080549069,1.95098282772447,-0.00258768646745011,5,4,25,4369,0
,10062822.6227344,300.011966406248,0.07,0.199208755372504,10,10.0004080549069,-8.81957251578296,0.00121149263577536,5,86,25,4369,0
,10062846.900625,299.992409375,0.07,0.199208755372504,30,10.0003985509341,9.23916353816351,0.00119336900146057,5,40,25,4369,0
,10062850.4176563,300.00339609375,0.07,0.199208755372504,30,10.0003985509341,-2.90296246577389,-0.00257359927571896,5,122,25,4369,0
,10062875.6048438,300.0143890625,0.07,0.199208755372504,50,10.0003795430668,-5.55591319302611,0.00123255057260394,5,76,25,4369,0
,10062909.7411719,300.0009703125,0.07,0.199208755372504,10,10.0004080549069,9.95225335673296,0.000769865291658789,5,30,25,4369,0
,10062913.4343751,299.995012500002,0.07,0.199208755372504,10,10.0004080549069,-7.07135635025724,-0.000459942675661295,5,112,25,4369,0
,10062938.0997656,299.999820312498,0.07,0.199208755372504,30,10.0003985509341,-0.980210468118438,0.00123655992663569,5,66,25,4369,0
,10062963.4559375,300.00210625,0.07,0.199208755372504,50,10.0003795430668,8.31501170155209,-0.002402309095487,5,20,25,4369,0
,10062966.9857812,300.015046874999,0.07,0.199208755372504,50,10.0003795430668,-9.56976655739189,0.00110155954025686,5,102,25,4369,0
,10063001.3121875,299.985128125,0.07,0.199208755372504,10,10.0004080549069,3.82699047950326,0.00122090830700472,5,56,25,4369,0
,10063025.8896094,299.993675,0.07,0.199208755372504,30,10.0003985509341,4.71415524386975,-0.00256662871429904,5,10,25,4369,0
,10063029.3714062,299.992649999998,0.07,0.199208755372504,30,10.0003985509341,-9.80824369692192,0.00118238560389727,5,92,25,4369,0
,10063053.7461719,300.001985937499,0.07,0.199208755372504,50,10.0003795430668,7.73039792438553,0.0012088768184185,5,46,25,4369,0
,10063088.65,300.0011,0.07,0.199208755372504,10,10.0004080549069,0,-0.00259651482338086,5,0,25,4369,0
,10063092.0549219,300.010068750002,0.07,0.199208755372504,10,10.0004080549069,-7.73041996433595,0.00122404744615778,5,82,25,4369,0
,10063116.649375,300.002157812499,0.07,0.199208755372504,30,10.0003985509341,9.80824369692192,0.00116528606870108,5,36,25,4369,0
,10063120.1215626,300.001036718747,0.07,0.199208755372504,30,10.0003985509341,-4.71415524386975,-0.00253496445818908,5,118,25,4369,0
,10063144.5534376,299.997174999999,0.07,0.199208755372504,50,10.0003795430668,-3.82697956849444,0.00123421954922378,5,72,25,4369,0
,10063180.4239844,300.00348046875,0.07,0.199208755372504,10,10.0004080549069,9.56979384152169,-0.000224778486881404,5,26,25,4369,0
,10063184.3157813,300.001526562501,0.07,0.199208755372504,10,10.0004080549069,-8.31503540828069,0.000985934457276016,5,108,25,4369,0
,10063209.1485937,299.998944531251,0.07,0.199208755372504,30,10.0003985509341,0.980210468118436,0.0012361167723106,5,62,25,4369,0
,10063233.739375,300.00186875,0.07,0.199208755372504,50,10.0003795430668,7.07133618934179,-0.00251258430071175,5,16,25,4369,0
,10063237.2980469,299.997864843751,0.07,0.199208755372504,50,10.0003795430668,-9.9522249821852,0.00114606651477516,5,98,25,4369,0
,10063270.8176562,299.995257812501,0.07,0.199208755372504,10,10.0004080549069,5.55592903335573,0.00122214609291405,5,52,25,4369,0
,10063294.6099219,299.99078359375,0.07,0.199208755372504,30,10.0003985509341,2.90296246577389,-0.00258677503249298,5,6,25,4369,0
,10063298.1621876,299.998759375001,0.07,0.199208755372504,30,10.0003985509341,-9.23916353816351,0.00120623173036923,5,88,25,4369,0
,10063322.991875,299.996840625,0.07,0.199208755372504,50,10.0003795430668,8.81954737058493,0.00118955834768712,5,42,25,4369,0
,10063326.4512501,299.991843750001,0.07,0.199208755372504,50,10.0003795430668,-1.95097726534041,-0.00257339361123741,5,124,25,4369,0
,10063362.1264844,299.999195312499,0.07,0.199208755372504,10,10.0004080549069,-6.34419170892896,0.00124656682601199,5,78,25,4369,0
,10063385.81625,300.0094,0.07,0.199208755372504,30,10.0003985509341,10.0003985509341,0.0011276701439379,5,32,25,4369,0
,10063389.3557032,300.006453125,0.07,0.199208755372504,30,10.0003985509341,-6.34418567967242,-0.00244006301121166,5,114,25,4369,0
,10063413.6220313,300.012831250001,0.07,0.199208755372504,50,10.0003795430668,-1.95097726534041,0.00123888165690005,5,68,25,4369,0
,10063444.4380469,300.0016015625,0.07,0.199208755372504,10,10.0004080549069,8.81957251578297,-0.00220489018829539,5,22,25,4369,0
,10063447.9903126,299.993593750002,0.07,0.199208755372504,10,10.0004080549069,-9.23917231868949,0.0010893345461227,5,104,25,4369,0
,10063472.928125,300.012665625,0.07,0.199208755372504,30,10.0003985509341,2.90296246577389,0.00123529158170438,5,58,25,4369,0
,10063496.2298437,300.00288125,0.07,0.199208755372504,50,10.0003795430668,5.5559131930261,-0.00256375349126756,5,12,25,4369,0
,10063499.8846093,300.007878125,0.07,0.199208755372504,50,10.0003795430668,-9.9522249821852,0.00118090943433344,5,94,25,4369,0
,10063535.9025,299.998275000001,0.07,0.199208755372504,10,10.0004080549069,7.07135635025724,0.00120970944408327,5,48,25,4369,0
,10063560.2410156,299.9929921875,0.07,0.199208755372504,30,10.0003985509341,0.980210468118438,-0.00259152852878389,5,2,25,4369,0
,10063563.7676563,300.004971875,0.07,0.199208755372504,30,10.0003985509341,-8.31502750601608,0.00121341701338275,5,84,25,4369,0
,10063588.0840625,299.997569531249,0.07,0.199208755372504,50,10.0003795430668,9.56976655739189,0.00116728120483458,5,38,25,4369,0
,10063591.9662499,299.994590624998,0.07,0.199208755372504,50,10.0003795430668,-3.82697956849444,-0.00253717447631061,5,120,25,4369,0
,10063626.5363281,300.010508593752,0.07,0.199208755372504,10,10.0004080549069,-4.71415972401153,0.0012393796350807,5,74,25,4369,0
,10063650.8109375,299.9948453125,0.07,0.199208755372504,30,10.0003985509341,9.80824369692192,0.00105138680535472,5,28,25,4369,0
,10063654.4304688,300.00083515625,0.07,0.199208755372504,30,10.0003985509341,-7.73041261766559,-0.000382625019281276,5,110,25,4369,0
,10063678.1275,300.0115,0.07,0.199208755372504,50,10.0003795430668,1.2246528329075E-15,0.00123881213366985,5,64,25,4369,0
,10063709.0022656,300.00047109375,0.07,0.199208755372504,10,10.0004080549069,7.73041996433595,-0.00249717151746154,5,18,25,4369,0
,10063712.8620313,299.996467187501,0.07,0.199208755372504,10,10.0004080549069,-9.80825301827858,0.00114388822112232,5,100,25,4369,0
,10063737.2300781,300.003080468751,0.07,0.199208755372504,30,10.0003985509341,4.71415524386975,0.00123022111236221,5,54,25,4369,0
,10063761.514375,299.98518125,0.07,0.199208755372504,50,10.0003795430668,3.82697956849444,-0.00258624791167676,5,8,25,4369,0
,10063765.0954687,299.991139062498,0.07,0.199208755372504,50,10.0003795430668,-9.56976655739189,0.00119874621741474,5,90,25,4369,0
,10063800.640625,300.0011640625,0.07,0.199208755372504,10,10.0004080549069,8.31503540828069,0.0011978909606114,5,44,25,4369,0
,10063804.1640625,300.00715390625,0.07,0.199208755372504,10,10.0004080549069,-0.980211399670677,-0.00256168539635837,5,126,25,4369,0
,10063828.65125,299.995043749998,0.07,0.199208755372504,30,10.0003985509341,-7.0713496299336,0.0012269723487811,5,80,25,4369,0
,10063853.4544531,300.008784375,0.07,0.199208755372504,50,10.0003795430668,9.9522249821852,0.001130111515522,5,34,25,4369,0
,10063856.8657813,299.995843750001,0.07,0.199208755372504,50,10.0003795430668,-5.5559131930261,-0.00242359815165401,5,116,25,4369,0
,10063891.2913281,300.002721875001,0.07,0.199208755372504,10,10.0004080549069,-2.90296522463158,0.00123585894471035,5,70,25,4369,0
,10063916.6328125,299.990471875001,0.07,0.199208755372504,30,10.0003985509341,9.23916353816351,0.00048301415517926,5,24,25,4369,0
,10063920.0761719,299.993450781252,0.07,0.199208755372504,30,10.0003985509341,-8.81956413402722,0.000973876772655383,5,106,25,4369,0
,10063943.9160938,299.990520312499,0.07,0.199208755372504,50,10.0003795430668,1.95097726534041,0.00123725486919284,5,60,25,4369,0
,10063978.991875,299.9775203125,0.07,0.199208755372504,10,10.0004080549069,6.34419170892896,-0.00255845166975632,5,14,25,4369,0
,10063982.4,299.988474999998,0.07,0.199208755372504,10,10.0004080549069,-10.0004080549069,0.00118364958325401,5,96,25,4369,0
,10064007.4275781,299.995903125,0.07,0.199208755372504,30,10.0003985509341,6.34418567967242,0.00123223503275464,5,50,25,4369,0
,10064031.9539062,300.0037453125,0.07,0.199208755372504,50,10.0003795430668,1.95097726534041,-0.00258832322433591,5,4,25,4369,0
,10064035.6214843,300.006724218752,0.07,0.199208755372504,50,10.0003795430668,-8.81954737058493,0.0012168588116765,5,86,25,4369,0
,10064069.5790625,300.000306249999,0.07,0.199208755372504,10,10.0004080549069,9.23917231868949,0.00117713061627001,5,40,25,4369,0
,10064073.0416406,300.006264062498,0.07,0.199208755372504,10,10.0004080549069,-2.90296522463158,-0.00250996090471745,5,122,25,4369,0
,10064097.1906249,299.994240625001,0.07,0.199208755372504,30,10.0003985509341,-5.55592375323133,0.00123687547683302,5,76,25,4369,0
,10064121.710625,299.998503125001,0.07,0.199208755372504,50,10.0003795430668,9.9522249821852,0.00105816260911524,5,30,25,4369,0
,10064125.375,300.002475000003,0.07,0.199208755372504,50,10.0003795430668,-7.07133618934179,-0.0014195918571204,5,112,25,4369,0
,10064156.9851563,300.002924999998,0.07,0.199208755372504,10,10.0004080549069,-0.980211399670677,0.00124635902466252,5,66,25,4369,0
,10064180.971875,299.99465625,0.07,0.199208755372504,30,10.0003985509341,8.31502750601608,-0.00236585535781665,5,20,25,4369,0
,10064184.5465624,300.008621875002,0.07,0.199208755372504,30,10.0003985509341,-9.56978474678674,0.00109227665234357,5,102,25,4369,0
,10064209.2875,299.992753125,0.07,0.199208755372504,50,10.0003795430668,3.82697956849445,0.00122860656119883,5,56,25,4369,0
,10064239.1541406,300.00106015625,0.07,0.199208755372504,10,10.0004080549069,4.71415972401153,-0.00257983483606949,5,10,25,4369,0
,10064242.5910938,299.9921234375,0.07,0.199208755372504,10,10.0004080549069,-9.80825301827858,0.00120012293336913,5,92,25,4369,0
,10064266.6424219,299.998928906249,0.07,0.199208755372504,30,10.0003985509341,7.7304126176656,0.00121102209151205,5,46,25,4369,0
,10064290.435,299.99955,0.07,0.199208755372504,50,10.0003795430668,0,-0.00258650141768157,5,0,25,4369,0
,10064294.2819532,300.0115296875,0.07,0.199208755372504,50,10.0003795430668,-7.73039792438554,0.00122608398087323,5,82,25,4369,0
,10064329.6303125,300.004274999999,0.07,0.199208755372504,10,10.0004080549069,9.80825301827859,0.00112517329398543,5,36,25,4369,0
,10064332.9679688,300.015037499998,0.07,0.199208755372504,10,10.0004080549069,-4.71415972401154,-0.00225856143515557,5,118,25,4369,0
,10064358.4175,299.997000000001,0.07,0.199208755372504,30,10.0003985509341,-3.82698684249031,0.00123913108836859,5,72,25,4369,0
,10064382.1759375,300.00487890625,0.07,0.199208755372504,50,10.0003795430668,9.56976655739189,0.000649738218635321,5,26,25,4369,0
,10064385.6481251,300.012854687502,0.07,0.199208755372504,50,10.0003795430668,-8.31501170155209,0.000910772196948527,5,108,25,4369,0
,10064421.2826562,300.011446874998,0.07,0.199208755372504,10,10.0004080549069,0.980211399670675,0.00122557277791202,5,62,25,4369,0
,10064445.39,300.00805625,0.07,0.199208755372504,30,10.0003985509341,7.0713496299336,-0.0024976147364618,5,16,25,4369,0
,10064448.9774999,300.007063281249,0.07,0.199208755372504,30,10.0003985509341,-9.95224389852435,0.00113992078695446,5,98,25,4369,0
,10064472.760625,299.9905296875,0.07,0.199208755372504,50,10.0003795430668,5.5559131930261,0.00122556858696043,5,52,25,4369,0
,10064508.0542187,299.9916203125,0.07,0.199208755372504,10,10.0004080549069,2.90296522463157,-0.0025995567557402,5,6,25,4369,0
,10064511.596875,299.994631249998,0.07,0.199208755372504,10,10.0004080549069,-9.23917231868949,0.00120699900435284,5,88,25,4369,0
,10064535.8175782,300.0043734375,0.07,0.199208755372504,30,10.0003985509341,8.81956413402722,0.00120497787267797,5,42,25,4369,0
,10064539.1904689,299.997390624999,0.07,0.199208755372504,30,10.0003985509341,-1.95098097359134,-0.00258597312495112,5,124,25,4369,0
,10064563.9876562,300.001307812499,0.07,0.199208755372504,50,10.0003795430668,-6.34417362120911,0.00123335453681648,5,78,25,4369,0
,10064600.1775,300.000874999999,0.07,0.199208755372504,10,10.0004080549069,10.0004080549069,0.000958008458837867,5,32,25,4369,0
,10064603.8354688,300.008882812497,0.07,0.199208755372504,10,10.0004080549069,-6.34419170892896,-0.00140860443934798,5,114,25,4369,0
,10064627.5132813,300.004096875001,0.07,0.199208755372504,30,10.0003985509341,-1.95098097359135,0.00124141696788784,5,68,25,4369,0
,10064651.5707031,299.9961828125,0.07,0.199208755372504,50,10.0003795430668,8.81954737058493,-0.00204154984094203,5,22,25,4369,0
,10064654.8346875,299.998168750001,0.07,0.199208755372504,50,10.0003795430668,-9.23914597718402,0.00106169930659235,5,104,25,4369,0
,10064685.7857813,299.99959453125,0.07,0.199208755372504,10,10.0004080549069,2.90296522463157,0.00122447701869533,5,58,25,4369,0
,10064709.986875,299.975125,0.07,0.199208755372504,30,10.0003985509341,5.55592375323133,-0.00255941840199133,5,12,25,4369,0
,10064713.3821875,299.992037500002,0.07,0.199208755372504,30,10.0003985509341,-9.95224389852435,0.00117580289952457,5,94,25,4369,0
,10064737.635,299.997868750001,0.07,0.199208755372504,50,10.0003795430668,7.07133618934179,0.00121571691706776,5,48,25,4369,0
,10064774.1488281,300.0113359375,0.07,0.199208755372504,10,10.0004080549069,0.980211399670678,-0.00259306310908869,5,2,25,4369,0
,10064777.7907812,299.996409375,0.07,0.199208755372504,10,10.0004080549069,-8.31503540828069,0.00123244739370421,5,84,25,4369,0
,10064803.9690625,299.996526562499,0.07,0.199208755372504,30,10.0003985509341,9.56978474678673,0.00118148765371491,5,38,25,4369,0
,10064807.4412501,300.007481249997,0.07,0.199208755372504,30,10.0003985509341,-3.82698684249031,-0.00255523993271507,5,120,25,4369,0
,10064831.6646094,300.001417968752,0.07,0.199208755372504,50,10.0003795430668,-4.71414628362317,0.00123510928824544,5,74,25,4369,0
,10064864.5028125,299.999353125001,0.07,0.199208755372504,10,10.0004080549069,9.80825301827858,0.000418982235714795,5,28,25,4369,0
,10064867.8789062,300.020301562503,0.07,0.199208755372504,10,10.0004080549069,-7.73041996433595,0.000579586485400796,5,110,25,4369,0
,10064891.9699999,299.994350000001,0.07,0.199208755372504,30,10.0003985509341,1.22465516062299E-15,0.00124096230138093,5,64,25,4369,0
,10064917.5566406,300.002603125,0.07,0.199208755372504,50,10.0003795430668,7.73039792438553,-0.00246808240190148,5,18,25,4369,0
,10064920.9807813,299.99760625,0.07,0.199208755372504,50,10.0003795430668,-9.80822505428553,0.00113124465569854,5,100,25,4369,0
,10064956.441875,300.000721874999,0.07,0.199208755372504,10,10.0004080549069,4.71415972401154,0.00121226999908686,5,54,25,4369,0
,10064980.9990625,299.992434375,0.07,0.199208755372504,30,10.0003985509341,3.82698684249032,-0.00258405641135242,5,8,25,4369,0
,10064984.5769532,299.99842421875,0.07,0.199208755372504,30,10.0003985509341,-9.56978474678673,0.00119842369005912,5,90,25,4369,0
,10065009.1728125,299.989315624999,0.07,0.199208755372504,50,10.0003795430668,8.31501170155208,0.0012057919986546,5,44,25,4369,0
,10065012.7282812,299.992326562498,0.07,0.199208755372504,50,10.0003795430668,-0.980208605021648,-0.00258421050384641,5,126,25,4369,0
,10065047.36625,300.001331250002,0.07,0.199208755372504,10,10.0004080549069,-7.07135635025724,0.00123159581562504,5,80,25,4369,0
,10065071.49375,299.992701562501,0.07,0.199208755372504,30,10.0003985509341,9.95224389852435,0.001146507048462,5,34,25,4369,0
,10065074.7225,299.989690625002,0.07,0.199208755372504,30,10.0003985509341,-5.55592375323133,-0.00249571768411746,5,116,25,4369,0
,10065100.0200781,300.002814062501,0.07,0.199208755372504,50,10.0003795430668,-2.90295694808129,0.00124055580236018,5,70,25,4369,0
,10065135.00375,299.99219375,0.07,0.199208755372504,10,10.0004080549069,9.23917231868949,-0.00123410718515515,5,24,25,4369,0
,10065138.4503126,299.999176562501,0.07,0.199208755372504,10,10.0004080549069,-8.81957251578297,0.00103205966297537,5,106,25,4369,0
,10065163.0325,300.003353124999,0.07,0.199208755372504,30,10.0003985509341,1.95098097359135,0.00123789217064364,5,60,25,4369,0
,10065187.3967188,299.9994328125,0.07,0.199208755372504,50,10.0003795430668,6.34417362120911,-0.00254174848087132,5,14,25,4369,0
,10065190.8625001,299.993475000002,0.07,0.199208755372504,50,10.0003795430668,-10.0003795430668,0.0011684003751725,5,96,25,4369,0
,10065225.4186719,299.994104687501,0.07,0.199208755372504,10,10.0004080549069,6.34419170892896,0.00121968012535945,5,50,25,4369,0
,10065250.0753125,299.99574375,0.07,0.199208755372504,30,10.0003985509341,1.95098097359135,-0.00259009746110274,5,4,25,4369,0
,10065253.3617188,300.000740625,0.07,0.199208755372504,30,10.0003985509341,-8.81956413402722,0.00121800345368683,5,86,25,4369,0
,10065277.87125,300.004621875,0.07,0.199208755372504,50,10.0003795430668,9.23914597718402,0.00118450773879886,5,40,25,4369,0
,10065281.6765626,300.01061171875,0.07,0.199208755372504,50,10.0003795430668,-2.90295694808129,-0.0025578030385077,5,122,25,4369,0
,10065316.6720313,299.999259374999,0.07,0.199208755372504,10,10.0004080549069,-5.55592903335573,0.00125258869957179,5,76,25,4369,0
,10065340.5528125,299.98673671875,0.07,0.199208755372504,30,10.0003985509341,9.95224389852435,0.00109854561742395,5,30,25,4369,0
,10065344.3325001,299.985743749999,0.07,0.199208755372504,30,10.0003985509341,-7.0713496299336,-0.00214307769460397,5,112,25,4369,0
,10065368.8761719,300.008595312499,0.07,0.199208755372504,50,10.0003795430668,-0.980208605021649,0.00123838763684034,5,66,25,4369,0
,10065404.665625,300.0050078125,0.07,0.199208755372504,10,10.0004080549069,8.31503540828069,-0.00244627735810354,5,20,25,4369,0
,10065408.1121876,300.004014843749,0.07,0.199208755372504,10,10.0004080549069,-9.56979384152169,0.00111391156679019,5,102,25,4369,0
,10065432.774375,299.99756875,0.07,0.199208755372504,30,10.0003985509341,3.82698684249032,0.0012394500663504,5,56,25,4369,0
,10065457.6592188,299.99530625,0.07,0.199208755372504,50,10.0003795430668,4.71414628362317,-0.002573600737378,5,10,25,4369,0
,10065461.1378125,299.986337499998,0.07,0.199208755372504,50,10.0003795430668,-9.80822505428553,0.00119039411656558,5,92,25,4369,0
,10065495.7196875,300.00570390625,0.07,0.199208755372504,10,10.0004080549069,7.73041996433595,0.00120518117910251,5,46,25,4369,0
,10065519.53,299.9986,0.07,0.199208755372504,30,10.0003985509341,0,-0.00259173238494744,5,0,25,4369,0
,10065523.2039843,299.989599218751,0.07,0.199208755372504,30,10.0003985509341,-7.7304126176656,0.00122766353241685,5,82,25,4369,0
,10065547.2165625,300.00443125,0.07,0.199208755372504,50,10.0003795430668,9.80822505428553,0.00115189161151648,5,36,25,4369,0
,10065550.5798437,300.008146874999,0.07,0.199208755372504,50,10.0003795430668,-4.71414628362317,-0.00249823862686753,5,118,25,4369,0
,10065587.159375,299.990315624999,0.07,0.199208755372504,10,10.0004080549069,-3.82699047950326,0.00124434533063322,5,72,25,4369,0
,10065612.200625,299.998415625,0.07,0.199208755372504,30,10.0003985509341,9.56978474678673,0.000970483977451093,5,26,25,4369,0
,10065615.8137501,299.993418750001,0.07,0.199208755372504,30,10.0003985509341,-8.31502750601608,0.000853955732761986,5,108,25,4369,0
,10065640.3310937,299.98830078125,0.07,0.199208755372504,50,10.0003795430668,0.980208605021647,0.00123940012417734,5,62,25,4369,0
,10065673.845,299.99815,0.07,0.199208755372504,10,10.0004080549069,7.07135635025724,-0.00253199716098607,5,16,25,4369,0
,10065677.2531249,299.999175000002,0.07,0.199208755372504,10,10.0004080549069,-9.95225335673296,0.00117590592708438,5,98,25,4369,0
,10065702.1528125,299.992003125,0.07,0.199208755372504,30,10.0003985509341,5.55592375323133,0.0012282599022405,5,52,25,4369,0
,10065727.0026563,300.01289140625,0.07,0.199208755372504,50,10.0003795430668,2.90295694808128,-0.00258796568959951,5,6,25,4369,0
,10065730.660625,300.003890625001,0.07,0.199208755372504,50,10.0003795430668,-9.23914597718402,0.00121293505653739,5,88,25,4369,0
,10065764.7007812,299.98654140625,0.07,0.199208755372504,10,10.0004080549069,8.81957251578296,0.00116868992336094,5,42,25,4369,0
,10065768.0896875,299.985548437499,0.07,0.199208755372504,10,10.0004080549069,-1.95098282772447,-0.00253361591603607,5,124,25,4369,0
,10065792.8068751,300.00754765625,0.07,0.199208755372504,30,10.0003985509341,-6.34418567967242,0.00123222429667496,5,78,25,4369,0
,10065817.38125,300.0058,0.07,0.199208755372504,50,10.0003795430668,10.0003795430668,0.00110744354315102,5,32,25,4369,0
,10065820.7797657,299.983890624998,0.07,0.199208755372504,50,10.0003795430668,-6.3441736212091,-0.00220866943709552,5,114,25,4369,0
,10065851.7421874,299.995121875002,0.07,0.199208755372504,10,10.0004080549069,-1.95098282772447,0.00123955163871869,5,68,25,4369,0
,10065876.164375,299.99619765625,0.07,0.199208755372504,30,10.0003985509341,8.81956413402722,-0.00161611682011021,5,22,25,4369,0
,10065879.7775001,300.007184375,0.07,0.199208755372504,30,10.0003985509341,-9.23916353816351,0.0010393427995344,5,104,25,4369,0
,10065904.2151563,300.011218749999,0.07,0.199208755372504,50,10.0003795430668,2.90295694808128,0.00123765780590475,5,58,25,4369,0
,10065939.0648437,300.0010046875,0.07,0.199208755372504,10,10.0004080549069,5.55592903335573,-0.00257732346653938,5,12,25,4369,0
,10065942.7196093,300.000011718749,0.07,0.199208755372504,10,10.0004080549069,-9.95225335673296,0.00120691605843604,5,94,25,4369,0
,10065966.171875,300.00699375,0.07,0.199208755372504,30,10.0003985509341,7.0713496299336,0.00122226710017357,5,48,25,4369,0
,10065988.429375,300.0057984375,0.07,0.199208755372504,50,10.0003795430668,0.980208605021649,-0.00258575933985412,5,2,25,4369,0
,10065991.6837499,300.007784375001,0.07,0.199208755372504,50,10.0003795430668,-8.31501170155209,0.00122208273969591,5,84,25,4369,0
,10066024.9363281,300.000319531249,0.07,0.199208755372504,10,10.0004080549069,9.56979384152169,0.00113663292722777,5,38,25,4369,0
,10066028.6615626,299.995290624998,0.07,0.199208755372504,10,10.0004080549069,-3.82699047950326,-0.00240521650994197,5,120,25,4369,0
,10066053.3333594,299.993327343751,0.07,0.199208755372504,30,10.0003985509341,-4.71415524386975,0.00123713152586586,5,74,25,4369,0
,10066077.9795312,300.007193749999,0.07,0.199208755372504,50,10.0003795430668,9.80822505428553,0.000952055212110279,5,28,25,4369,0
,10066081.6535155,300.001171874998,0.07,0.199208755372504,50,10.0003795430668,-7.73039792438553,0.000229238905012607,5,110,25,4369,0
,10066116.3949999,300.006599999999,0.07,0.199208755372504,10,10.0004080549069,1.22465632448555E-15,0.00124490848975256,5,64,25,4369,0
,10066141.9366406,300.004509375,0.07,0.199208755372504,30,10.0003985509341,7.73041261766559,-0.00244885579579406,5,18,25,4369,0
,10066145.7707812,299.991568750001,0.07,0.199208755372504,30,10.0003985509341,-9.80824369692192,0.00112295719898409,5,100,25,4369,0
,10066170.4734375,300.009592968751,0.07,0.199208755372504,50,10.0003795430668,4.71414628362317,0.0012294746004045,5,54,25,4369,0
,10066203.29375,299.996790625,0.07,0.199208755372504,10,10.0004080549069,3.82699047950326,-0.00258327927440405,5,8,25,4369,0
,10066206.7659376,300.000794531249,0.07,0.199208755372504,10,10.0004080549069,-9.56979384152169,0.00121120014227927,5,90,25,4369,0
,10066232.1435938,299.9991359375,0.07,0.199208755372504,30,10.0003985509341,8.31502750601608,0.00121443105551104,5,44,25,4369,0
,10066235.8496095,299.99314609375,0.07,0.199208755372504,30,10.0003985509341,-0.980210468118437,-0.00258905334501631,5,126,25,4369,0
,10066259.98625,299.995556249998,0.07,0.199208755372504,50,10.0003795430668,-7.07133618934179,0.0012342766392976,5,80,25,4369,0
,10066294.6742968,299.997686718749,0.07,0.199208755372504,10,10.0004080549069,9.95225335673296,0.00106362131191417,5,34,25,4369,0
,10066298.1817187,299.999704687497,0.07,0.199208755372504,10,10.0004080549069,-5.55592903335573,-0.0019741736468859,5,116,25,4369,0
,10066322.350625,300.003124218751,0.07,0.199208755372504,30,10.0003985509341,-2.90296246577389,0.00124093578455763,5,70,25,4369,0
,10066347.06,300.0032,0.07,0.199208755372504,50,10.0003795430668,9.23914597718402,-0.000378625793382527,5,24,25,4369,0
,10066350.545,300.0032,0.07,0.199208755372504,50,10.0003795430668,-8.81954737058493,0.0010061654727906,5,106,25,4369,0
,10066380.4114062,299.990943749998,0.07,0.199208755372504,10,10.0004080549069,1.95098282772447,0.0012489507207647,5,60,25,4369,0
,10066405.1719531,299.9843921875,0.07,0.199208755372504,30,10.0003985509341,6.34418567967242,-0.00252679274934862,5,14,25,4369,0
,10066408.3462499,299.991375000001,0.07,0.199208755372504,30,10.0003985509341,-10.0003985509341,0.00116129315251278,5,96,25,4369,0
,10066432.3350781,299.98850546875,0.07,0.199208755372504,50,10.0003795430668,6.34417362120911,0.00122212790884078,5,50,25,4369,0
,10066468.1903125,299.9915296875,0.07,0.199208755372504,10,10.0004080549069,1.95098282772447,-0.00259910826571286,5,4,25,4369,0
,10066471.7842187,300.006488281252,0.07,0.199208755372504,10,10.0004080549069,-8.81957251578296,0.00122501747682691,5,86,25,4369,0
,10066496.14625,299.997553124999,0.07,0.199208755372504,30,10.0003985509341,9.23916353816351,0.00119727699913912,5,40,25,4369,0
,10066499.4903125,299.982594531247,0.07,0.199208755372504,30,10.0003985509341,-2.90296246577389,-0.00257267965935171,5,122,25,4369,0
,10066523.7859375,300.004428125002,0.07,0.199208755372504,50,10.0003795430668,-5.55591319302611,0.0012397029902786,5,76,25,4369,0
,10066560.1800781,300.00413515625,0.07,0.199208755372504,10,10.0004080549069,9.95225335673296,0.000769916223362087,5,30,25,4369,0
,10066563.815625,300.000131250001,0.07,0.199208755372504,10,10.0004080549069,-7.07135635025724,-0.00051997834816575,5,112,25,4369,0
,10066588.9208594,300.004078125,0.07,0.199208755372504,30,10.0003985509341,-0.980210468118438,0.00124085946784665,5,66,25,4369,0
,10066613.5854687,299.996715625,0.07,0.199208755372504,50,10.0003795430668,8.31501170155209,-0.00240130829624832,5,20,25,4369,0
,10066616.8878906,299.994729687499,0.07,0.199208755372504,50,10.0003795430668,-9.56976655739189,0.00110444384627044,5,102,25,4369,0
,10066650.621875,300.002453124998,0.07,0.199208755372504,10,10.0004080549069,3.82699047950326,0.0012410240015015,5,56,25,4369,0
,10066675.796875,300.00247734375,0.07,0.199208755372504,30,10.0003985509341,4.71415524386975,-0.00257256912947115,5,10,25,4369,0
,10066679.2562501,299.994501562499,0.07,0.199208755372504,30,10.0003985509341,-9.80824369692192,0.00118673500967108,5,92,25,4369,0
,10066703.3879687,299.9990171875,0.07,0.199208755372504,50,10.0003795430668,7.73039792438553,0.00121362586505711,5,46,25,4369,0
,10066707.0646093,300.005914843751,0.07,0.199208755372504,50,10.0003795430668,-0.490695366569778,-0.00258129104040563,5,127,25,4369,0